Workbook
Name AllData: Report!$A$8:$R$44

Sheet Data
A1: CompanyName | B1: Fleet Name
A2: RunDate | B2: 42695.919
A3: FromDate | B3: 42688.919
A4: ToDate | B4: 42695.919
A5: DistanceUnit | B5: miles
A6: SpeedUnit | B6: mph
A7: SendReport | B7: TRUE
A8: LastModifiedUser | B8: vikramsridhar@geotab.com
A9: Language | B9: en
A10: DutyStatusDateTime | B10: DutyStatusStatus | C10: .StatusLog.Device.DeviceName | D10: .StatusLog.Device.DeviceId | E10: .StatusLog.Device.DeviceComment | F10: .StatusLog.Device.DeviceGroup | G10: .StatusLog.Driver.UserFirstName | H10: .StatusLog.Driver.UserLastName | I10: .StatusLog.Driver.UserName | J10: DutyStatusId | K10: DutyStatusCoDrivers | L10: DutyStatusDetailTrailers | M10: DutyStatusDetailOdometer | N10: DutyStatusDetailDistance | O10: DutyStatusDetailLongitude | P10: DutyStatusDetailLatitude | Q10: DutyStatusDetailHosRuleSet | R10: DutyStatusLocation | S10: DutyStatusDetailAnnotations | T10: DutyStatusOrigin | U10: DutyStatusVerifyDateTime | V10: DutyStatusEditDateTime
A11: 42689.442 | B11: OFF | C11: Dispatch - 1 CC | D11: b16 | F11: Company Group, Company Wide Reports, Driver 1, AMO | G11: John | H11: Smith | I11: johnsmith | J11: abYdVyIZ7ykq4q6a-fcHCuQ | M11: 83531.242 | N11: 25.950359 | O11: -79.712051 | P11: 43.437134 | Q11: America8DayBig | R11: ON Oakville | T11: Manual | U11: 42691.515
A12: 42690.193 | B12: D | C12: Dispatch - 1 CC | D12: b16 | F12: Company Group, Company Wide Reports, Driver 1, AMO | G12: John | H12: Smith | I12: johnsmith | J12: aJVmy6RwLl0iD94DOb0yjkw | M12: 83557.195 | N12: 0.01497083 | O12: -79.967972 | P12: 43.269146 | Q12: America8DayBig | R12: 3mi NNE ON Ancaster | U12: 42691.515
A13: 42690.196 | B13: ON | C13: Dispatch - 1 CC | D13: b16 | F13: Company Group, Company Wide Reports, Driver 1, AMO | G13: John | H13: Smith | I13: johnsmith | J13: aBpw1pD5jXkWQEIyp8-dFGw | M13: 83557.211 | N13: 0 | O13: -79.967972 | P13: 43.269119 | Q13: America8DayBig | R13: 3mi NNE ON Ancaster | U13: 42691.515
A14: 42690.198 | B14: D | C14: Dispatch - 1 CC | D14: b16 | F14: Company Group, Company Wide Reports, Driver 1, AMO | G14: John | H14: Smith | I14: johnsmith | J14: azEXVa33T6UeUiOTxbpkryA | M14: 83557.211 | N14: 13.960617 | O14: -79.968002 | P14: 43.269146 | Q14: America8DayBig | R14: 3mi NNE ON Ancaster | U14: 42691.515
A15: 42690.212 | B15: ON | C15: Dispatch - 1 CC | D15: b16 | F15: Company Group, Company Wide Reports, Driver 1, AMO | G15: John | H15: Smith | I15: johnsmith | J15: a4WWZVo00OkK9uylnUf-npg | M15: 83571.172 | N15: 0 | O15: -79.877785 | P15: 43.19767 | Q15: America8DayBig | R15: ON Hamilton | U15: 42691.515
A16: 42690.569 | B16: PC | C16: Dispatch - 1 CC | D16: b16 | F16: Company Group, Company Wide Reports, Driver 1, AMO | G16: John | H16: Smith | I16: johnsmith | J16: aRkM0S7jfAEu1rrDYGuU47Q | M16: 83571.172 | N16: 13.707966 | O16: -79.877785 | P16: 43.19767 | Q16: America8DayBig | R16: ON Hamilton | U16: 42691.515
A17: 42690.586 | B17: ON | C17: Dispatch - 1 CC | D17: b16 | F17: Company Group, Company Wide Reports, Driver 1, AMO | G17: John | H17: Smith | I17: johnsmith | J17: agX3EDx_mO0CG406sOxGPSQ | M17: 83584.875 | N17: 0 | O17: -79.967926 | P17: 43.269173 | Q17: America8DayBig | R17: 3mi NNE ON Ancaster | U17: 42691.515
A18: 42690.625 | B18: OFF | C18: Dispatch - 1 CC | D18: b16 | F18: Company Group, Company Wide Reports, Driver 1, AMO | G18: John | H18: Smith | I18: johnsmith | J18: a5PNQkhNlskSl9RuzfHw2WA | M18: 83584.875 | N18: 26.066063 | O18: -79.967926 | P18: 43.269173 | Q18: America8DayBig | R18: 3mi NNE ON Ancaster | T18: OtherUser | U18: 42691.515 | V18: 42691.5
A19: 42691.61 | B19: ON | C19: Dispatch - 1 CC | D19: b16 | F19: Company Group, Company Wide Reports, Driver 1, AMO | G19: John | H19: Smith | I19: johnsmith | J19: abzUgXogbY06A2090TI8hRg | L19: 34339 | M19: 83610.945 | N19: 0 | O19: -79.686142 | P19: 43.452469 | Q19: America8DayBig | R19: ON Oakville | T19: Manual | U19: 42691.61
A20: 42691.66 | B20: OFF | C20: Dispatch - 1 CC | D20: b16 | F20: Company Group, Company Wide Reports, Driver 1, AMO | G20: John | H20: Smith | I20: johnsmith | J20: ae0KHoK5LqUyu3v-hYzoOBQ | L20: 34339 | M20: 83610.945 | N20: 0 | O20: -79.686142 | P20: 43.452469 | Q20: America8DayBig | R20: ON Oakville | T20: Manual
A21: 42691.66 | B21: D | C21: Dispatch - 1 CC | D21: b16 | F21: Company Group, Company Wide Reports, Driver 1, AMO | G21: John | H21: Smith | I21: johnsmith | J21: aXGzv8nGAlUySdxp8XYV4MQ | L21: 34339 | M21: 83610.945 | N21: 0 | O21: -79.686142 | P21: 43.452469 | Q21: America8DayBig | R21: ON Oakville | T21: Manual
A22: 42691.66 | B22: SB | C22: Dispatch - 1 CC | D22: b16 | F22: Company Group, Company Wide Reports, Driver 1, AMO | G22: John | H22: Smith | I22: johnsmith | J22: aaopSrFUCuUiQBeySs1oOgA | L22: 34339 | M22: 83610.945 | N22: 0 | O22: -79.686142 | P22: 43.452469 | Q22: America8DayBig | R22: ON Oakville | T22: Manual
A23: 42691.66 | B23: OFF | C23: Dispatch - 1 CC | D23: b16 | F23: Company Group, Company Wide Reports, Driver 1, AMO | G23: John | H23: Smith | I23: johnsmith | J23: aFmCltcCFUUmtYH-0wnoZCg | L23: 34339 | M23: 83610.945 | N23: 0 | O23: -79.686142 | P23: 43.452469 | Q23: America8DayBig | R23: ON Oakville | T23: Manual
A24: 42691.663 | B24: YM | C24: Dispatch - 1 CC | D24: b16 | F24: Company Group, Company Wide Reports, Driver 1, AMO | G24: John | H24: Smith | I24: johnsmith | J24: aJYgYspCckEOPqEIJqvvkpg | L24: 34339 | M24: 83610.945 | N24: 0 | O24: -79.686142 | P24: 43.452469 | Q24: America8DayBig | R24: ON Oakville | S24: Moving truck (johnsmith) | T24: Manual
A25: 42691.663 | B25: SB | C25: Dispatch - 1 CC | D25: b16 | F25: Company Group, Company Wide Reports, Driver 1, AMO | G25: John | H25: Smith | I25: johnsmith | J25: abJmNK0ksfE2A-O6zs0xRfA | L25: 34339 | M25: 83610.945 | N25: 0 | O25: -79.686142 | P25: 43.452469 | Q25: America8DayBig | R25: ON Oakville | T25: Manual | V25: 42695.541
A26: 42691.664 | B26: PC | C26: Dispatch - 1 CC | D26: b16 | F26: Company Group, Company Wide Reports, Driver 1, AMO | G26: John | H26: Smith | I26: johnsmith | J26: azu4gA1MQ7UyS36uFBpWBFw | L26: 34339 | M26: 83610.945 | N26: 0 | O26: -79.686142 | P26: 43.452469 | Q26: America8DayBig | R26: ON Oakville | S26: Grabbing Dinner (johnsmith) | T26: Manual
A27: 42691.664 | B27: OFF | C27: Dispatch - 1 CC | D27: b16 | F27: Company Group, Company Wide Reports, Driver 1, AMO | G27: John | H27: Smith | I27: johnsmith | J27: aCniTHYhS50WJMtHlhmA7vQ | L27: 34339 | M27: 83610.945 | O27: -79.686142 | P27: 43.452469 | Q27: America8DayBig | R27: ON Oakville | T27: Manual
A28: 42689.453 | B28: OFF | C28: Dispatch - 1 CC | D28: b16 | F28: Company Group, Company Wide Reports, Driver 1, AMO | G28: Jake | H28: Lee | I28: JakeLee | J28: aRf-yZfz5AUy5SwUgl7j0Uw | M28: 83531.242 | N28: 0 | O28: -79.712051 | P28: 43.437134 | Q28: America7DayBig | R28: ON Oakville | T28: Manual | U28: 42691.456
A29: 42689.458 | B29: ON | C29: Dispatch - 1 CC | D29: b16 | F29: Company Group, Company Wide Reports, Driver 1, AMO | G29: Jake | H29: Lee | I29: JakeLee | J29: agsAMRGUfvE225VoNaMGjyA | M29: 83531.242 | N29: 0 | O29: -79.712051 | P29: 43.437134 | Q29: America7DayBig | R29: ON Oakville | T29: OtherUser | U29: 42691.456 | V29: 42691.387
A30: 42689.5 | B30: D | C30: Dispatch - 1 CC | D30: b16 | F30: Company Group, Company Wide Reports, Driver 1, AMO | G30: Jake | H30: Lee | I30: JakeLee | J30: axxaAxQUnpU26BqO6h-dCgA | M30: 83531.242 | N30: 3.4936652 | O30: -79.712051 | P30: 43.437134 | Q30: America7DayBig | R30: ON Oakville | T30: OtherUser | U30: 42691.389 | V30: 42691.387
A31: 42689.792 | B31: ON | C31: Dispatch - 1 CC | D31: b16 | F31: Company Group, Company Wide Reports, Driver 1, AMO | G31: Jake | H31: Lee | I31: JakeLee | J31: a0ibDrYc8nUK5fO3R7HCMBQ | M31: 83534.734 | N31: 22.456694 | O31: -79.684021 | P31: 43.455051 | Q31: America7DayBig | R31: ON Oakville | T31: OtherUser | U31: 42691.456 | V31: 42691.388
A32: 42689.843 | B32: OFF | C32: Dispatch - 1 CC | D32: b16 | F32: Company Group, Company Wide Reports, Driver 1, AMO | G32: Jake | H32: Lee | I32: JakeLee | J32: aqUha8IPXz0Kay7IP9psF1w | M32: 83557.195 | N32: 39.954853 | O32: -79.967972 | P32: 43.269146 | Q32: America7DayBig | R32: 3mi NNE ON Ancaster | T32: OtherUser | U32: 42691.389 | V32: 42691.389
A33: 42691.444 | B33: ON | C33: Dispatch - 1 CC | D33: b16 | F33: Company Group, Company Wide Reports, Driver 1, AMO | G33: Jake | H33: Lee | I33: JakeLee | J33: aBWkJPLyzTESMv1i9E5Nd4g | M33: 83597.148 | N33: 7.5621328 | O33: -79.797966 | P33: 43.357208 | Q33: America7DayBig | R33: ON Burlington | S33: Fuel Fill up (LeoLandauer) | T33: Manual | U33: 42691.456
A34: 42691.449 | B34: D | C34: Dispatch - 1 CC | D34: b16 | F34: Company Group, Company Wide Reports, Driver 1, AMO | G34: Jake | H34: Lee | I34: JakeLee | J34: aWZJOb_rWBkixqL89ECaLLw | M34: 83604.711 | N34: 2.9317713 | O34: -79.703857 | P34: 43.44302 | Q34: America7DayBig | R34: ON Oakville | T34: Manual | U34: 42691.456
A35: 42691.46 | B35: ON | C35: Dispatch - 1 CC | D35: b16 | F35: Company Group, Company Wide Reports, Driver 1, AMO | G35: Jake | H35: Lee | I35: JakeLee | J35: aG4PjAg0qqU6GxElNDVY0uw | L35: 34339 | M35: 83607.641 | N35: 3.3008592 | O35: -79.681511 | P35: 43.457741 | Q35: America7DayBig | R35: ON Oakville | T35: Manual
A36: 42691.52 | B36: OFF | C36: Dispatch - 1 CC | D36: b16 | F36: Company Group, Company Wide Reports, Driver 1, AMO | G36: Jake | H36: Lee | I36: JakeLee | J36: a8Vus9-W5OEem1al-i4WGgg | L36: 34339 | M36: 83610.945 | O36: -79.686142 | P36: 43.452469 | Q36: America7DayBig | R36: ON Oakville | T36: Manual
A37: 42691.759 | B37: D | C37: Dispatch - 7 LS | D37: b58 | F37: Videos | G37: Sam | H37: Smith | I37: SamSmith | J37: aCBdSqz4FRkqahNVXreRTOQ | L37: 606657 | M37: 845.99774 | N37: 0.3098754 | O37: -79.716301 | P37: 43.717323 | Q37: AmericaSalesperson | R37: ON Brampton | T37: Automatic
A38: 42691.76 | B38: ON | C38: Dispatch - 7 LS | D38: b58 | F38: Videos | G38: Sam | H38: Smith | I38: SamSmith | J38: aWfqdKjGb_kuspM0R-JXeRw | L38: 606657 | M38: 846.30762 | N38: 0 | O38: -79.719475 | P38: 43.717838 | Q38: AmericaSalesperson | R38: ON Brampton | T38: Automatic
A39: 42691.796 | B39: D | C39: Dispatch - 7 LS | D39: b58 | F39: Videos | G39: Sam | H39: Smith | I39: SamSmith | J39: aQ3w9-0G59ESGskitnfnk2A | L39: 606657 | M39: 846.30762 | N39: 0 | O39: -79.719452 | P39: 43.717812 | Q39: AmericaSalesperson | R39: ON Brampton | T39: Automatic
A40: 42691.798 | B40: ON | C40: Dispatch - 7 LS | D40: b58 | F40: Videos | G40: Sam | H40: Smith | I40: SamSmith | J40: aVRxT3EE9oEeVkZpdFUhF2g | L40: 606657 | M40: 846.30762 | N40: 0 | O40: -79.719452 | P40: 43.717812 | Q40: AmericaSalesperson | R40: ON Brampton | T40: Automatic
...

Sheet Summary
A1: =Data!B1 -> Fleet Name
A2: OFF Duty to Drive Instances
A5: Created | B5: =Data!B2 -> 42695.919
A6: From | B6: =Data!B3 -> 42688.919
A7: To | B7: =Data!B4 -> 42695.919
A8: Flag | B8: 1
A10: Sum of Flag
A11: Driver | B11: Full Name | C11: Total
A12: johnsmith | B12: John Smith | C12: 2
A13: Grand Total | C13: 2

Sheet Setup

Sheet Report
A1: Duty Status Logs
A3: Created | B3: =Data!B2 -> 42695.919
A4: From | B4: =Data!B3 -> 42688.919
A5: To | B5: =Data!B4 -> 42695.919
A6: Distance Unit | B6: =Data!B5 -> miles
A8: Driver | B8: First Name | C8: Last Name | D8: Full Name | E8: Date | F8: Status | G8: Flag | H8: Device | I8: CoDrivers | J8: Trailers | K8: Longitude | L8: Latitude | M8: Address | N8: Odometer | O8: Distance | P8: Log Origin | Q8: Verify Date | R8: Edit Date
A9: =Data!I11 -> johnsmith | B9: =Data!G11 -> John | C9: =Data!H11 -> Smith | D9: =B9 & " " & C9 -> John Smith | E9: =Data!A11 -> 42689.442 | F9: =Data!B11 -> OFF | G9: =IF(AND(F9="OFF",F10="D",A9=A10),1,0) -> 1 | H9: =Data!C11 -> Dispatch - 1 CC | I9: =Data!K11 -> 0 | J9: =Data!L11 -> 0 | K9: =Data!O11 -> -79.712051 | L9: =Data!P11 -> 43.437134 | M9: =Data!R11 -> ON Oakville | N9: =Data!M11 -> 83531.242 | O9: =Data!N11 -> 25.950359 | P9: =IF(Data!T11=0,"",Data!T11) -> Manual | Q9: =IF(Data!U11=0,"",Data!U11) -> 42691.515 | R9: =IF(Data!V11=0,"",Data!V11)
A10: =Data!I12 -> johnsmith | B10: =Data!G12 -> John | C10: =Data!H12 -> Smith | D10: =B10 & " " & C10 -> John Smith | E10: =Data!A12 -> 42690.193 | F10: =Data!B12 -> D | G10: =IF(AND(F10="OFF",F11="D",A10=A11),1,0) -> 0 | H10: =Data!C12 -> Dispatch - 1 CC | I10: =Data!K12 -> 0 | J10: =Data!L12 -> 0 | K10: =Data!O12 -> -79.967972 | L10: =Data!P12 -> 43.269146 | M10: =Data!R12 -> 3mi NNE ON Ancaster | N10: =Data!M12 -> 83557.195 | O10: =Data!N12 -> 0.01497083 | P10: =IF(Data!T12=0,"",Data!T12) | Q10: =IF(Data!U12=0,"",Data!U12) -> 42691.515 | R10: =IF(Data!V12=0,"",Data!V12)
A11: =Data!I13 -> johnsmith | B11: =Data!G13 -> John | C11: =Data!H13 -> Smith | D11: =B11 & " " & C11 -> John Smith | E11: =Data!A13 -> 42690.196 | F11: =Data!B13 -> ON | G11: =IF(AND(F11="OFF",F12="D",A11=A12),1,0) -> 0 | H11: =Data!C13 -> Dispatch - 1 CC | I11: =Data!K13 -> 0 | J11: =Data!L13 -> 0 | K11: =Data!O13 -> -79.967972 | L11: =Data!P13 -> 43.269119 | M11: =Data!R13 -> 3mi NNE ON Ancaster | N11: =Data!M13 -> 83557.211 | O11: =Data!N13 -> 0 | P11: =IF(Data!T13=0,"",Data!T13) | Q11: =IF(Data!U13=0,"",Data!U13) -> 42691.515 | R11: =IF(Data!V13=0,"",Data!V13)
A12: =Data!I14 -> johnsmith | B12: =Data!G14 -> John | C12: =Data!H14 -> Smith | D12: =B12 & " " & C12 -> John Smith | E12: =Data!A14 -> 42690.198 | F12: =Data!B14 -> D | G12: =IF(AND(F12="OFF",F13="D",A12=A13),1,0) -> 0 | H12: =Data!C14 -> Dispatch - 1 CC | I12: =Data!K14 -> 0 | J12: =Data!L14 -> 0 | K12: =Data!O14 -> -79.968002 | L12: =Data!P14 -> 43.269146 | M12: =Data!R14 -> 3mi NNE ON Ancaster | N12: =Data!M14 -> 83557.211 | O12: =Data!N14 -> 13.960617 | P12: =IF(Data!T14=0,"",Data!T14) | Q12: =IF(Data!U14=0,"",Data!U14) -> 42691.515 | R12: =IF(Data!V14=0,"",Data!V14)
A13: =Data!I15 -> johnsmith | B13: =Data!G15 -> John | C13: =Data!H15 -> Smith | D13: =B13 & " " & C13 -> John Smith | E13: =Data!A15 -> 42690.212 | F13: =Data!B15 -> ON | G13: =IF(AND(F13="OFF",F14="D",A13=A14),1,0) -> 0 | H13: =Data!C15 -> Dispatch - 1 CC | I13: =Data!K15 -> 0 | J13: =Data!L15 -> 0 | K13: =Data!O15 -> -79.877785 | L13: =Data!P15 -> 43.19767 | M13: =Data!R15 -> ON Hamilton | N13: =Data!M15 -> 83571.172 | O13: =Data!N15 -> 0 | P13: =IF(Data!T15=0,"",Data!T15) | Q13: =IF(Data!U15=0,"",Data!U15) -> 42691.515 | R13: =IF(Data!V15=0,"",Data!V15)
A14: =Data!I16 -> johnsmith | B14: =Data!G16 -> John | C14: =Data!H16 -> Smith | D14: =B14 & " " & C14 -> John Smith | E14: =Data!A16 -> 42690.569 | F14: =Data!B16 -> PC | G14: =IF(AND(F14="OFF",F15="D",A14=A15),1,0) -> 0 | H14: =Data!C16 -> Dispatch - 1 CC | I14: =Data!K16 -> 0 | J14: =Data!L16 -> 0 | K14: =Data!O16 -> -79.877785 | L14: =Data!P16 -> 43.19767 | M14: =Data!R16 -> ON Hamilton | N14: =Data!M16 -> 83571.172 | O14: =Data!N16 -> 13.707966 | P14: =IF(Data!T16=0,"",Data!T16) | Q14: =IF(Data!U16=0,"",Data!U16) -> 42691.515 | R14: =IF(Data!V16=0,"",Data!V16)
A15: =Data!I17 -> johnsmith | B15: =Data!G17 -> John | C15: =Data!H17 -> Smith | D15: =B15 & " " & C15 -> John Smith | E15: =Data!A17 -> 42690.586 | F15: =Data!B17 -> ON | G15: =IF(AND(F15="OFF",F16="D",A15=A16),1,0) -> 0 | H15: =Data!C17 -> Dispatch - 1 CC | I15: =Data!K17 -> 0 | J15: =Data!L17 -> 0 | K15: =Data!O17 -> -79.967926 | L15: =Data!P17 -> 43.269173 | M15: =Data!R17 -> 3mi NNE ON Ancaster | N15: =Data!M17 -> 83584.875 | O15: =Data!N17 -> 0 | P15: =IF(Data!T17=0,"",Data!T17) | Q15: =IF(Data!U17=0,"",Data!U17) -> 42691.515 | R15: =IF(Data!V17=0,"",Data!V17)
A16: =Data!I18 -> johnsmith | B16: =Data!G18 -> John | C16: =Data!H18 -> Smith | D16: =B16 & " " & C16 -> John Smith | E16: =Data!A18 -> 42690.625 | F16: =Data!B18 -> OFF | G16: =IF(AND(F16="OFF",F17="D",A16=A17),1,0) -> 0 | H16: =Data!C18 -> Dispatch - 1 CC | I16: =Data!K18 -> 0 | J16: =Data!L18 -> 0 | K16: =Data!O18 -> -79.967926 | L16: =Data!P18 -> 43.269173 | M16: =Data!R18 -> 3mi NNE ON Ancaster | N16: =Data!M18 -> 83584.875 | O16: =Data!N18 -> 26.066063 | P16: =IF(Data!T18=0,"",Data!T18) -> OtherUser | Q16: =IF(Data!U18=0,"",Data!U18) -> 42691.515 | R16: =IF(Data!V18=0,"",Data!V18) -> 42691.5
A17: =Data!I19 -> johnsmith | B17: =Data!G19 -> John | C17: =Data!H19 -> Smith | D17: =B17 & " " & C17 -> John Smith | E17: =Data!A19 -> 42691.61 | F17: =Data!B19 -> ON | G17: =IF(AND(F17="OFF",F18="D",A17=A18),1,0) -> 0 | H17: =Data!C19 -> Dispatch - 1 CC | I17: =Data!K19 -> 0 | J17: =Data!L19 -> 34339 | K17: =Data!O19 -> -79.686142 | L17: =Data!P19 -> 43.452469 | M17: =Data!R19 -> ON Oakville | N17: =Data!M19 -> 83610.945 | O17: =Data!N19 -> 0 | P17: =IF(Data!T19=0,"",Data!T19) -> Manual | Q17: =IF(Data!U19=0,"",Data!U19) -> 42691.61 | R17: =IF(Data!V19=0,"",Data!V19)
A18: =Data!I20 -> johnsmith | B18: =Data!G20 -> John | C18: =Data!H20 -> Smith | D18: =B18 & " " & C18 -> John Smith | E18: =Data!A20 -> 42691.66 | F18: =Data!B20 -> OFF | G18: =IF(AND(F18="OFF",F19="D",A18=A19),1,0) -> 1 | H18: =Data!C20 -> Dispatch - 1 CC | I18: =Data!K20 -> 0 | J18: =Data!L20 -> 34339 | K18: =Data!O20 -> -79.686142 | L18: =Data!P20 -> 43.452469 | M18: =Data!R20 -> ON Oakville | N18: =Data!M20 -> 83610.945 | O18: =Data!N20 -> 0 | P18: =IF(Data!T20=0,"",Data!T20) -> Manual | Q18: =IF(Data!U20=0,"",Data!U20) | R18: =IF(Data!V20=0,"",Data!V20)
A19: =Data!I21 -> johnsmith | B19: =Data!G21 -> John | C19: =Data!H21 -> Smith | D19: =B19 & " " & C19 -> John Smith | E19: =Data!A21 -> 42691.66 | F19: =Data!B21 -> D | G19: =IF(AND(F19="OFF",F20="D",A19=A20),1,0) -> 0 | H19: =Data!C21 -> Dispatch - 1 CC | I19: =Data!K21 -> 0 | J19: =Data!L21 -> 34339 | K19: =Data!O21 -> -79.686142 | L19: =Data!P21 -> 43.452469 | M19: =Data!R21 -> ON Oakville | N19: =Data!M21 -> 83610.945 | O19: =Data!N21 -> 0 | P19: =IF(Data!T21=0,"",Data!T21) -> Manual | Q19: =IF(Data!U21=0,"",Data!U21) | R19: =IF(Data!V21=0,"",Data!V21)
A20: =Data!I22 -> johnsmith | B20: =Data!G22 -> John | C20: =Data!H22 -> Smith | D20: =B20 & " " & C20 -> John Smith | E20: =Data!A22 -> 42691.66 | F20: =Data!B22 -> SB | G20: =IF(AND(F20="OFF",F21="D",A20=A21),1,0) -> 0 | H20: =Data!C22 -> Dispatch - 1 CC | I20: =Data!K22 -> 0 | J20: =Data!L22 -> 34339 | K20: =Data!O22 -> -79.686142 | L20: =Data!P22 -> 43.452469 | M20: =Data!R22 -> ON Oakville | N20: =Data!M22 -> 83610.945 | O20: =Data!N22 -> 0 | P20: =IF(Data!T22=0,"",Data!T22) -> Manual | Q20: =IF(Data!U22=0,"",Data!U22) | R20: =IF(Data!V22=0,"",Data!V22)
... A25: =Data!I27 -> johnsmith | B25: =Data!G27 -> John | C25: =Data!H27 -> Smith | D25: =B25 & " " & C25 -> John Smith | E25: =Data!A27 -> 42691.664 | F25: =Data!B27 -> OFF | G25: =IF(AND(F25="OFF",F26="D",A25=A26),1,0) -> 0 | H25: =Data!C27 -> Dispatch - 1 CC | I25: =Data!K27 -> 0 | J25: =Data!L27 -> 34339 | K25: =Data!O27 -> -79.686142 | L25: =Data!P27 -> 43.452469 | M25: =Data!R27 -> ON Oakville | N25: =Data!M27 -> 83610.945 | O25: =Data!N27 -> 0 | P25: =IF(Data!T27=0,"",Data!T27) -> Manual | Q25: =IF(Data!U27=0,"",Data!U27) | R25: =IF(Data!V27=0,"",Data!V27)
A26: JakeLee | B26: Jake | C26: Lee | D26: =B26 & " " & C26 -> Jake Lee | E26: =Data!A28 -> 42689.453 | F26: =Data!B28 -> OFF | G26: =IF(AND(F26="OFF",F27="D",A26=A27),1,0) -> 0 | H26: =Data!C28 -> Dispatch - 1 CC | I26: =Data!K28 -> 0 | J26: =Data!L28 -> 0 | K26: =Data!O28 -> -79.712051 | L26: =Data!P28 -> 43.437134 | M26: =Data!R28 -> ON Oakville | N26: =Data!M28 -> 83531.242 | O26: =Data!N28 -> 0 | P26: =IF(Data!T28=0,"",Data!T28) -> Manual | Q26: =IF(Data!U28=0,"",Data!U28) -> 42691.456 | R26: =IF(Data!V28=0,"",Data!V28)
A27: JakeLee | B27: Jake | C27: Lee | D27: =B27 & " " & C27 -> Jake Lee | E27: =Data!A29 -> 42689.458 | F27: =Data!B29 -> ON | G27: =IF(AND(F27="OFF",F28="D",A27=A28),1,0) -> 0 | H27: =Data!C29 -> Dispatch - 1 CC | I27: =Data!K29 -> 0 | J27: =Data!L29 -> 0 | K27: =Data!O29 -> -79.712051 | L27: =Data!P29 -> 43.437134 | M27: =Data!R29 -> ON Oakville | N27: =Data!M29 -> 83531.242 | O27: =Data!N29 -> 0 | P27: =IF(Data!T29=0,"",Data!T29) -> OtherUser | Q27: =IF(Data!U29=0,"",Data!U29) -> 42691.456 | R27: =IF(Data!V29=0,"",Data!V29) -> 42691.387
A28: JakeLee | B28: Jake | C28: Lee | D28: =B28 & " " & C28 -> Jake Lee | E28: =Data!A30 -> 42689.5 | F28: =Data!B30 -> D | G28: =IF(AND(F28="OFF",F29="D",A28=A29),1,0) -> 0 | H28: =Data!C30 -> Dispatch - 1 CC | I28: =Data!K30 -> 0 | J28: =Data!L30 -> 0 | K28: =Data!O30 -> -79.712051 | L28: =Data!P30 -> 43.437134 | M28: =Data!R30 -> ON Oakville | N28: =Data!M30 -> 83531.242 | O28: =Data!N30 -> 3.4936652 | P28: =IF(Data!T30=0,"",Data!T30) -> OtherUser | Q28: =IF(Data!U30=0,"",Data!U30) -> 42691.389 | R28: =IF(Data!V30=0,"",Data!V30) -> 42691.387
A29: JakeLee | B29: Jake | C29: Lee | D29: =B29 & " " & C29 -> Jake Lee | E29: =Data!A31 -> 42689.792 | F29: =Data!B31 -> ON | G29: =IF(AND(F29="OFF",F30="D",A29=A30),1,0) -> 0 | H29: =Data!C31 -> Dispatch - 1 CC | I29: =Data!K31 -> 0 | J29: =Data!L31 -> 0 | K29: =Data!O31 -> -79.684021 | L29: =Data!P31 -> 43.455051 | M29: =Data!R31 -> ON Oakville | N29: =Data!M31 -> 83534.734 | O29: =Data!N31 -> 22.456694 | P29: =IF(Data!T31=0,"",Data!T31) -> OtherUser | Q29: =IF(Data!U31=0,"",Data!U31) -> 42691.456 | R29: =IF(Data!V31=0,"",Data!V31) -> 42691.388
A30: JakeLee | B30: Jake | C30: Lee | D30: =B30 & " " & C30 -> Jake Lee | E30: =Data!A32 -> 42689.843 | F30: =Data!B32 -> OFF | G30: =IF(AND(F30="OFF",F31="D",A30=A31),1,0) -> 0 | H30: =Data!C32 -> Dispatch - 1 CC | I30: =Data!K32 -> 0 | J30: =Data!L32 -> 0 | K30: =Data!O32 -> -79.967972 | L30: =Data!P32 -> 43.269146 | M30: =Data!R32 -> 3mi NNE ON Ancaster | N30: =Data!M32 -> 83557.195 | O30: =Data!N32 -> 39.954853 | P30: =IF(Data!T32=0,"",Data!T32) -> OtherUser | Q30: =IF(Data!U32=0,"",Data!U32) -> 42691.389 | R30: =IF(Data!V32=0,"",Data!V32) -> 42691.389
A31: JakeLee | B31: Jake | C31: Lee | D31: =B31 & " " & C31 -> Jake Lee | E31: =Data!A33 -> 42691.444 | F31: =Data!B33 -> ON | G31: =IF(AND(F31="OFF",F32="D",A31=A32),1,0) -> 0 | H31: =Data!C33 -> Dispatch - 1 CC | I31: =Data!K33 -> 0 | J31: =Data!L33 -> 0 | K31: =Data!O33 -> -79.797966 | L31: =Data!P33 -> 43.357208 | M31: =Data!R33 -> ON Burlington | N31: =Data!M33 -> 83597.148 | O31: =Data!N33 -> 7.5621328 | P31: =IF(Data!T33=0,"",Data!T33) -> Manual | Q31: =IF(Data!U33=0,"",Data!U33) -> 42691.456 | R31: =IF(Data!V33=0,"",Data!V33)
A32: JakeLee | B32: Jake | C32: Lee | D32: =B32 & " " & C32 -> Jake Lee | E32: =Data!A34 -> 42691.449 | F32: =Data!B34 -> D | G32: =IF(AND(F32="OFF",F33="D",A32=A33),1,0) -> 0 | H32: =Data!C34 -> Dispatch - 1 CC | I32: =Data!K34 -> 0 | J32: =Data!L34 -> 0 | K32: =Data!O34 -> -79.703857 | L32: =Data!P34 -> 43.44302 | M32: =Data!R34 -> ON Oakville | N32: =Data!M34 -> 83604.711 | O32: =Data!N34 -> 2.9317713 | P32: =IF(Data!T34=0,"",Data!T34) -> Manual | Q32: =IF(Data!U34=0,"",Data!U34) -> 42691.456 | R32: =IF(Data!V34=0,"",Data!V34)
A33: JakeLee | B33: Jake | C33: Lee | D33: =B33 & " " & C33 -> Jake Lee | E33: =Data!A35 -> 42691.46 | F33: =Data!B35 -> ON | G33: =IF(AND(F33="OFF",F34="D",A33=A34),1,0) -> 0 | H33: =Data!C35 -> Dispatch - 1 CC | I33: =Data!K35 -> 0 | J33: =Data!L35 -> 34339 | K33: =Data!O35 -> -79.681511 | L33: =Data!P35 -> 43.457741 | M33: =Data!R35 -> ON Oakville | N33: =Data!M35 -> 83607.641 | O33: =Data!N35 -> 3.3008592 | P33: =IF(Data!T35=0,"",Data!T35) -> Manual | Q33: =IF(Data!U35=0,"",Data!U35) | R33: =IF(Data!V35=0,"",Data!V35)
A34: JakeLee | B34: Jake | C34: Lee | D34: =B34 & " " & C34 -> Jake Lee | E34: =Data!A36 -> 42691.52 | F34: =Data!B36 -> OFF | G34: =IF(AND(F34="OFF",F35="D",A34=A35),1,0) -> 0 | H34: =Data!C36 -> Dispatch - 1 CC | I34: =Data!K36 -> 0 | J34: =Data!L36 -> 34339 | K34: =Data!O36 -> -79.686142 | L34: =Data!P36 -> 43.452469 | M34: =Data!R36 -> ON Oakville | N34: =Data!M36 -> 83610.945 | O34: =Data!N36 -> 0 | P34: =IF(Data!T36=0,"",Data!T36) -> Manual | Q34: =IF(Data!U36=0,"",Data!U36) | R34: =IF(Data!V36=0,"",Data!V36)
A35: SamSmith | B35: Sam | C35: Smith | D35: =B35 & " " & C35 -> Sam Smith | E35: =Data!A37 -> 42691.759 | F35: =Data!B37 -> D | G35: =IF(AND(F35="OFF",F36="D",A35=A36),1,0) -> 0 | H35: =Data!C37 -> Dispatch - 7 LS | I35: =Data!K37 -> 0 | J35: =Data!L37 -> 606657 | K35: =Data!O37 -> -79.716301 | L35: =Data!P37 -> 43.717323 | M35: =Data!R37 -> ON Brampton | N35: =Data!M37 -> 845.99774 | O35: =Data!N37 -> 0.3098754 | P35: =IF(Data!T37=0,"",Data!T37) -> Automatic | Q35: =IF(Data!U37=0,"",Data!U37) | R35: =IF(Data!V37=0,"",Data!V37)
A36: SamSmith | B36: Sam | C36: Smith | D36: =B36 & " " & C36 -> Sam Smith | E36: =Data!A38 -> 42691.76 | F36: =Data!B38 -> ON | G36: =IF(AND(F36="OFF",F37="D",A36=A37),1,0) -> 0 | H36: =Data!C38 -> Dispatch - 7 LS | I36: =Data!K38 -> 0 | J36: =Data!L38 -> 606657 | K36: =Data!O38 -> -79.719475 | L36: =Data!P38 -> 43.717838 | M36: =Data!R38 -> ON Brampton | N36: =Data!M38 -> 846.30762 | O36: =Data!N38 -> 0 | P36: =IF(Data!T38=0,"",Data!T38) -> Automatic | Q36: =IF(Data!U38=0,"",Data!U38) | R36: =IF(Data!V38=0,"",Data!V38)
A37: SamSmith | B37: Sam | C37: Smith | D37: =B37 & " " & C37 -> Sam Smith | E37: =Data!A39 -> 42691.796 | F37: =Data!B39 -> D | G37: =IF(AND(F37="OFF",F38="D",A37=A38),1,0) -> 0 | H37: =Data!C39 -> Dispatch - 7 LS | I37: =Data!K39 -> 0 | J37: =Data!L39 -> 606657 | K37: =Data!O39 -> -79.719452 | L37: =Data!P39 -> 43.717812 | M37: =Data!R39 -> ON Brampton | N37: =Data!M39 -> 846.30762 | O37: =Data!N39 -> 0 | P37: =IF(Data!T39=0,"",Data!T39) -> Automatic | Q37: =IF(Data!U39=0,"",Data!U39) | R37: =IF(Data!V39=0,"",Data!V39)
... A44: SamSmith | B44: Sam | C44: Smith | D44: =B44 & " " & C44 -> Sam Smith | E44: =Data!A46 -> 42691.873 | F44: =Data!B46 -> ON | G44: =IF(AND(F44="OFF",F45="D",A44=A45),1,0) -> 0 | H44: =Data!C46 -> Dispatch - 7 LS | I44: =Data!K46 -> 0 | J44: =Data!L46 -> 606657 | K44: =Data!O46 -> -79.869873 | L44: =Data!P46 -> 43.869415 | M44: =Data!R46 -> 11mi ESE ON Orangeville | N44: =Data!M46 -> 866.81287 | O44: =Data!N46 -> 0 | P44: =IF(Data!T46=0,"",Data!T46) -> Automatic | Q44: =IF(Data!U46=0,"",Data!U46) | R44: =IF(Data!V46=0,"",Data!V46)

Sheet Languages
A1: English | B1: French | C1: Spanish | D1: German | E1: Japanese | F1: Polish
A2: **Driver | B2: Conducteur | C2: Conductor | D2: Fahrer | E2: ドライバー | F2: Kierowca
A3: **Date | B3: Date | C3: Fecha | D3: Datum | E3: データ | F3: Data
A4: **Status | B4: État | C4: Estado | D4: Status | E4: ステータス | F4: Status
A5: **Device | B5: Dispositif | C5: Dispositivo | D5: Gerät | E5: デバイス | F5: Urzadzenie
A6: **CoDrivers | B6: Co-chauffeurs | C6: Copiloto | D6: Beifahrer | E6: 補助ドライバー | F6: Wspólkierowcy
A7: **Trailers | B7: Gros porteurs | C7: Remolques | D7: Anhänger | E7: トレーラー | F7: Przyczepy
A8: **Longitude | B8: Longitude | C8: Longitud | D8: Längengrad | E8: 経度 | F8: Dlugosc geograficzna
A9: **Latitude | B9: Latitude | C9: Latitud | D9: Breitengrad | E9: 緯度 | F9: Szerokosc geograficzna
A10: **Address | B10: Adresse | C10: Dirección | D10: Adresse | E10: 住所 | F10: Adres
A11: **Odometer | B11: Odomètre | C11: Odómetro | D11: Kilometerstand | E11: オドメータ | F11: Licznik kilometrów
A12: **Distance | B12: Distance | C12: Distancia | D12: Entfernung | E12: 距離 | F12: Odleglosc
... A23: **Log Origin | B23: Origine du Journal | C23: Origen del Registro | D23: Protokollherkunft | E23: ログの起源 | F23: Powstanie dziennika
