Workbook
Name AllData: Report!$A$11:$S$140

Sheet Summary
A1: **Excessive Yard Move | E1: =Data!B2 -> 43961.708
A2: =Data!B1 -> ABC Company
I3: **This report allows the carrier to flag drivers who exceed a customizable excessive YM threshold. The excessive YM threshold can be modified in cell B9.
A4: **Date
A5: **From | B5: =Data!B3 -> 43954 | E5: **Excessive YM Events | F5: =COUNTA(A13:A1048) -> 2
A6: **To | B6: =Data!B4 -> 43961
A7: **Days | B7: =B6-B5 -> 6.9999884
A9: **YM Distance Threshold | B9: 5
A10: **Distance Unit | B10: =Data!B5 -> miles
A12: **Driver | B12: **Vehicle | C12: Excessive YM | D12: **Status | E12: **Date | F12: **YM Distance
A13: Driver1 | B13: Vehicle1 | C13: 1 | D13: YM | E13: May 04, 2020 | F13: 20.686911
A14: Driver2 | B14: Vehicle2 | C14: 1 | D14: YM | E14: May 08, 2020 | F14: 14.275276

Sheet Excessive YM Events
B2: **Excessive YM Events
B4: =Summary!F5 -> 2
B17: **From: | C17: =Data!B3 -> 43954 | D17: **To: | E17: =Data!B4 -> 43961
J21: Language Translations
J22: **Excessive YM
J23: **Occurances
J24: =Summary!A10&" ("&Summary!B10&")" -> **Distance Unit (miles)
J31: Excessive YM | K31: **Driver | L31: **Vehicle | M31: **Date | N31: Max of Accumulating YM Distance for the date
J32: 1 | K32: Driver1 | L32: Vehicle1 | M32: May 04, 2020 | N32: 20.686911
K33: Driver2 | L33: Vehicle2 | M33: May 08, 2020 | N33: 14.275276

Sheet Report
A1: **Excessive Yard Move | D1: =Data!B2 -> 43961.708
A2: =Data!B1 -> ABC Company
A4: **Date
A5: **From | B5: =Data!B3 -> 43954
A6: **To | B6: =Data!B4 -> 43961
A7: **Days | B7: =B6-B5 -> 6.9999884
A9: **Distance Unit | B9: =Data!B5 -> miles
A11: **Driver | B11: **First Name | C11: **Last Name | D11: **Vehicle | E11: **Date | F11: **Date and Time | G11: **Duty Status | H11: **Status | I11: **Duration | J11: **Distance | K11: Driver Change? | L11: Date Change? | M11: YM Distance | N11: Accumulating YM Distance for the date | O11: Flag for a YM log | P11: Excessive YM Distance for the date | Q11: Excessive YM | R11: Excessive YM Log | S11: **Verify Date
A12: =Data!H11 -> Driver1 | B12: =Data!F11 -> FirstName1 | C12: =Data!G11 -> LastName1 | D12: =Data!D11 -> Vehicle1 | E12: =TEXT(INT(Data!A11),"mmm dd, yyyy") -> May 03, 2020 | F12: =Data!A11 -> 43954 | G12: =Data!B11 -> D | H12: =IF(ISNUMBER(SEARCH("YM",G12)),"YM","NOT") -> NOT | I12: =Data!C11 -> 1.2951389 | J12: =Data!J11 -> 2.4854848 | K12: =IF(K11="Driver Change?",FALSE,IF((A11<>A12),TRUE,FALSE)) -> FALSE | L12: =IF(L11="Date Change?",FALSE,IF(AND(INT(F11)<>INT(F12),F12<>""),TRUE,FALSE)) -> FALSE | M12: =IF(ISNUMBER(SEARCH("YM",G12)),J12,0) -> 0 | N12: =IF(OR(K12, L12),0,IF(AND(M12>0,ISNUMBER(SEARCH("YM",N11))=FALSE),J12+N11,IF(ISNUMBER(SEARCH("YM",N11))=TRUE,M12,N11))) -> 0 | O12: =ISNUMBER(SEARCH("YM",G12)) -> FALSE | P12: =IF(N12>Summary!$B$9,TRUE,FALSE) -> FALSE | Q12: =IF(AND(O12, P12), 1, 0) -> 0 | R12: =IF(Q12=1, 'Excessive YM Events'!$J$22, "") | S12: =IF(Data!L11=0,"",Data!L11) -> 43956.862
A13: =Data!H12 -> Driver1 | B13: =Data!F12 -> FirstName1 | C13: =Data!G12 -> LastName1 | D13: =Data!D12 -> Vehicle1 | E13: =TEXT(INT(Data!A12),"mmm dd, yyyy") -> May 04, 2020 | F13: =Data!A12 -> 43955.295 | G13: =Data!B12 -> ON | H13: =IF(ISNUMBER(SEARCH("YM",G13)),"YM","NOT") -> NOT | I13: =Data!C12 -> 0.011138194 | J13: =Data!J12 -> 0 | K13: =IF(K12="Driver Change?",FALSE,IF((A12<>A13),TRUE,FALSE)) -> FALSE | L13: =IF(L12="Date Change?",FALSE,IF(AND(INT(F12)<>INT(F13),F13<>""),TRUE,FALSE)) -> TRUE | M13: =IF(ISNUMBER(SEARCH("YM",G13)),J13,0) -> 0 | N13: =IF(OR(K13, L13),0,IF(AND(M13>0,ISNUMBER(SEARCH("YM",N12))=FALSE),J13+N12,IF(ISNUMBER(SEARCH("YM",N12))=TRUE,M13,N12))) -> 0 | O13: =ISNUMBER(SEARCH("YM",G13)) -> FALSE | P13: =IF(N13>Summary!$B$9,TRUE,FALSE) -> FALSE | Q13: =IF(AND(O13, P13), 1, 0) -> 0 | R13: =IF(Q13=1, 'Excessive YM Events'!$J$22, "") | S13: =IF(Data!L12=0,"",Data!L12) -> 43956.286
A14: =Data!H13 -> Driver1 | B14: =Data!F13 -> FirstName1 | C14: =Data!G13 -> LastName1 | D14: =Data!D13 -> Vehicle1 | E14: =TEXT(INT(Data!A13),"mmm dd, yyyy") -> May 04, 2020 | F14: =Data!A13 -> 43955.304 | G14: =Data!B13 -> OFF | H14: =IF(ISNUMBER(SEARCH("YM",G14)),"YM","NOT") -> NOT | I14: =Data!C13 -> 0 | J14: =Data!J13 -> 0 | K14: =IF(K13="Driver Change?",FALSE,IF((A13<>A14),TRUE,FALSE)) -> FALSE | L14: =IF(L13="Date Change?",FALSE,IF(AND(INT(F13)<>INT(F14),F14<>""),TRUE,FALSE)) -> FALSE | M14: =IF(ISNUMBER(SEARCH("YM",G14)),J14,0) -> 0 | N14: =IF(OR(K14, L14),0,IF(AND(M14>0,ISNUMBER(SEARCH("YM",N13))=FALSE),J14+N13,IF(ISNUMBER(SEARCH("YM",N13))=TRUE,M14,N13))) -> 0 | O14: =ISNUMBER(SEARCH("YM",G14)) -> FALSE | P14: =IF(N14>Summary!$B$9,TRUE,FALSE) -> FALSE | Q14: =IF(AND(O14, P14), 1, 0) -> 0 | R14: =IF(Q14=1, 'Excessive YM Events'!$J$22, "") | S14: =IF(Data!L13=0,"",Data!L13) -> 43956.286
A15: =Data!H14 -> Driver1 | B15: =Data!F14 -> FirstName1 | C15: =Data!G14 -> LastName1 | D15: =Data!D14 -> Vehicle1 | E15: =TEXT(INT(Data!A14),"mmm dd, yyyy") -> May 04, 2020 | F15: =Data!A14 -> 43955.306 | G15: =Data!B14 -> D | H15: =IF(ISNUMBER(SEARCH("YM",G15)),"YM","NOT") -> NOT | I15: =Data!C14 -> 0.00045902778 | J15: =Data!J14 -> 0.88891089 | K15: =IF(K14="Driver Change?",FALSE,IF((A14<>A15),TRUE,FALSE)) -> FALSE | L15: =IF(L14="Date Change?",FALSE,IF(AND(INT(F14)<>INT(F15),F15<>""),TRUE,FALSE)) -> FALSE | M15: =IF(ISNUMBER(SEARCH("YM",G15)),J15,0) -> 0 | N15: =IF(OR(K15, L15),0,IF(AND(M15>0,ISNUMBER(SEARCH("YM",N14))=FALSE),J15+N14,IF(ISNUMBER(SEARCH("YM",N14))=TRUE,M15,N14))) -> 0 | O15: =ISNUMBER(SEARCH("YM",G15)) -> FALSE | P15: =IF(N15>Summary!$B$9,TRUE,FALSE) -> FALSE | Q15: =IF(AND(O15, P15), 1, 0) -> 0 | R15: =IF(Q15=1, 'Excessive YM Events'!$J$22, "") | S15: =IF(Data!L14=0,"",Data!L14) -> 43956.286
A16: =Data!H15 -> Driver1 | B16: =Data!F15 -> FirstName1 | C16: =Data!G15 -> LastName1 | D16: =Data!D15 -> Vehicle1 | E16: =TEXT(INT(Data!A15),"mmm dd, yyyy") -> May 04, 2020 | F16: =Data!A15 -> 43955.307 | G16: =Data!B15 -> ON | H16: =IF(ISNUMBER(SEARCH("YM",G16)),"YM","NOT") -> NOT | I16: =Data!C15 -> 0.032361111 | J16: =Data!J15 -> 0.008041773 | K16: =IF(K15="Driver Change?",FALSE,IF((A15<>A16),TRUE,FALSE)) -> FALSE | L16: =IF(L15="Date Change?",FALSE,IF(AND(INT(F15)<>INT(F16),F16<>""),TRUE,FALSE)) -> FALSE | M16: =IF(ISNUMBER(SEARCH("YM",G16)),J16,0) -> 0 | N16: =IF(OR(K16, L16),0,IF(AND(M16>0,ISNUMBER(SEARCH("YM",N15))=FALSE),J16+N15,IF(ISNUMBER(SEARCH("YM",N15))=TRUE,M16,N15))) -> 0 | O16: =ISNUMBER(SEARCH("YM",G16)) -> FALSE | P16: =IF(N16>Summary!$B$9,TRUE,FALSE) -> FALSE | Q16: =IF(AND(O16, P16), 1, 0) -> 0 | R16: =IF(Q16=1, 'Excessive YM Events'!$J$22, "") | S16: =IF(Data!L15=0,"",Data!L15) -> 43956.286
A17: =Data!H16 -> Driver1 | B17: =Data!F16 -> FirstName1 | C17: =Data!G16 -> LastName1 | D17: =Data!D16 -> Vehicle1 | E17: =TEXT(INT(Data!A16),"mmm dd, yyyy") -> May 04, 2020 | F17: =Data!A16 -> 43955.339 | G17: =Data!B16 -> D | H17: =IF(ISNUMBER(SEARCH("YM",G17)),"YM","NOT") -> NOT | I17: =Data!C16 -> 2.9050926e-05 | J17: =Data!J16 -> 0.93382579 | K17: =IF(K16="Driver Change?",FALSE,IF((A16<>A17),TRUE,FALSE)) -> FALSE | L17: =IF(L16="Date Change?",FALSE,IF(AND(INT(F16)<>INT(F17),F17<>""),TRUE,FALSE)) -> FALSE | M17: =IF(ISNUMBER(SEARCH("YM",G17)),J17,0) -> 0 | N17: =IF(OR(K17, L17),0,IF(AND(M17>0,ISNUMBER(SEARCH("YM",N16))=FALSE),J17+N16,IF(ISNUMBER(SEARCH("YM",N16))=TRUE,M17,N16))) -> 0 | O17: =ISNUMBER(SEARCH("YM",G17)) -> FALSE | P17: =IF(N17>Summary!$B$9,TRUE,FALSE) -> FALSE | Q17: =IF(AND(O17, P17), 1, 0) -> 0 | R17: =IF(Q17=1, 'Excessive YM Events'!$J$22, "") | S17: =IF(Data!L16=0,"",Data!L16) -> 43956.286
A18: =Data!H17 -> Driver1 | B18: =Data!F17 -> FirstName1 | C18: =Data!G17 -> LastName1 | D18: =Data!D17 -> Vehicle1 | E18: =TEXT(INT(Data!A17),"mmm dd, yyyy") -> May 04, 2020 | F18: =Data!A17 -> 43955.339 | G18: =Data!B17 -> ON | H18: =IF(ISNUMBER(SEARCH("YM",G18)),"YM","NOT") -> NOT | I18: =Data!C17 -> 0.021591319 | J18: =Data!J17 -> 0 | K18: =IF(K17="Driver Change?",FALSE,IF((A17<>A18),TRUE,FALSE)) -> FALSE | L18: =IF(L17="Date Change?",FALSE,IF(AND(INT(F17)<>INT(F18),F18<>""),TRUE,FALSE)) -> FALSE | M18: =IF(ISNUMBER(SEARCH("YM",G18)),J18,0) -> 0 | N18: =IF(OR(K18, L18),0,IF(AND(M18>0,ISNUMBER(SEARCH("YM",N17))=FALSE),J18+N17,IF(ISNUMBER(SEARCH("YM",N17))=TRUE,M18,N17))) -> 0 | O18: =ISNUMBER(SEARCH("YM",G18)) -> FALSE | P18: =IF(N18>Summary!$B$9,TRUE,FALSE) -> FALSE | Q18: =IF(AND(O18, P18), 1, 0) -> 0 | R18: =IF(Q18=1, 'Excessive YM Events'!$J$22, "") | S18: =IF(Data!L17=0,"",Data!L17) -> 43956.286
A19: =Data!H18 -> Driver1 | B19: =Data!F18 -> FirstName1 | C19: =Data!G18 -> LastName1 | D19: =Data!D18 -> Vehicle1 | E19: =TEXT(INT(Data!A18),"mmm dd, yyyy") -> May 04, 2020 | F19: =Data!A18 -> 43955.361 | G19: =Data!B18 -> D | H19: =IF(ISNUMBER(SEARCH("YM",G19)),"YM","NOT") -> NOT | I19: =Data!C18 -> 0.011467789 | J19: =Data!J18 -> 0.7638365 | K19: =IF(K18="Driver Change?",FALSE,IF((A18<>A19),TRUE,FALSE)) -> FALSE | L19: =IF(L18="Date Change?",FALSE,IF(AND(INT(F18)<>INT(F19),F19<>""),TRUE,FALSE)) -> FALSE | M19: =IF(ISNUMBER(SEARCH("YM",G19)),J19,0) -> 0 | N19: =IF(OR(K19, L19),0,IF(AND(M19>0,ISNUMBER(SEARCH("YM",N18))=FALSE),J19+N18,IF(ISNUMBER(SEARCH("YM",N18))=TRUE,M19,N18))) -> 0 | O19: =ISNUMBER(SEARCH("YM",G19)) -> FALSE | P19: =IF(N19>Summary!$B$9,TRUE,FALSE) -> FALSE | Q19: =IF(AND(O19, P19), 1, 0) -> 0 | R19: =IF(Q19=1, 'Excessive YM Events'!$J$22, "") | S19: =IF(Data!L18=0,"",Data!L18) -> 43956.286
A20: =Data!H19 -> Driver1 | B20: =Data!F19 -> FirstName1 | C20: =Data!G19 -> LastName1 | D20: =Data!D19 -> Vehicle1 | E20: =TEXT(INT(Data!A19),"mmm dd, yyyy") -> May 04, 2020 | F20: =Data!A19 -> 43955.372 | G20: =Data!B19 -> ON | H20: =IF(ISNUMBER(SEARCH("YM",G20)),"YM","NOT") -> NOT | I20: =Data!C19 -> 0.0309314 | J20: =Data!J19 -> 0.0081987698 | K20: =IF(K19="Driver Change?",FALSE,IF((A19<>A20),TRUE,FALSE)) -> FALSE | L20: =IF(L19="Date Change?",FALSE,IF(AND(INT(F19)<>INT(F20),F20<>""),TRUE,FALSE)) -> FALSE | M20: =IF(ISNUMBER(SEARCH("YM",G20)),J20,0) -> 0 | N20: =IF(OR(K20, L20),0,IF(AND(M20>0,ISNUMBER(SEARCH("YM",N19))=FALSE),J20+N19,IF(ISNUMBER(SEARCH("YM",N19))=TRUE,M20,N19))) -> 0 | O20: =ISNUMBER(SEARCH("YM",G20)) -> FALSE | P20: =IF(N20>Summary!$B$9,TRUE,FALSE) -> FALSE | Q20: =IF(AND(O20, P20), 1, 0) -> 0 | R20: =IF(Q20=1, 'Excessive YM Events'!$J$22, "") | S20: =IF(Data!L19=0,"",Data!L19) -> 43956.286
A21: =Data!H20 -> Driver1 | B21: =Data!F20 -> FirstName1 | C21: =Data!G20 -> LastName1 | D21: =Data!D20 -> Vehicle1 | E21: =TEXT(INT(Data!A20),"mmm dd, yyyy") -> May 04, 2020 | F21: =Data!A20 -> 43955.403 | G21: =Data!B20 -> D | H21: =IF(ISNUMBER(SEARCH("YM",G21)),"YM","NOT") -> NOT | I21: =Data!C20 -> 0.057890162 | J21: =Data!J20 -> 6.1095295 | K21: =IF(K20="Driver Change?",FALSE,IF((A20<>A21),TRUE,FALSE)) -> FALSE | L21: =IF(L20="Date Change?",FALSE,IF(AND(INT(F20)<>INT(F21),F21<>""),TRUE,FALSE)) -> FALSE | M21: =IF(ISNUMBER(SEARCH("YM",G21)),J21,0) -> 0 | N21: =IF(OR(K21, L21),0,IF(AND(M21>0,ISNUMBER(SEARCH("YM",N20))=FALSE),J21+N20,IF(ISNUMBER(SEARCH("YM",N20))=TRUE,M21,N20))) -> 0 | O21: =ISNUMBER(SEARCH("YM",G21)) -> FALSE | P21: =IF(N21>Summary!$B$9,TRUE,FALSE) -> FALSE | Q21: =IF(AND(O21, P21), 1, 0) -> 0 | R21: =IF(Q21=1, 'Excessive YM Events'!$J$22, "") | S21: =IF(Data!L20=0,"",Data!L20) -> 43956.286
A22: =Data!H21 -> Driver1 | B22: =Data!F21 -> FirstName1 | C22: =Data!G21 -> LastName1 | D22: =Data!D21 -> Vehicle1 | E22: =TEXT(INT(Data!A21),"mmm dd, yyyy") -> May 04, 2020 | F22: =Data!A21 -> 43955.461 | G22: =Data!B21 -> ON | H22: =IF(ISNUMBER(SEARCH("YM",G22)),"YM","NOT") -> NOT | I22: =Data!C21 -> 0.20180706 | J22: =Data!J21 -> 0.015320825 | K22: =IF(K21="Driver Change?",FALSE,IF((A21<>A22),TRUE,FALSE)) -> FALSE | L22: =IF(L21="Date Change?",FALSE,IF(AND(INT(F21)<>INT(F22),F22<>""),TRUE,FALSE)) -> FALSE | M22: =IF(ISNUMBER(SEARCH("YM",G22)),J22,0) -> 0 | N22: =IF(OR(K22, L22),0,IF(AND(M22>0,ISNUMBER(SEARCH("YM",N21))=FALSE),J22+N21,IF(ISNUMBER(SEARCH("YM",N21))=TRUE,M22,N21))) -> 0 | O22: =ISNUMBER(SEARCH("YM",G22)) -> FALSE | P22: =IF(N22>Summary!$B$9,TRUE,FALSE) -> FALSE | Q22: =IF(AND(O22, P22), 1, 0) -> 0 | R22: =IF(Q22=1, 'Excessive YM Events'!$J$22, "") | S22: =IF(Data!L21=0,"",Data!L21) -> 43956.286
A23: =Data!H22 -> Driver1 | B23: =Data!F22 -> FirstName1 | C23: =Data!G22 -> LastName1 | D23: =Data!D22 -> Vehicle1 | E23: =TEXT(INT(Data!A22),"mmm dd, yyyy") -> May 04, 2020 | F23: =Data!A22 -> 43955.503 | G23: =Data!B22 -> YM | H23: =IF(ISNUMBER(SEARCH("YM",G23)),"YM","NOT") -> YM | I23: =Data!C22 -> 0 | J23: =Data!J22 -> 20.686911 | K23: =IF(K22="Driver Change?",FALSE,IF((A22<>A23),TRUE,FALSE)) -> FALSE | L23: =IF(L22="Date Change?",FALSE,IF(AND(INT(F22)<>INT(F23),F23<>""),TRUE,FALSE)) -> FALSE | M23: =IF(ISNUMBER(SEARCH("YM",G23)),J23,0) -> 20.686911 | N23: =IF(OR(K23, L23),0,IF(AND(M23>0,ISNUMBER(SEARCH("YM",N22))=FALSE),J23+N22,IF(ISNUMBER(SEARCH("YM",N22))=TRUE,M23,N22))) -> 20.686911 | O23: =ISNUMBER(SEARCH("YM",G23)) -> TRUE | P23: =IF(N23>Summary!$B$9,TRUE,FALSE) -> TRUE | Q23: =IF(AND(O23, P23), 1, 0) -> 1 | R23: =IF(Q23=1, 'Excessive YM Events'!$J$22, "") -> **Excessive YM | S23: =IF(Data!L22=0,"",Data!L22)
... A140: =Data!H139 -> Driver2 | B140: =Data!F139 -> FirstName2 | C140: =Data!G139 -> LastName2 | D140: =Data!D139 -> Vehicle2 | E140: =TEXT(INT(Data!A139),"mmm dd, yyyy") -> May 08, 2020 | F140: =Data!A139 -> 43959.862 | G140: =Data!B139 -> ON | H140: =IF(ISNUMBER(SEARCH("YM",G140)),"YM","NOT") -> NOT | I140: =Data!C139 -> 0 | J140: =Data!J139 -> 0 | K140: =IF(K139="Driver Change?",FALSE,IF((A139<>A140),TRUE,FALSE)) -> FALSE | L140: =IF(L139="Date Change?",FALSE,IF(AND(INT(F139)<>INT(F140),F140<>""),TRUE,FALSE)) -> FALSE | M140: =IF(ISNUMBER(SEARCH("YM",G140)),J140,0) -> 0 | N140: =IF(OR(K140, L140),0,IF(AND(M140>0,ISNUMBER(SEARCH("YM",N139))=FALSE),J140+N139,IF(ISNUMBER(SEARCH("YM",N139))=TRUE,M140,N139))) -> 14.275276 | O140: =ISNUMBER(SEARCH("YM",G140)) -> FALSE | P140: =IF(N140>Summary!$B$9,TRUE,FALSE) -> TRUE | Q140: =IF(AND(O140, P140), 1, 0) -> 0 | R140: =IF(Q140=1, 'Excessive YM Events'!$J$22, "") | S140: =IF(Data!L139=0,"",Data!L139) -> 43961.685

Sheet Data
A1: CompanyName | B1: ABC Company
A2: RunDate | B2: 43961.708
A3: FromDate | B3: 43954
A4: ToDate | B4: 43961
A5: DistanceUnit | B5: miles
A6: SpeedUnit | B6: miles/h
A7: SendReport | B7: TRUE
A8: LastModifiedUser | B8: **<No User>
A9: Language | B9: en
A10: DutyStatusDateTime | B10: DutyStatusStatus | C10: DutyStatusDetailDuration | D10: .StatusLog.Device.DeviceName | E10: .StatusLog.Device.DeviceGroup | F10: .StatusLog.Driver.UserFirstName | G10: .StatusLog.Driver.UserLastName | H10: .StatusLog.Driver.UserName | I10: .Driver.DriverGroup | J10: DutyStatusDetailDistance | K10: DutyStatusDetailAnnotations | L10: DutyStatusVerifyDateTime
A11: 43954 | B11: D | C11: 1.2951389 | D11: Vehicle1 | E11: Vehicle Group1 | F11: FirstName1 | G11: LastName1 | H11: Driver1 | J11: 2.4854848 | L11: 43956.862
A12: 43955.295 | B12: ON | C12: 0.011138194 | D12: Vehicle1 | E12: Vehicle Group1 | F12: FirstName1 | G12: LastName1 | H12: Driver1 | L12: 43956.286
A13: 43955.304 | B13: OFF | D13: Vehicle1 | E13: Vehicle Group1 | F13: FirstName1 | G13: LastName1 | H13: Driver1 | L13: 43956.286
A14: 43955.306 | B14: D | C14: 0.00045902778 | D14: Vehicle1 | E14: Vehicle Group1 | F14: FirstName1 | G14: LastName1 | H14: Driver1 | J14: 0.88891089 | L14: 43956.286
A15: 43955.307 | B15: ON | C15: 0.032361111 | D15: Vehicle1 | E15: Vehicle Group1 | F15: FirstName1 | G15: LastName1 | H15: Driver1 | J15: 0.008041773 | L15: 43956.286
A16: 43955.339 | B16: D | C16: 2.9050926e-05 | D16: Vehicle1 | E16: Vehicle Group1 | F16: FirstName1 | G16: LastName1 | H16: Driver1 | J16: 0.93382579 | L16: 43956.286
A17: 43955.339 | B17: ON | C17: 0.021591319 | D17: Vehicle1 | E17: Vehicle Group1 | F17: FirstName1 | G17: LastName1 | H17: Driver1 | J17: 0 | L17: 43956.286
A18: 43955.361 | B18: D | C18: 0.011467789 | D18: Vehicle1 | E18: Vehicle Group1 | F18: FirstName1 | G18: LastName1 | H18: Driver1 | J18: 0.7638365 | L18: 43956.286
A19: 43955.372 | B19: ON | C19: 0.0309314 | D19: Vehicle1 | E19: Vehicle Group1 | F19: FirstName1 | G19: LastName1 | H19: Driver1 | J19: 0.0081987698 | L19: 43956.286
A20: 43955.403 | B20: D | C20: 0.057890162 | D20: Vehicle1 | E20: Vehicle Group1 | F20: FirstName1 | G20: LastName1 | H20: Driver1 | J20: 6.1095295 | L20: 43956.286
A21: 43955.461 | B21: ON | C21: 0.20180706 | D21: Vehicle1 | E21: Vehicle Group1 | F21: FirstName1 | G21: LastName1 | H21: Driver1 | J21: 0.015320825 | L21: 43956.286
A22: 43955.503 | B22: YM | D22: Vehicle1 | E22: Vehicle Group1 | F22: FirstName1 | G22: LastName1 | H22: Driver1 | J22: 20.686911
A23: 43955.544 | B23: ON | D23: Vehicle1 | E23: Vehicle Group1 | F23: FirstName1 | G23: LastName1 | H23: Driver1 | J23: 0
A24: 43955.586 | B24: D | D24: Vehicle1 | E24: Vehicle Group1 | F24: FirstName1 | G24: LastName1 | H24: Driver1 | J24: 18.564384
A25: 43955.628 | B25: ON | D25: Vehicle1 | E25: Vehicle Group1 | F25: FirstName1 | G25: LastName1 | H25: Driver1 | J25: 0
A26: 43955.663 | B26: D | C26: 0.0088922106 | D26: Vehicle1 | E26: Vehicle Group1 | F26: FirstName1 | G26: LastName1 | H26: Driver1 | J26: 0.097211905 | L26: 43956.286
A27: 43955.672 | B27: ON | C27: 0.0067660069 | D27: Vehicle1 | E27: Vehicle Group1 | F27: FirstName1 | G27: LastName1 | H27: Driver1 | J27: 0 | L27: 43956.286
A28: 43955.678 | B28: D | C28: 0.07855162 | D28: Vehicle1 | E28: Vehicle Group1 | F28: FirstName1 | G28: LastName1 | H28: Driver1 | J28: 30.634232 | L28: 43956.286
A29: 43955.72 | B29: ON | D29: Vehicle1 | E29: Vehicle Group1 | F29: FirstName1 | G29: LastName1 | H29: Driver1 | J29: 0.010922249
A30: 43955.757 | B30: D | C30: 0.023161343 | D30: Vehicle1 | E30: Vehicle Group1 | F30: FirstName1 | G30: LastName1 | H30: Driver1 | J30: 46.344536 | L30: 43956.286
A31: 43955.78 | B31: ON | C31: 0.0815625 | D31: Vehicle1 | E31: Vehicle Group1 | F31: FirstName1 | G31: LastName1 | H31: Driver1 | J31: 0 | L31: 43956.286
A32: 43955.822 | B32: D | D32: Vehicle1 | E32: Vehicle Group1 | F32: FirstName1 | G32: LastName1 | H32: Driver1 | J32: 18.876789
A33: 43955.862 | B33: ON | C33: 0.00046631944 | D33: Vehicle1 | E33: Vehicle Group1 | F33: FirstName1 | G33: LastName1 | H33: Driver1 | J33: 0 | L33: 43956.286
A34: 43955.862 | B34: D | C34: 0.42042488 | D34: Vehicle1 | E34: Vehicle Group1 | F34: FirstName1 | G34: LastName1 | H34: Driver1 | J34: 1.0338554 | L34: 43956.286
A35: 43955.862 | B35: ON | D35: Vehicle1 | E35: Vehicle Group1 | F35: FirstName1 | G35: LastName1 | H35: Driver1 | J35: 0 | L35: 43956.286
A36: 43956.283 | B36: D | C36: 0.010052512 | D36: Vehicle1 | E36: Vehicle Group1 | F36: FirstName1 | G36: LastName1 | H36: Driver1 | J36: 2.2360694 | L36: 43956.861
A37: 43956.293 | B37: ON | C37: 0.00072295139 | D37: Vehicle1 | E37: Vehicle Group1 | F37: FirstName1 | G37: LastName1 | H37: Driver1 | J37: 0.022216471 | L37: 43956.861
A38: 43956.293 | B38: D | C38: 0.16371316 | D38: Vehicle1 | E38: Vehicle Group1 | F38: FirstName1 | G38: LastName1 | H38: Driver1 | J38: 5.8045483 | L38: 43956.861
A39: 43956.335 | B39: ON | D39: Vehicle1 | E39: Vehicle Group1 | F39: FirstName1 | G39: LastName1 | H39: Driver1 | J39: 0.0094726877
A40: 43956.377 | B40: D | D40: Vehicle1 | E40: Vehicle Group1 | F40: FirstName1 | G40: LastName1 | H40: Driver1 | J40: 1.6062226
...

Sheet Languages
A1: English | B1: French | C1: Spanish | D1: German | E1: Japanese | F1: Polish | G1: Portuguese-Brazil | H1: Dutch | I1: Italian | J1: Simplified Chinese
A2: **Driver | B2: Conducteur | C2: Conductor | D2: Fahrer | E2: ドライバー | F2: Kierowca | G2: Motorista | H2: Chauffeur | I2: Conducente | J2: 驾驶员
A3: **Date | B3: Date | C3: Fecha | D3: Datum | E3: データ | F3: Data | G3: Data | H3: Datum | I3: Data | J3: 日期
A4: **Status | B4: État | C4: Estado | D4: Status | E4: ステータス | F4: Status | G4: Status | H4: Status | I4: Stato | J4: 状态
A5: **Device | B5: Dispositif | C5: Dispositivo | D5: Gerät | E5: デバイス | F5: Urzadzenie | G5: Dispositivo | H5: Apparaat | I5: Dispositivo | J5: 设备
A6: **Co-drivers | B6: Co-chauffeurs | C6: Copiloto | D6: Beifahrer | E6: 補助ドライバー | F6: Wspólkierowcy | G6: Comotoristas | H6: Tweede chauffeurs | I6: Secondi conducenti | J6: 副驾驶
A7: **Trailers | B7: Gros porteurs | C7: Remolques | D7: Anhänger | E7: トレーラー | F7: Przyczepy | G7: Reboques | H7: Aanhangers | I7: Rimorchi | J7: 拖车
A8: **Longitude | B8: Longitude | C8: Longitud | D8: Längengrad | E8: 経度 | F8: Dlugosc geograficzna | G8: Longitude | H8: Lengtegraad | I8: Longitudine | J8: 经度
A9: **Latitude | B9: Latitude | C9: Latitud | D9: Breitengrad | E9: 緯度 | F9: Szerokosc geograficzna | G9: Latitude | H9: Breedtegraad | I9: Latitudine | J9: 纬度
A10: **Address | B10: Adresse | C10: Dirección | D10: Adresse | E10: 住所 | F10: Adres | G10: Endereço | H10: Adres | I10: Indirizzo | J10: 地址
A11: **Odometer | B11: Odomètre | C11: Odómetro | D11: Kilometerstand | E11: オドメータ | F11: Licznik kilometrów | G11: Hodômetro | H11: Kilometerteller | I11: Contachilometri | J11: 里程表
A12: **Duration | B12: durée | C12: duración | D12: Dauer | E12: 期間 | F12: Czas trwania | G12: duração | H12: duur | I12: durata | J12: 时长
... A25: **Shipments | B25: Expéditions | C25: Envíos | D25: Lieferungen | E25: 出荷物 | F25: Wysyłki | G25: Remessas | H25: Zendingen | I25: Spedizioni | J25: 发运
A26: **Driver in Excessive YM
A27: **Days
A28: **Occurances
A29: **Max YM Distance over
A30: **Drivers In Excessive YM
A31: **YM Distance for the date
A32: **Excessive YM Log
A33: **Excessive YM
A34: **Change the Maximum alowed YM value based on your company Policy.
A35: **This report allows the carrier to flag drivers who exceed a customizable excessive YM threshold. The excessive YM threshold can be modified in cell B9.
A36: **Vehicle
A37: **From:
... A45: **YM Distance
