Workbook
Name AllData: Report!$A$9:$H$96

Sheet Report
A1: **HOS Violations | D1: =Data!B2 -> 44013.473
A2: =Data!B1 -> ABC Company
A4: **Date | D4: **Total Violations | E4: =COUNTIF(G:G,1) -> 87
A5: **From | B5: =Data!B3 -> 43983.473
A6: **To | B6: =Data!B4 -> 44013.473
A7: **Days | B7: =B6-B5 -> 30
A9: **Driver | B9: **Driver Group | C9: **Start Date | D9: **End Date | E9: **Driving Duration | F9: **Type | G9: **Count | H9: **Reason
A10: =Data!A10 -> Driver A | B10: =Data!C10 -> Entire Organization | C10: =Data!D10 -> 43103.844 | D10: =IF(ISBLANK(Data!E10),"Ongoing",TEXT(Data!E10,"mmm DD, yyyy h:mm:ss AM/PM")) -> Ongoing | E10: =Data!F10 -> 909.58715 | F10: =Data!G10 -> Rest | G10: =IF(NOT(ISBLANK(H10)),1,0) -> 1 | H10: =Data!H10 -> Driving after more than 8-hour rest limit violation
A11: =Data!A11 -> Driver A | B11: =Data!C11 -> Entire Organization | C11: =Data!D11 -> 43103.969 | D11: =IF(ISBLANK(Data!E11),"Ongoing",TEXT(Data!E11,"mmm DD, yyyy h:mm:ss AM/PM")) -> Ongoing | E11: =Data!F11 -> 909.46215 | F11: =Data!G11 -> Driving | G11: =IF(NOT(ISBLANK(H11)),1,0) -> 1 | H11: =Data!H11 -> Maximum 11-hour driving limit violation
A12: =Data!A12 -> Driver A | B12: =Data!C12 -> Entire Organization | C12: =Data!D12 -> 43104.094 | D12: =IF(ISBLANK(Data!E12),"Ongoing",TEXT(Data!E12,"mmm DD, yyyy h:mm:ss AM/PM")) -> Ongoing | E12: =Data!F12 -> 909.33715 | F12: =Data!G12 -> Workday | G12: =IF(NOT(ISBLANK(H12)),1,0) -> 1 | H12: =Data!H12 -> Maximum 14-hour workday limit violation
A13: =Data!A13 -> Driver A | B13: =Data!C13 -> Entire Organization | C13: =Data!D13 -> 44009.417 | D13: =IF(ISBLANK(Data!E13),"Ongoing",TEXT(Data!E13,"mmm DD, yyyy h:mm:ss AM/PM")) -> Ongoing | E13: =Data!F13 -> 23.487493 | F13: =Data!G13 -> Driving | G13: =IF(NOT(ISBLANK(H13)),1,0) -> 1 | H13: =Data!H13 -> Maximum 11 hour driving limit violation
A14: =Data!A14 -> Driver B | B14: =Data!C14 -> Entire Organization | C14: =Data!D14 -> 43988.673 | D14: =IF(ISBLANK(Data!E14),"Ongoing",TEXT(Data!E14,"mmm DD, yyyy h:mm:ss AM/PM")) -> Jun 08, 2020 8:22:27 AM | E14: =Data!F14 -> 0.041075081 | F14: =Data!G14 -> Rest | G14: =IF(NOT(ISBLANK(H14)),1,0) -> 1 | H14: =Data!H14 -> Driving after more than 8-hour rest limit violation
A15: =Data!A15 -> Driver C | B15: =Data!C15 -> Entire Organization | C15: =Data!D15 -> 43968.657 | D15: =IF(ISBLANK(Data!E15),"Ongoing",TEXT(Data!E15,"mmm DD, yyyy h:mm:ss AM/PM")) -> Jun 04, 2020 8:32:44 AM | E15: =Data!F15 -> 0.049925556 | F15: =Data!G15 -> Cycle | G15: =IF(NOT(ISBLANK(H15)),1,0) -> 1 | H15: =Data!H15 -> Maximum 70 hour(s) on duty in 8 days violation
A16: =Data!A16 -> Driver C | B16: =Data!C16 -> Entire Organization | C16: =Data!D16 -> 43980.529 | D16: =IF(ISBLANK(Data!E16),"Ongoing",TEXT(Data!E16,"mmm DD, yyyy h:mm:ss AM/PM")) -> Jun 02, 2020 6:30:00 PM | E16: =Data!F16 -> 0.024191516 | F16: =Data!G16 -> Workday | G16: =IF(NOT(ISBLANK(H16)),1,0) -> 1 | H16: =Data!H16 -> Maximum 14-hour workday limit violation
A17: =Data!A17 -> Driver C | B17: =Data!C17 -> Entire Organization | C17: =Data!D17 -> 43980.529 | D17: =IF(ISBLANK(Data!E17),"Ongoing",TEXT(Data!E17,"mmm DD, yyyy h:mm:ss AM/PM")) -> Jun 02, 2020 6:30:00 PM | E17: =Data!F17 -> 0.024191516 | F17: =Data!G17 -> Rest | G17: =IF(NOT(ISBLANK(H17)),1,0) -> 1 | H17: =Data!H17 -> Driving after more than 8-hour rest limit violation
A18: =Data!A18 -> Driver C | B18: =Data!C18 -> Entire Organization | C18: =Data!D18 -> 43993.768 | D18: =IF(ISBLANK(Data!E18),"Ongoing",TEXT(Data!E18,"mmm DD, yyyy h:mm:ss AM/PM")) -> Jun 12, 2020 12:26:44 AM | E18: =Data!F18 -> 0.001344375 | F18: =Data!G18 -> Cycle | G18: =IF(NOT(ISBLANK(H18)),1,0) -> 1 | H18: =Data!H18 -> Maximum 70 hour(s) on duty in 8 days violation
A19: =Data!A19 -> Driver C | B19: =Data!C19 -> Entire Organization | C19: =Data!D19 -> 44000.679 | D19: =IF(ISBLANK(Data!E19),"Ongoing",TEXT(Data!E19,"mmm DD, yyyy h:mm:ss AM/PM")) -> Ongoing | E19: =Data!F19 -> 0.057834444 | F19: =Data!G19 -> Cycle | G19: =IF(NOT(ISBLANK(H19)),1,0) -> 1 | H19: =Data!H19 -> Maximum 70 hour(s) on duty in 8 days violation
A20: =Data!A20 -> Driver C | B20: =Data!C20 -> Entire Organization | C20: =Data!D20 -> 44000.679 | D20: =IF(ISBLANK(Data!E20),"Ongoing",TEXT(Data!E20,"mmm DD, yyyy h:mm:ss AM/PM")) -> Ongoing | E20: =Data!F20 -> 0.057834444 | F20: =Data!G20 -> Workday | G20: =IF(NOT(ISBLANK(H20)),1,0) -> 1 | H20: =Data!H20 -> Maximum 14-hour workday limit violation
A21: =Data!A21 -> Driver C | B21: =Data!C21 -> Entire Organization | C21: =Data!D21 -> 44000.679 | D21: =IF(ISBLANK(Data!E21),"Ongoing",TEXT(Data!E21,"mmm DD, yyyy h:mm:ss AM/PM")) -> Ongoing | E21: =Data!F21 -> 0.057834444 | F21: =Data!G21 -> Rest | G21: =IF(NOT(ISBLANK(H21)),1,0) -> 1 | H21: =Data!H21 -> Driving after more than 8-hour rest limit violation
... A96: =Data!A96 -> Driver G | B96: =Data!C96 -> Entire Organization | C96: =Data!D96 -> 44005.525 | D96: =IF(ISBLANK(Data!E96),"Ongoing",TEXT(Data!E96,"mmm DD, yyyy h:mm:ss AM/PM")) -> Jun 23, 2020 1:06:03 PM | E96: =Data!F96 -> 0.020742627 | F96: =Data!G96 -> Rest | G96: =IF(NOT(ISBLANK(H96)),1,0) -> 1 | H96: =Data!H96 -> Driving after more than 5-hour rest limit violation

Sheet Total Violations
A1: **HOS Violations | C1: =Data!B2 -> 44013.473
A2: =Data!B1 -> ABC Company
A4: **Date
A5: **From | B5: =Data!B3 -> 43983.473
A6: **To | B6: =Data!B4 -> 44013.473
A7: **Days | B7: =B6-B5 -> 30
A9: **Total Violations | B9: =Report!E4 -> 87
C14: =Report!E4 -> 87

Sheet Summary
A1: **HOS Violations | C1: =Data!B2 -> 44013.473
A2: =Data!B1 -> ABC Company
A4: **Date
A5: **From | B5: =Data!B3 -> 43983.473
A6: **To | B6: =Data!B4 -> 44013.473
A7: **Days | B7: =B6-B5 -> 30
A9: **Driver | B9: **Type | C9: **Reason | D9: **Total HOS Violations
A10: Driver A | B10: Driving | C10: Maximum 11 hour driving limit violation | D10: 1
A11: Driver A | B11: Driving | C11: Maximum 11-hour driving limit violation | D11: 1
A12: Driver A | B12: Rest | C12: Driving after more than 8-hour rest limit violation | D12: 1
A13: Driver A | B13: Workday | C13: Maximum 14-hour workday limit violation | D13: 1
A14: Driver B | B14: Rest | C14: Driving after more than 8-hour rest limit violation | D14: 1
A15: Driver C | B15: Cycle | C15: Maximum 70 hour(s) on duty in 8 days violation | D15: 3
A16: Driver C | B16: Rest | C16: Driving after more than 8-hour rest limit violation | D16: 2
A17: Driver C | B17: Workday | C17: Maximum 14-hour workday limit violation | D17: 2
A18: Driver D | B18: Cycle | C18: Maximum 70 hour(s) on duty in 7 days violation | D18: 1
A19: Driver D | B19: Driving | C19: Maximum 15-hour driving limit violation | D19: 1
A20: Driver D | B20: Duty | C20: Maximum 20-hour on-duty limit violation | D20: 1
A21: Driver E | B21: Cycle | C21: Maximum 60 hour(s) on duty in 7 days violation | D21: 1
... A41: Driver G | B41: Rest | C41: Driving after more than 5-hour rest limit violation | D41: 3
A42: Grand Total | D42: 87

Sheet Details
A1: **HOS Violations | C1: =Data!B2 -> 44013.473
A2: =Data!B1 -> ABC Company
A4: **Date
A5: **From | B5: =Data!B3 -> 43983.473
A6: **To | B6: =Data!B4 -> 44013.473
A7: **Days | B7: =B6-B5 -> 30
A9: **Driver | B9: **Driver Group | C9: **Type | D9: **Reason | E9: **Start Date | F9: **End Date | G9: **Total Driving Duration | H9: **Total HOS Violations
A10: Driver A | B10: Entire Organization | C10: Driving | D10: Maximum 11 hour driving limit violation | E10: 44009.417 | F10: Ongoing | G10: 23.487488 | H10: 1
A11: Driver A | B11: Entire Organization | C11: Driving | D11: Maximum 11-hour driving limit violation | E11: 43103.969 | F11: Ongoing | G11: 909.46215 | H11: 1
A12: Driver A | B12: Entire Organization | C12: Rest | D12: Driving after more than 8-hour rest limit violation | E12: 43103.844 | F12: Ongoing | G12: 909.58715 | H12: 1
A13: Driver A | B13: Entire Organization | C13: Workday | D13: Maximum 14-hour workday limit violation | E13: 43104.094 | F13: Ongoing | G13: 909.33715 | H13: 1
A14: Driver A Total | G14: 2751.8739 | H14: 4
A15: Driver B | B15: Entire Organization | C15: Rest | D15: Driving after more than 8-hour rest limit violation | E15: 43988.673 | F15: Jun 08, 2020 8:22:27 AM | G15: 0.041076389 | H15: 1
A16: Driver B Total | G16: 0.041076389 | H16: 1
A17: Driver C | B17: Entire Organization | C17: Cycle | D17: Maximum 70 hour(s) on duty in 8 days violation | E17: 43968.657 | F17: Jun 04, 2020 8:32:44 AM | G17: 0.049930556 | H17: 1
A18: Driver C | B18: Entire Organization | C18: Cycle | D18: Maximum 70 hour(s) on duty in 8 days violation | E18: 43993.768 | F18: Jun 12, 2020 12:26:44 AM | G18: 0.0013425926 | H18: 1
A19: Driver C | B19: Entire Organization | C19: Cycle | D19: Maximum 70 hour(s) on duty in 8 days violation | E19: 44000.679 | F19: Ongoing | G19: 0.057835648 | H19: 1
A20: Driver C | B20: Entire Organization | C20: Rest | D20: Driving after more than 8-hour rest limit violation | E20: 43980.529 | F20: Jun 02, 2020 6:30:00 PM | G20: 0.024189815 | H20: 1
A21: Driver C | B21: Entire Organization | C21: Rest | D21: Driving after more than 8-hour rest limit violation | E21: 44000.679 | F21: Ongoing | G21: 0.057835648 | H21: 1
A22: Driver C | B22: Entire Organization | C22: Workday | D22: Maximum 14-hour workday limit violation | E22: 43980.529 | F22: Jun 02, 2020 6:30:00 PM | G22: 0.024189815 | H22: 1
A23: Driver C | B23: Entire Organization | C23: Workday | D23: Maximum 14-hour workday limit violation | E23: 44000.679 | F23: Ongoing | G23: 0.057835648 | H23: 1
A24: Driver C Total | G24: 0.27315972 | H24: 7
A25: Driver D | B25: Entire Organization | C25: Cycle | D25: Maximum 70 hour(s) on duty in 7 days violation | E25: 43987.917 | F25: Ongoing | G25: 4.0876852 | H25: 1
A26: Driver D | B26: Entire Organization | C26: Driving | D26: Maximum 15-hour driving limit violation | E26: 43986.203 | F26: Ongoing | G26: 5.801713 | H26: 1
A27: Driver D | B27: Entire Organization | C27: Duty | D27: Maximum 20-hour on-duty limit violation | E27: 43985.578 | F27: Ongoing | G27: 6.426713 | H27: 1
A28: Driver D Total | G28: 16.316111 | H28: 3
A29: Driver E | B29: Entire Organization | C29: Cycle | D29: Maximum 60 hour(s) on duty in 7 days violation | E29: 43992.335 | F29: Jun 18, 2020 8:00:00 PM | G29: 0.19488426 | H29: 1
A30: Driver E | B30: Entire Organization | C30: Cycle | D30: Maximum 70 hour(s) on duty in 7 days violation | E30: 43995.631 | F30: Jun 18, 2020 9:46:15 AM | G30: 0.061770833 | H30: 1
A31: Driver E | B31: Entire Organization | C31: Cycle | D31: Maximum 70 hour(s) on duty in 7 days violation | E31: 43995.788 | F31: Jun 18, 2020 8:00:00 PM | G31: 0.23230324 | H31: 1
A32: Driver E | B32: Entire Organization | C32: Cycle | D32: Maximum 70 hour(s) on duty in 7 days violation | E32: 44008.519 | F32: Ongoing | G32: 0.27021991 | H32: 1
A33: Driver E | B33: Entire Organization | C33: Cycle | D33: Maximum 70 hour(s) on duty in 8 days violation | E33: 43970.702 | F33: Jun 19, 2020 8:51:34 PM | G33: 0.61055556 | H33: 1
A34: Driver E | B34: Entire Organization | C34: CycleRest | D34: Driving without 24-hour consecutive off-duty in the preceding 14 days | E34: 43995.631 | F34: Jun 16, 2020 7:37:41 AM | G34: 0.061770833 | H34: 1
A35: Driver E | B35: Entire Organization | C35: CycleRest | D35: Driving without 24-hour consecutive off-duty in the preceding 14 days | E35: 43995.788 | F35: Jun 16, 2020 7:37:41 AM | G35: 0.15015046 | H35: 1
A36: Driver E | B36: Entire Organization | C36: DailyDuty | D36: Maximum 14 hour(s) on-duty per day violation | E36: 43995.788 | F36: Jun 13, 2020 8:32:01 PM | G36: 0.036493056 | H36: 1
A37: Driver E | B37: Entire Organization | C37: DailyDuty | D37: Maximum 14 hour(s) on-duty per day violation | E37: 43996.989 | F37: Jun 14, 2020 11:58:15 PM | G37: 0.0093865741 | H37: 1
A38: Driver E | B38: Entire Organization | C38: DailyDuty | D38: Maximum 14 hour(s) on-duty per day violation | E38: 44006.71 | F38: Jun 24, 2020 9:52:59 PM | G38: 0.063888889 | H38: 1
A39: Driver E | B39: Entire Organization | C39: DailyDuty | D39: Maximum 14 hour(s) on-duty per day violation | E39: 44008.661 | F39: Jun 26, 2020 4:18:19 PM | G39: 0.018703704 | H39: 1
A40: Driver E | B40: Entire Organization | C40: DailyDuty | D40: Maximum 14 hour(s) on-duty per day violation | E40: 44009.583 | F40: Jun 27, 2020 4:57:35 PM | G40: 0.067268519 | H40: 1
... A88: Driver E | B88: Entire Organization | C88: Workday | D88: Maximum 16-hour workday limit violation | E88: 44008.519 | F88: Ongoing | G88: 0.27021991 | H88: 1
A89: Driver E Total | G89: 4.8745833 | H89: 60
...

Sheet Graph
A1: HOS Violations
A2: =Data!B1 -> ABC Company
A4: Date
A5: From | B5: =Data!B3 -> 43983.473
A6: To | B6: =Data!B4 -> 44013.473
A7: Days | B7: =B6-B5 -> 30
A9: **Reason | B9: **Total HOS Violations
A10: Driving after more than 8-hour rest limit violation | B10: 16
A11: Minimum 10-hour off-duty per day violation | B11: 11
A12: Maximum 14-hour workday limit violation | B12: 8
A13: Minimum 2-hour rest per day violation | B13: 7
A14: Maximum 16-hour workday limit violation | B14: 7
A15: Maximum 14-hour on-duty limit violation | B15: 7
A16: Maximum 14 hour(s) on-duty per day violation | B16: 6
A17: Maximum 70 hour(s) on duty in 7 days violation | B17: 4
A18: Maximum 70 hour(s) on duty in 8 days violation | B18: 4
A19: Driving after more than 5-hour rest limit violation | B19: 3
A20: Maximum 11-hour driving limit violation | B20: 2
A21: Maximum 60 hour(s) on duty in 7 days violation | B21: 2
... A31: Grand Total | B31: 87

Sheet Graph 2
A1: HOS Violations
A2: =Data!B1 -> ABC Company
A4: Date
A5: From | B5: =Data!B3 -> 43983.473
A6: To | B6: =Data!B4 -> 44013.473
A7: Days | B7: =B6-B5 -> 30
A9: **Highest HOS Violations
A10: **Driver | B10: **Total HOS Violations
A11: Driver E | B11: 60
A12: Driver C | B12: 7
A13: Driver F | B13: 6
A14: Driver G | B14: 6
A15: Driver A | B15: 4
A16: Driver D | B16: 3
A17: Driver B | B17: 1
A18: Grand Total | B18: 87

Sheet Languages
A1: English | B1: French | C1: Spanish | D1: German | E1: Japanese | F1: Polish | G1: Portuguese-Brazil | H1: Dutch | I1: Italian | J1: Simplified Chinese
A2: **Driver | B2: Conducteur | C2: Conductor | D2: Fahrer | E2: ドライバー | F2: Kierowca | G2: Motorista | H2: Chauffeur | I2: Conducente | J2: 驾驶员
A3: **Start Date | B3: Date de début | C3: Fecha de inicio | D3: Startdatum | E3: 開始日 | F3: Data rozpoczecia | G3: Data de início | H3: Startdatum | I3: Data iniziale | J3: 开始日期
A4: **End Date | B4: Date de fin | C4: Fecha de finalización | D4: Enddatum | E4: 終了日 | F4: Data zakonczenia | G4: Data final | H4: Einddatum | I4: Data di fine | J4: 结束日期
A5: **Driving Duration | B5: Durée de conduite | C5: Duración de conducción | D5: Fahrtendauer | E5: 運転期間 | F5: Czas trwania jazdy | G5: Duração da condução | H5: Rijduur | I5: Durata di guida | J5: 驾驶时长
A6: **Type | B6: Type | C6: Tipo | D6: Typ | E6: 種類 | F6: Typ | G6: Tipo | H6: Type | I6: Tipo | J6: 类型
A7: **Reason | B7: Raison | C7: Motivo | D7: Grund | E7: 理由 | F7: Powód | G7: Razão | H7: Reden | I7: Ragione | J7: 原因
A8: **HOS Driver Logs | B8: Registre HDS du chauffeur | C8: Registros de horas de servicio del conductor | D8: Fahrerlenkzeit (HOS) Protokolle | E8: HOS ドライバーログ | F8: Dzienniki czasu pracy kierowców | G8: Registros do motorista de HOS | H8: DU-chauffeurslogboeken | I8: Registri dei conducenti HOS | J8: HOS 驾驶员日志
A9: **Summary | B9: Sommaire | C9: Resumen | D9: Zusammenfassung | E9: 走行データ | F9: Podsumowanie | G9: Resumo | H9: Overzicht | I9: Riassunto | J9: 汇总
A10: **Created | B10: Créé | C10: Creado | D10: Angelegt | E10: 作成済 | F10: Utworzono | G10: Criado em | H10: Aangemaakt | I10: Creato | J10: 创建日期
A11: **From | B11: À partir de | C11: De | D11: Von | E11: から | F11: Od | G11: De | H11: Van | I11: Da | J11: 自
A12: **To | B12: Pour | C12: Para | D12: An | E12: へ | F12: Do | G12: Para | H12: Aan | I12: A | J12: 至
... A15: **Time Zone | B15: Fuseau horaire | C15: Huso horario | D15: Zeitzone | E15: タイムゾーン | F15: Strefa czasowa | G15: Zona horária | H15: Tijdzone | I15: Fuso orario | J15: 时区
A16: **Count
A17: **Driver Group
A18: **HOS Violations
A19: **Date
A20: **Days
A21: **Total HOS Violations
A22: **Highest HOS Violations
A23: **HOS Violations by Reason
A24: **Total Driving Duration

Sheet Data
A1: CompanyName | B1: ABC Company
A2: RunDate | B2: 44013.473
A3: FromDate | B3: 43983.473
A4: ToDate | B4: 44013.473
A5: DistanceUnit | B5: miles
A6: SpeedUnit | B6: mph
A7: SendReport | B7: TRUE
A8: LastModifiedUser | B8: mygproduct@geotab.com
A9: .Driver.UserName | B9: .Driver.UserId | C9: .Driver.DriverGroup | D9: HosViolationStartDateTime | E9: HosViolationEndDateTime | F9: HosViolationDrivingDuration | G9: HosViolationType | H9: HosViolationReason
A10: Driver A | B10: b41B4DC10 | C10: Entire Organization | D10: 43103.844 | F10: 909.58715 | G10: Rest | H10: Driving after more than 8-hour rest limit violation
A11: Driver A | B11: b41B4DC10 | C11: Entire Organization | D11: 43103.969 | F11: 909.46215 | G11: Driving | H11: Maximum 11-hour driving limit violation
A12: Driver A | B12: b41B4DC10 | C12: Entire Organization | D12: 43104.094 | F12: 909.33715 | G12: Workday | H12: Maximum 14-hour workday limit violation
A13: Driver A | B13: b41B4DC10 | C13: Entire Organization | D13: 44009.417 | F13: 23.487493 | G13: Driving | H13: Maximum 11 hour driving limit violation
A14: Driver B | B14: b41B4DC88 | C14: Entire Organization | D14: 43988.673 | E14: 43990.349 | F14: 0.041075081 | G14: Rest | H14: Driving after more than 8-hour rest limit violation
A15: Driver C | B15: b41B4DD86 | C15: Entire Organization | D15: 43968.657 | E15: 43986.356 | F15: 0.049925556 | G15: Cycle | H15: Maximum 70 hour(s) on duty in 8 days violation
A16: Driver C | B16: b41B4DD86 | C16: Entire Organization | D16: 43980.529 | E16: 43984.771 | F16: 0.024191516 | G16: Workday | H16: Maximum 14-hour workday limit violation
A17: Driver C | B17: b41B4DD86 | C17: Entire Organization | D17: 43980.529 | E17: 43984.771 | F17: 0.024191516 | G17: Rest | H17: Driving after more than 8-hour rest limit violation
A18: Driver C | B18: b41B4DD86 | C18: Entire Organization | D18: 43993.768 | E18: 43994.019 | F18: 0.001344375 | G18: Cycle | H18: Maximum 70 hour(s) on duty in 8 days violation
A19: Driver C | B19: b41B4DD86 | C19: Entire Organization | D19: 44000.679 | F19: 0.057834444 | G19: Cycle | H19: Maximum 70 hour(s) on duty in 8 days violation
A20: Driver C | B20: b41B4DD86 | C20: Entire Organization | D20: 44000.679 | F20: 0.057834444 | G20: Workday | H20: Maximum 14-hour workday limit violation
A21: Driver C | B21: b41B4DD86 | C21: Entire Organization | D21: 44000.679 | F21: 0.057834444 | G21: Rest | H21: Driving after more than 8-hour rest limit violation
A22: Driver D | B22: b41B4DDC8 | C22: Entire Organization | D22: 43985.578 | F22: 6.4267094 | G22: Duty | H22: Maximum 20-hour on-duty limit violation
A23: Driver D | B23: b41B4DDC8 | C23: Entire Organization | D23: 43986.203 | F23: 5.8017094 | G23: Driving | H23: Maximum 15-hour driving limit violation
A24: Driver D | B24: b41B4DDC8 | C24: Entire Organization | D24: 43987.917 | F24: 4.0876846 | G24: Cycle | H24: Maximum 70 hour(s) on duty in 7 days violation
A25: Driver E | B25: b41B4DDBC | C25: Entire Organization | D25: 43968.272 | E25: 43991.567 | F25: 0.64842272 | G25: Workday | H25: Maximum 14-hour workday limit violation
A26: Driver E | B26: b41B4DDBC | C26: Entire Organization | D26: 43970.702 | E26: 44001.869 | F26: 0.61055917 | G26: Cycle | H26: Maximum 70 hour(s) on duty in 8 days violation
A27: Driver E | B27: b41B4DDBC | C27: Entire Organization | D27: 43972.823 | E27: 43991.567 | F27: 0.15602124 | G27: Workday | H27: Maximum 12-hour workday limit violation
A28: Driver E | B28: b41B4DDBC | C28: Entire Organization | D28: 43972.823 | E28: 44000.833 | F28: 0.024784132 | G28: Driving | H28: Maximum 13 hour driving limit violation
A29: Driver E | B29: b41B4DDBC | C29: Entire Organization | D29: 43979.277 | E29: 43985.384 | F29: 0.26425274 | G29: Rest | H29: Driving after more than 8-hour rest limit violation
A30: Driver E | B30: b41B4DDBC | C30: Entire Organization | D30: 43981.625 | E30: 43991.567 | F30: 0.42485241 | G30: Driving | H30: Maximum 11-hour driving limit violation
A31: Driver E | B31: b41B4DDBC | C31: Entire Organization | D31: 43986.241 | E31: 43986.598 | F31: 0.029982569 | G31: Rest | H31: Driving after more than 8-hour rest limit violation
A32: Driver E | B32: b41B4DDBC | C32: Entire Organization | D32: 43987.236 | E32: 43987.363 | F32: 0.033745324 | G32: Rest | H32: Driving after more than 8-hour rest limit violation
A33: Driver E | B33: b41B4DDBC | C33: Entire Organization | D33: 43988.268 | E33: 43988.519 | F33: 0.0025740394 | G33: Rest | H33: Driving after more than 8-hour rest limit violation
A34: Driver E | B34: b41B4DDBC | C34: Entire Organization | D34: 43989.275 | E34: 43989.347 | F34: 0.0056353009 | G34: Rest | H34: Driving after more than 8-hour rest limit violation
A35: Driver E | B35: b41B4DDBC | C35: Entire Organization | D35: 43990.245 | E35: 43991.425 | F35: 0.061551007 | G35: Rest | H35: Driving after more than 8-hour rest limit violation
A36: Driver E | B36: b41B4DDBC | C36: Entire Organization | D36: 43992.335 | E36: 44000.833 | F36: 0.19488094 | G36: Cycle | H36: Maximum 60 hour(s) on duty in 7 days violation
... A70: Driver E | B70: b41B4DDBC | C70: Entire Organization | D70: 44008 | E70: 44009 | F70: 0 | G70: DailyRest | H70: Minimum 2-hour rest per day violation
A71: Driver E | B71: b41B4DDBC | C71: Entire Organization | D71: 44008.519 | F71: 0.27022418 | G71: Cycle | H71: Maximum 70 hour(s) on duty in 7 days violation
A72: Driver E | B72: b41B4DDBC | C72: Entire Organization | D72: 44008.519 | F72: 0.27022418 | G72: Duty | H72: Maximum 14-hour on-duty limit violation
A73: Driver E | B73: b41B4DDBC | C73: Entire Organization | D73: 44008.519 | F73: 0.27022418 | G73: Workday | H73: Maximum 16-hour workday limit violation
...
