Workbook
Name AllData: Report!$A$11:$P$152
Name Slicer_Date: #N/A

Sheet Summary
A1: **Unverified Logs | C1: =Data!B2 -> 44032.083
A2: =Data!B1 -> ABC Company
A4: =Report!A4 -> **Date
A5: =Report!A5 -> **From | B5: =Data!B3 -> 44013
A6: =Report!A6 -> **To | B6: =Data!B4 -> 44032
A7: =Report!A7 -> **Days | B7: =B6-B5 -> 19
A9: **Time Zone | B9: =Data!B5 -> America/New_York
A11: Unverified Days | D11: Date
A12: **Driver | B12: **First Name | C12: **Last Name | D12: 44013 | E12: 44015 | F12: 44017 | G12: 44019 | H12: 44020 | I12: 44023 | J12: 44024 | K12: 44025 | L12: 44026 | M12: 44027 | N12: 44028 | O12: 44029 | P12: 44030 | Q12: 44031 | R12: 44032 | S12: Days
A13: Driver A | B13: FirstName A | C13: LastName A | E13: 1 | F13: 0 | G13: 1 | H13: 0 | I13: 1 | J13: 1 | K13: 0 | L13: 1 | M13: 0 | S13: 5
A14: Driver B | B14: FirstName B | C14: LastName B | D14: 0 | M14: 0 | N14: 1 | O14: 0 | P14: 1 | R14: 1 | S14: 3
A15: Driver H | B15: FirstName H | C15: LastName H | G15: 0 | N15: 1 | R15: 1 | S15: 2
A16: Driver K | B16: FirstName K | C16: LastName K | J16: 1 | S16: 1
A17: Driver G | B17: FirstName G | C17: LastName G | Q17: 1 | S17: 1
A18: Driver D | B18: FirstName D | C18: LastName D | L18: 1 | S18: 1
A19: Driver J | B19: FirstName J | C19: LastName J | D19: 0 | Q19: 1 | S19: 1
A20: Driver E | B20: FirstName E | C20: LastName E | R20: 1 | S20: 1
A21: Driver C | B21: FirstName C | C21: LastName C | Q21: 1 | S21: 1
A22: Driver L | B22: FirstName L | C22: LastName L | R22: 1 | S22: 1
A23: Driver M | B23: FirstName M | C23: LastName M | D23: 1 | S23: 1
A24: Driver F | B24: FirstName F | C24: LastName F | N24: 0 | S24: 0

Sheet Details
A1: **Unverified Logs | C1: =Data!B2 -> 44032.083
A2: =Data!B1 -> ABC Company
A4: =Report!A4 -> **Date
A5: =Report!A5 -> **From | B5: =Data!B3 -> 44013
A6: =Report!A6 -> **To | B6: =Data!B4 -> 44032
A7: =Report!A7 -> **Days | B7: =B6-B5 -> 19
A9: **Time Zone | B9: =Data!B5 -> America/New_York
A11: Unverified Days | B11: (All)
A13: **Driver | B13: **First Name | C13: **Last Name | D13: Unverified Dates | E13: Unverified Days
A14: Driver A | B14: FirstName A | C14: LastName A | D14: NA | E14: 0
A15: Driver A | B15: FirstName A | C15: LastName A | D15: 44015 | E15: 1
A16: Driver A | B16: FirstName A | C16: LastName A | D16: 44019 | E16: 1
A17: Driver A | B17: FirstName A | C17: LastName A | D17: 44023 | E17: 1
A18: Driver A | B18: FirstName A | C18: LastName A | D18: 44024 | E18: 1
A19: Driver A | B19: FirstName A | C19: LastName A | D19: 44026 | E19: 1
A20: Driver A Total | E20: 5
A21: Driver B | B21: FirstName B | C21: LastName B | D21: NA | E21: 0
A22: Driver B | B22: FirstName B | C22: LastName B | D22: 44028 | E22: 1
A23: Driver B | B23: FirstName B | C23: LastName B | D23: 44030 | E23: 1
A24: Driver B | B24: FirstName B | C24: LastName B | D24: 44032 | E24: 1
A25: Driver B Total | E25: 3
A26: Driver C | B26: FirstName C | C26: LastName C | D26: NA | E26: 0
A27: Driver C | B27: FirstName C | C27: LastName C | D27: 44031 | E27: 1
A28: Driver C Total | E28: 1
A29: Driver D | B29: FirstName D | C29: LastName D | D29: NA | E29: 0
A30: Driver D | B30: FirstName D | C30: LastName D | D30: 44026 | E30: 1
A31: Driver D Total | E31: 1
A32: Driver E | B32: FirstName E | C32: LastName E | D32: NA | E32: 0
A33: Driver E | B33: FirstName E | C33: LastName E | D33: 44032 | E33: 1
A34: Driver E Total | E34: 1
A35: Driver F | B35: FirstName F | C35: LastName F | D35: NA | E35: 0
A36: Driver F Total | E36: 0
A37: Driver G | B37: FirstName G | C37: LastName G | D37: NA | E37: 0
A38: Driver G | B38: FirstName G | C38: LastName G | D38: 44031 | E38: 1
A39: Driver G Total | E39: 1
A40: Driver H | B40: FirstName H | C40: LastName H | D40: NA | E40: 0
A41: Driver H | B41: FirstName H | C41: LastName H | D41: 44028 | E41: 1
A42: Driver H | B42: FirstName H | C42: LastName H | D42: 44032 | E42: 1
A43: Driver H Total | E43: 2
A44: Driver J | B44: FirstName J | C44: LastName J | D44: NA | E44: 0
...

Sheet Report
A1: **Unverified Logs | C1: =Data!B2 -> 44032.083
A2: =Data!B1 -> ABC Company
A4: **Date
A5: **From | B5: =Data!B3 -> 44013
A6: **To | B6: =Data!B4 -> 44032
A7: **Days | B7: =B6-B5 -> 19
A9: **Time Zone | B9: =Data!B5 -> America/New_York
A11: **Driver | B11: **First Name | C11: **Last Name | D11: Include | E11: Unverified Logs Count | F11: Unverified Days | G11: Verified Days | H11: Unverified Dates | I11: Date | J11: **Log Date and Time | K11: **Status | L11: **Vehicle | M11: Flag for not considered logs | N11: Verify | O11: **Check | P11: **Verify Date
A12: =Data!G12 -> Driver C | B12: =Data!E12 -> FirstName C | C12: =Data!F12 -> LastName C | D12: =IF(OR(A12<>A11, I12<>I11), TRUE, FALSE) -> TRUE | E12: =IF(D12,SUMIFS(O:O,A:A,A12,I:I, I12),"NA") -> 2 | F12: =IF(ISNUMBER(E12), IF(E12>=1, 1, 0), 0) -> 1 | G12: =IF(ISNUMBER(E12), IF(E12>=1, 0, 1), 0) -> 0 | H12: =IF(AND(F12=1,ISNUMBER(SEARCH("consider",O12))=FALSE),I12,"NA") -> 44031 | I12: =INT(Data!A12) -> 44031 | J12: =Data!A12 -> 44031.014 | K12: =Data!B12 -> D | L12: =Data!C12 -> Vehicle C | M12: =IF(OR(K12="D",K12="ON",K12="OFF",K12="SB",K12="YM",K12="PC"), TRUE, FALSE) -> TRUE | N12: =IF(M12=FALSE, 0, IF(O12=0, 1, 0)) -> 1 | O12: =IF(M12=FALSE,"Not Considered",IF(AND(M12,P12<>""),0,1)) -> 0 | P12: =IF(Data!H12=0,"",Data!H12) -> 44037.462
A13: =Data!G13 -> Driver C | B13: =Data!E13 -> FirstName C | C13: =Data!F13 -> LastName C | D13: =IF(OR(A13<>A12, I13<>I12), TRUE, FALSE) -> FALSE | E13: =IF(D13,SUMIFS(O:O,A:A,A13,I:I, I13),"NA") -> NA | F13: =IF(ISNUMBER(E13), IF(E13>=1, 1, 0), 0) -> 0 | G13: =IF(ISNUMBER(E13), IF(E13>=1, 0, 1), 0) -> 0 | H13: =IF(AND(F13=1,ISNUMBER(SEARCH("consider",O13))=FALSE),I13,"NA") -> NA | I13: =INT(Data!A13) -> 44031 | J13: =Data!A13 -> 44031.056 | K13: =Data!B13 -> ON | L13: =Data!C13 -> Vehicle C | M13: =IF(OR(K13="D",K13="ON",K13="OFF",K13="SB",K13="YM",K13="PC"), TRUE, FALSE) -> TRUE | N13: =IF(M13=FALSE, 0, IF(O13=0, 1, 0)) -> 1 | O13: =IF(M13=FALSE,"Not Considered",IF(AND(M13,P13<>""),0,1)) -> 0 | P13: =IF(Data!H13=0,"",Data!H13) -> 44037.462
A14: =Data!G14 -> Driver C | B14: =Data!E14 -> FirstName C | C14: =Data!F14 -> LastName C | D14: =IF(OR(A14<>A13, I14<>I13), TRUE, FALSE) -> FALSE | E14: =IF(D14,SUMIFS(O:O,A:A,A14,I:I, I14),"NA") -> NA | F14: =IF(ISNUMBER(E14), IF(E14>=1, 1, 0), 0) -> 0 | G14: =IF(ISNUMBER(E14), IF(E14>=1, 0, 1), 0) -> 0 | H14: =IF(AND(F14=1,ISNUMBER(SEARCH("consider",O14))=FALSE),I14,"NA") -> NA | I14: =INT(Data!A14) -> 44031 | J14: =Data!A14 -> 44031.563 | K14: =Data!B14 -> D | L14: =Data!C14 -> Vehicle C | M14: =IF(OR(K14="D",K14="ON",K14="OFF",K14="SB",K14="YM",K14="PC"), TRUE, FALSE) -> TRUE | N14: =IF(M14=FALSE, 0, IF(O14=0, 1, 0)) -> 1 | O14: =IF(M14=FALSE,"Not Considered",IF(AND(M14,P14<>""),0,1)) -> 0 | P14: =IF(Data!H14=0,"",Data!H14) -> 44037.462
A15: =Data!G15 -> Driver C | B15: =Data!E15 -> FirstName C | C15: =Data!F15 -> LastName C | D15: =IF(OR(A15<>A14, I15<>I14), TRUE, FALSE) -> FALSE | E15: =IF(D15,SUMIFS(O:O,A:A,A15,I:I, I15),"NA") -> NA | F15: =IF(ISNUMBER(E15), IF(E15>=1, 1, 0), 0) -> 0 | G15: =IF(ISNUMBER(E15), IF(E15>=1, 0, 1), 0) -> 0 | H15: =IF(AND(F15=1,ISNUMBER(SEARCH("consider",O15))=FALSE),I15,"NA") -> NA | I15: =INT(Data!A15) -> 44031 | J15: =Data!A15 -> 44031.565 | K15: =Data!B15 -> OFF | L15: =Data!C15 -> Vehicle C | M15: =IF(OR(K15="D",K15="ON",K15="OFF",K15="SB",K15="YM",K15="PC"), TRUE, FALSE) -> TRUE | N15: =IF(M15=FALSE, 0, IF(O15=0, 1, 0)) -> 1 | O15: =IF(M15=FALSE,"Not Considered",IF(AND(M15,P15<>""),0,1)) -> 0 | P15: =IF(Data!H15=0,"",Data!H15) -> 44037.462
A16: =Data!G16 -> Driver C | B16: =Data!E16 -> FirstName C | C16: =Data!F16 -> LastName C | D16: =IF(OR(A16<>A15, I16<>I15), TRUE, FALSE) -> FALSE | E16: =IF(D16,SUMIFS(O:O,A:A,A16,I:I, I16),"NA") -> NA | F16: =IF(ISNUMBER(E16), IF(E16>=1, 1, 0), 0) -> 0 | G16: =IF(ISNUMBER(E16), IF(E16>=1, 0, 1), 0) -> 0 | H16: =IF(AND(F16=1,ISNUMBER(SEARCH("consider",O16))=FALSE),I16,"NA") -> NA | I16: =INT(Data!A16) -> 44031 | J16: =Data!A16 -> 44031.589 | K16: =Data!B16 -> D | L16: =Data!C16 -> Vehicle C | M16: =IF(OR(K16="D",K16="ON",K16="OFF",K16="SB",K16="YM",K16="PC"), TRUE, FALSE) -> TRUE | N16: =IF(M16=FALSE, 0, IF(O16=0, 1, 0)) -> 0 | O16: =IF(M16=FALSE,"Not Considered",IF(AND(M16,P16<>""),0,1)) -> 1 | P16: =IF(Data!H16=0,"",Data!H16)
A17: =Data!G17 -> Driver C | B17: =Data!E17 -> FirstName C | C17: =Data!F17 -> LastName C | D17: =IF(OR(A17<>A16, I17<>I16), TRUE, FALSE) -> FALSE | E17: =IF(D17,SUMIFS(O:O,A:A,A17,I:I, I17),"NA") -> NA | F17: =IF(ISNUMBER(E17), IF(E17>=1, 1, 0), 0) -> 0 | G17: =IF(ISNUMBER(E17), IF(E17>=1, 0, 1), 0) -> 0 | H17: =IF(AND(F17=1,ISNUMBER(SEARCH("consider",O17))=FALSE),I17,"NA") -> NA | I17: =INT(Data!A17) -> 44031 | J17: =Data!A17 -> 44031.701 | K17: =Data!B17 -> SB | L17: =Data!C17 -> Vehicle C | M17: =IF(OR(K17="D",K17="ON",K17="OFF",K17="SB",K17="YM",K17="PC"), TRUE, FALSE) -> TRUE | N17: =IF(M17=FALSE, 0, IF(O17=0, 1, 0)) -> 0 | O17: =IF(M17=FALSE,"Not Considered",IF(AND(M17,P17<>""),0,1)) -> 1 | P17: =IF(Data!H17=0,"",Data!H17)
A18: =Data!G18 -> Driver D | B18: =Data!E18 -> FirstName D | C18: =Data!F18 -> LastName D | D18: =IF(OR(A18<>A17, I18<>I17), TRUE, FALSE) -> TRUE | E18: =IF(D18,SUMIFS(O:O,A:A,A18,I:I, I18),"NA") -> 2 | F18: =IF(ISNUMBER(E18), IF(E18>=1, 1, 0), 0) -> 1 | G18: =IF(ISNUMBER(E18), IF(E18>=1, 0, 1), 0) -> 0 | H18: =IF(AND(F18=1,ISNUMBER(SEARCH("consider",O18))=FALSE),I18,"NA") -> 44026 | I18: =INT(Data!A18) -> 44026 | J18: =Data!A18 -> 44026.014 | K18: =Data!B18 -> D | L18: =Data!C18 -> Vehicle D | M18: =IF(OR(K18="D",K18="ON",K18="OFF",K18="SB",K18="YM",K18="PC"), TRUE, FALSE) -> TRUE | N18: =IF(M18=FALSE, 0, IF(O18=0, 1, 0)) -> 1 | O18: =IF(M18=FALSE,"Not Considered",IF(AND(M18,P18<>""),0,1)) -> 0 | P18: =IF(Data!H18=0,"",Data!H18) -> 44037.462
A19: =Data!G19 -> Driver D | B19: =Data!E19 -> FirstName D | C19: =Data!F19 -> LastName D | D19: =IF(OR(A19<>A18, I19<>I18), TRUE, FALSE) -> FALSE | E19: =IF(D19,SUMIFS(O:O,A:A,A19,I:I, I19),"NA") -> NA | F19: =IF(ISNUMBER(E19), IF(E19>=1, 1, 0), 0) -> 0 | G19: =IF(ISNUMBER(E19), IF(E19>=1, 0, 1), 0) -> 0 | H19: =IF(AND(F19=1,ISNUMBER(SEARCH("consider",O19))=FALSE),I19,"NA") -> NA | I19: =INT(Data!A19) -> 44026 | J19: =Data!A19 -> 44026.056 | K19: =Data!B19 -> ON | L19: =Data!C19 -> Vehicle D | M19: =IF(OR(K19="D",K19="ON",K19="OFF",K19="SB",K19="YM",K19="PC"), TRUE, FALSE) -> TRUE | N19: =IF(M19=FALSE, 0, IF(O19=0, 1, 0)) -> 1 | O19: =IF(M19=FALSE,"Not Considered",IF(AND(M19,P19<>""),0,1)) -> 0 | P19: =IF(Data!H19=0,"",Data!H19) -> 44037.462
A20: =Data!G20 -> Driver D | B20: =Data!E20 -> FirstName D | C20: =Data!F20 -> LastName D | D20: =IF(OR(A20<>A19, I20<>I19), TRUE, FALSE) -> FALSE | E20: =IF(D20,SUMIFS(O:O,A:A,A20,I:I, I20),"NA") -> NA | F20: =IF(ISNUMBER(E20), IF(E20>=1, 1, 0), 0) -> 0 | G20: =IF(ISNUMBER(E20), IF(E20>=1, 0, 1), 0) -> 0 | H20: =IF(AND(F20=1,ISNUMBER(SEARCH("consider",O20))=FALSE),I20,"NA") -> NA | I20: =INT(Data!A20) -> 44026 | J20: =Data!A20 -> 44026.563 | K20: =Data!B20 -> D | L20: =Data!C20 -> Vehicle D | M20: =IF(OR(K20="D",K20="ON",K20="OFF",K20="SB",K20="YM",K20="PC"), TRUE, FALSE) -> TRUE | N20: =IF(M20=FALSE, 0, IF(O20=0, 1, 0)) -> 1 | O20: =IF(M20=FALSE,"Not Considered",IF(AND(M20,P20<>""),0,1)) -> 0 | P20: =IF(Data!H20=0,"",Data!H20) -> 44037.462
A21: =Data!G21 -> Driver D | B21: =Data!E21 -> FirstName D | C21: =Data!F21 -> LastName D | D21: =IF(OR(A21<>A20, I21<>I20), TRUE, FALSE) -> FALSE | E21: =IF(D21,SUMIFS(O:O,A:A,A21,I:I, I21),"NA") -> NA | F21: =IF(ISNUMBER(E21), IF(E21>=1, 1, 0), 0) -> 0 | G21: =IF(ISNUMBER(E21), IF(E21>=1, 0, 1), 0) -> 0 | H21: =IF(AND(F21=1,ISNUMBER(SEARCH("consider",O21))=FALSE),I21,"NA") -> NA | I21: =INT(Data!A21) -> 44026 | J21: =Data!A21 -> 44026.565 | K21: =Data!B21 -> OFF | L21: =Data!C21 -> Vehicle D | M21: =IF(OR(K21="D",K21="ON",K21="OFF",K21="SB",K21="YM",K21="PC"), TRUE, FALSE) -> TRUE | N21: =IF(M21=FALSE, 0, IF(O21=0, 1, 0)) -> 1 | O21: =IF(M21=FALSE,"Not Considered",IF(AND(M21,P21<>""),0,1)) -> 0 | P21: =IF(Data!H21=0,"",Data!H21) -> 44037.462
A22: =Data!G22 -> Driver D | B22: =Data!E22 -> FirstName D | C22: =Data!F22 -> LastName D | D22: =IF(OR(A22<>A21, I22<>I21), TRUE, FALSE) -> FALSE | E22: =IF(D22,SUMIFS(O:O,A:A,A22,I:I, I22),"NA") -> NA | F22: =IF(ISNUMBER(E22), IF(E22>=1, 1, 0), 0) -> 0 | G22: =IF(ISNUMBER(E22), IF(E22>=1, 0, 1), 0) -> 0 | H22: =IF(AND(F22=1,ISNUMBER(SEARCH("consider",O22))=FALSE),I22,"NA") -> NA | I22: =INT(Data!A22) -> 44026 | J22: =Data!A22 -> 44026.589 | K22: =Data!B22 -> D | L22: =Data!C22 -> Vehicle D | M22: =IF(OR(K22="D",K22="ON",K22="OFF",K22="SB",K22="YM",K22="PC"), TRUE, FALSE) -> TRUE | N22: =IF(M22=FALSE, 0, IF(O22=0, 1, 0)) -> 0 | O22: =IF(M22=FALSE,"Not Considered",IF(AND(M22,P22<>""),0,1)) -> 1 | P22: =IF(Data!H22=0,"",Data!H22)
A23: =Data!G23 -> Driver D | B23: =Data!E23 -> FirstName D | C23: =Data!F23 -> LastName D | D23: =IF(OR(A23<>A22, I23<>I22), TRUE, FALSE) -> FALSE | E23: =IF(D23,SUMIFS(O:O,A:A,A23,I:I, I23),"NA") -> NA | F23: =IF(ISNUMBER(E23), IF(E23>=1, 1, 0), 0) -> 0 | G23: =IF(ISNUMBER(E23), IF(E23>=1, 0, 1), 0) -> 0 | H23: =IF(AND(F23=1,ISNUMBER(SEARCH("consider",O23))=FALSE),I23,"NA") -> NA | I23: =INT(Data!A23) -> 44026 | J23: =Data!A23 -> 44026.701 | K23: =Data!B23 -> SB | L23: =Data!C23 -> Vehicle D | M23: =IF(OR(K23="D",K23="ON",K23="OFF",K23="SB",K23="YM",K23="PC"), TRUE, FALSE) -> TRUE | N23: =IF(M23=FALSE, 0, IF(O23=0, 1, 0)) -> 0 | O23: =IF(M23=FALSE,"Not Considered",IF(AND(M23,P23<>""),0,1)) -> 1 | P23: =IF(Data!H23=0,"",Data!H23)
... A152: =Data!G152 -> Driver B | B152: =Data!E152 -> FirstName B | C152: =Data!F152 -> LastName B | D152: =IF(OR(A152<>A151, I152<>I151), TRUE, FALSE) -> FALSE | E152: =IF(D152,SUMIFS(O:O,A:A,A152,I:I, I152),"NA") -> NA | F152: =IF(ISNUMBER(E152), IF(E152>=1, 1, 0), 0) -> 0 | G152: =IF(ISNUMBER(E152), IF(E152>=1, 0, 1), 0) -> 0 | H152: =IF(AND(F152=1,ISNUMBER(SEARCH("consider",O152))=FALSE),I152,"NA") -> NA | I152: =INT(Data!A152) -> 44032 | J152: =Data!A152 -> 44032.274 | K152: =Data!B152 -> OFF | L152: =Data!C152 -> Vehicle B | M152: =IF(OR(K152="D",K152="ON",K152="OFF",K152="SB",K152="YM",K152="PC"), TRUE, FALSE) -> TRUE | N152: =IF(M152=FALSE, 0, IF(O152=0, 1, 0)) -> 1 | O152: =IF(M152=FALSE,"Not Considered",IF(AND(M152,P152<>""),0,1)) -> 0 | P152: =IF(Data!H152=0,"",Data!H152) -> 42576.462

Sheet Graph
A1: **Unverified Logs | C1: =Data!B2 -> 44032.083
A2: =Data!B1 -> ABC Company
A4: =Report!A4 -> **Date
A5: =Report!A5 -> **From | B5: =Data!B3 -> 44013
A6: =Report!A6 -> **To | B6: =Data!B4 -> 44032
A7: =Report!A7 -> **Days | B7: =B6-B5 -> 19
A9: **Time Zone | B9: =Data!B5 -> America/New_York
A11: Date | B11: **Verified | C11: **Unverified
A12: 44013 | B12: 2 | C12: 1
A13: 44015 | B13: 0 | C13: 1
A14: 44017 | B14: 1 | C14: 0
A15: 44019 | B15: 1 | C15: 1
A16: 44020 | B16: 1 | C16: 0
A17: 44023 | B17: 0 | C17: 1
A18: 44024 | B18: 0 | C18: 2
A19: 44025 | B19: 1 | C19: 0
A20: 44026 | B20: 0 | C20: 2
A21: 44027 | B21: 2 | C21: 0
A22: 44028 | B22: 1 | C22: 2
A23: 44029 | B23: 1 | C23: 0
... A26: 44032 | B26: 0 | C26: 4

Sheet Count
B2: Days with Unverified Logs | T2: Language Translation
T3: **Total
B4: =T10 -> 8 | T4: **Verified
T5: **Unverified
T6: **Not Considered
T7: **Grace
T8: **Count of Unverified Logs
T9: **Pending days to be verified
T10: =COUNTA(Graph!B12:B49)-COUNTIF(Graph!B12:B49, "=0") -> 8
T11: =COUNTA(Graph!B12:B49) -> 15
T12: **Total pending days to be verified
T13: =Count!T10&" "&Count!T9 -> 8 **Pending days to be verified
S14: Chart Title | T14: =IF(Count!T10=Count!T11, T12, T13) -> 8 **Pending days to be verified
T15: **Number of Drivers
T16: **Date
B17: From: | C17: =Data!B3 -> 44013 | D17: To: | E17: =Data!B4 -> 44032 | T17: **Filter Options

Sheet Data
A1: CompanyName | B1: ABC Company
A2: RunDate | B2: 44032.083
A3: FromDate | B3: 44013
A4: ToDate | B4: 44032
A5: TimeZone | B5: America/New_York
A6: DistanceUnit | B6: km
A7: SpeedUnit | B7: km/h
A8: SendReport | B8: TRUE
A9: LastModifiedUser | B9: System
A10: Language | B10: en
A11: DutyStatusDateTime | B11: DutyStatusStatus | C11: .StatusLog.Device.DeviceName | D11: .StatusLog.Device.DeviceGroup | E11: .StatusLog.Driver.UserFirstName | F11: .StatusLog.Driver.UserLastName | G11: .StatusLog.Driver.UserName | H11: DutyStatusVerifyDateTime
A12: 44031.014 | B12: D | C12: Vehicle C | D12: ABC Vehicles | E12: FirstName C | F12: LastName C | G12: Driver C | H12: 44037.462
A13: 44031.056 | B13: ON | C13: Vehicle C | D13: ABC Vehicles | E13: FirstName C | F13: LastName C | G13: Driver C | H13: 44037.462
A14: 44031.563 | B14: D | C14: Vehicle C | D14: ABC Vehicles | E14: FirstName C | F14: LastName C | G14: Driver C | H14: 44037.462
A15: 44031.565 | B15: OFF | C15: Vehicle C | D15: ABC Vehicles | E15: FirstName C | F15: LastName C | G15: Driver C | H15: 44037.462
A16: 44031.589 | B16: D | C16: Vehicle C | D16: ABC Vehicles | E16: FirstName C | F16: LastName C | G16: Driver C
A17: 44031.701 | B17: SB | C17: Vehicle C | D17: ABC Vehicles | E17: FirstName C | F17: LastName C | G17: Driver C
A18: 44026.014 | B18: D | C18: Vehicle D | D18: ABC Vehicles | E18: FirstName D | F18: LastName D | G18: Driver D | H18: 44037.462
A19: 44026.056 | B19: ON | C19: Vehicle D | D19: ABC Vehicles | E19: FirstName D | F19: LastName D | G19: Driver D | H19: 44037.462
A20: 44026.563 | B20: D | C20: Vehicle D | D20: ABC Vehicles | E20: FirstName D | F20: LastName D | G20: Driver D | H20: 44037.462
A21: 44026.565 | B21: OFF | C21: Vehicle D | D21: ABC Vehicles | E21: FirstName D | F21: LastName D | G21: Driver D | H21: 44037.462
A22: 44026.589 | B22: D | C22: Vehicle D | D22: ABC Vehicles | E22: FirstName D | F22: LastName D | G22: Driver D
A23: 44026.701 | B23: SB | C23: Vehicle D | D23: ABC Vehicles | E23: FirstName D | F23: LastName D | G23: Driver D
A24: 44032.014 | B24: D | C24: Vehicle E | D24: ABC Vehicles | E24: FirstName E | F24: LastName E | G24: Driver E | H24: 44037.462
A25: 44032.056 | B25: ON | C25: Vehicle E | D25: ABC Vehicles | E25: FirstName E | F25: LastName E | G25: Driver E | H25: 44037.462
A26: 44032.563 | B26: D | C26: Vehicle E | D26: ABC Vehicles | E26: FirstName E | F26: LastName E | G26: Driver E | H26: 44037.462
A27: 44032.565 | B27: OFF | C27: Vehicle E | D27: ABC Vehicles | E27: FirstName E | F27: LastName E | G27: Driver E | H27: 44037.462
A28: 44032.589 | B28: D | C28: Vehicle E | D28: ABC Vehicles | E28: FirstName E | F28: LastName E | G28: Driver E
A29: 44032.701 | B29: SB | C29: Vehicle E | D29: ABC Vehicles | E29: FirstName E | F29: LastName E | G29: Driver E
A30: 44028.014 | B30: D | C30: Vehicle F | D30: ABC Vehicles | E30: FirstName F | F30: LastName F | G30: Driver F | H30: 44037.462
A31: 44028.056 | B31: ON | C31: Vehicle F | D31: ABC Vehicles | E31: FirstName F | F31: LastName F | G31: Driver F | H31: 44037.462
A32: 44028.563 | B32: D | C32: Vehicle F | D32: ABC Vehicles | E32: FirstName F | F32: LastName F | G32: Driver F | H32: 44037.462
A33: 44028.565 | B33: OFF | C33: Vehicle F | D33: ABC Vehicles | E33: FirstName F | F33: LastName F | G33: Driver F | H33: 44037.462
A34: 44028.589 | B34: D | C34: Vehicle F | D34: ABC Vehicles | E34: FirstName F | F34: LastName F | G34: Driver F | H34: 44037.462
A35: 44028.701 | B35: SB | C35: Vehicle F | D35: ABC Vehicles | E35: FirstName F | F35: LastName F | G35: Driver F | H35: 44037.462
A36: 44031.014 | B36: D | C36: Vehicle G | D36: ABC Vehicles | E36: FirstName G | F36: LastName G | G36: Driver G | H36: 44037.462
A37: 44031.056 | B37: ON | C37: Vehicle G | D37: ABC Vehicles | E37: FirstName G | F37: LastName G | G37: Driver G | H37: 44037.462
A38: 44031.563 | B38: D | C38: Vehicle G | D38: ABC Vehicles | E38: FirstName G | F38: LastName G | G38: Driver G | H38: 44037.462
A39: 44031.565 | B39: OFF | C39: Vehicle G | D39: ABC Vehicles | E39: FirstName G | F39: LastName G | G39: Driver G | H39: 44037.462
A40: 44031.589 | B40: D | C40: Vehicle G | D40: ABC Vehicles | E40: FirstName G | F40: LastName G | G40: Driver G
...

Sheet Languages
A1: English | B1: French | C1: Spanish | D1: German | E1: Japanese | F1: Polish | G1: Portuguese-Brazil | H1: Dutch | I1: Italian | J1: Simplified Chinese | K1: Thai | L1: Indonesian | M1: Czech | N1: Swedish | O1: Turkish
A2: **Driver | B2: Chauffeur | C2: Conductor | D2: Fahrer | E2: ドライバー | F2: Kierowca | G2: Motorista | H2: Chauffeur | I2: Conducente | J2: 驾驶员 | K2: ผู้ขับ | L2: Pengemudi | M2: Řidič | N2: Förare | O2: Sürücü
A3: **Date | B3: Date | C3: Fecha | D3: Datum | E3: データ | F3: Data | G3: Data | H3: Datum | I3: Data | J3: 日期 | K3: วันที่ | L3: Tanggal | M3: Datum | N3: Datum | O3: Tarih
A4: **Status | B4: Statut | C4: Estado | D4: Status | E4: ステータス | F4: Status | G4: Status | H4: Status | I4: Stato | J4: 状态 | K4: สถานะ | L4: Status | M4: Stav | N4: Status | O4: Durum
A5: **Device | B5: Dispositif | C5: Dispositivo | D5: Gerät | E5: デバイス | F5: Urządzenie | G5: Dispositivo | H5: Apparaat | I5: Dispositivo | J5: 设备 | K5: อุปกรณ์ | L5: Perangkat | M5: Zařízení | N5: Enhet | O5: Aygıt
A6: **Co-drivers | B6: Co-chauffeurs | C6: Co-Conductores | D6: Beifahrer | E6: 二次ドライバー | F6: Kierowcy towarzyszący | G6: Motoristas ajudantes | H6: Tweede chauffeurs | I6: Secondi conducenti | J6: 副驾驶 | K6: ผู้ช่วยคนขับ | L6: Pendamping pengemudi | M6: Spolujezdci | N6: Andreförare | O6: Yardımcı sürücüler
A7: **Trailers | B7: Remorques | C7: Remolques | D7: Anhänger | E7: トレーラー | F7: Przyczepy | G7: Reboques | H7: Aanhangers | I7: Rimorchi | J7: 拖车 | K7: รถเทรลเลอร์ | L7: Trailer | M7: Přívěsy | N7: Trailers | O7: Treylerler
A8: **Longitude | B8: Longitude | C8: Longitud | D8: Längengrad | E8: 経度 | F8: Długość geograficzna | G8: Longitude | H8: Lengtegraad | I8: Longitudine | J8: 经度 | K8: ลองจิจูด | L8: Garis Bujur | M8: Zeměpisná délka | N8: Longitud | O8: Boylam
A9: **Latitude | B9: Latitude | C9: Latitud | D9: Breitengrad | E9: 緯度 | F9: Szerokość geograficzna | G9: Latitude | H9: Breedtegraad | I9: Latitudine | J9: 纬度 | K9: ละติจูด | L9: Garis Lintang | M9: Zeměpisná šířka | N9: Latitud | O9: Enlem
A10: **Address | B10: Adresse | C10: Dirección | D10: Adresse | E10: 住所 | F10: Adres | G10: Endereço | H10: Adres | I10: Indirizzo | J10: 地址 | K10: ที่อยู่ | L10: Alamat | M10: Adresa | N10: Adress | O10: Adres
A11: **Odometer | B11: Odomètre | C11: Odómetro | D11: Kilometerstand | E11: オドメータ | F11: Licznik kilometrów | G11: Hodômetro | H11: Kilometerteller | I11: Contachilometri | J11: 里程表 | K11: มาตรระยะทาง | L11: Odometer | M11: Počítadlo ujetých kilometrů | N11: Mätarställning | O11: Kilometre Sayacı
A12: **Duration | B12: Durée | C12: Duración | D12: Dauer | E12: 期間 | F12: Czas trwania | G12: Duração | H12: Duur | I12: Durata | J12: 时长 | K12: ระยะเวลา | L12: Durasi | M12: Doba trvání | N12: Varaktighet | O12: Süre
... A44: **Number of Drivers | B44: Nombre de chauffeurs | C44: Cantidad de conductores | D44: Anzahl Fahrer | E44: 運転手の数 | F44: Liczba kierowców | G44: Número de motoristas | H44: Aantal bestuurders | I44: Numero di conducenti | J44: 驾驶员数量 | K44: จำนวนผู้ขับ | L44: Jumlah Pengemudi | M44: Počet řidičů | N44: Antal förare | O44: Sürücü Sayısı
