Workbook
Name AllData: Report!$A$12:$Q$260

Sheet Total Count Graph
B2: **Active Diagnostics
B4: =COUNTIFS(Report!G:G,"Diagnostic",Report!H:H,"Active",Report!F:F,"#N/A") -> 8
B9: **Active Malfunctions
B11: =COUNTIFS(Report!G:G,"Malfunction",Report!H:H,"Active",Report!F:F,"#N/A") -> 1
B16: =Summary!A5&": "&TEXT(Summary!B5, "mmm dd, yyyy") -> **From: Apr 13, 2019 | C16: =Summary!A6&": "&TEXT(Summary!B6, "mmm dd, yyyy") -> **To: May 13, 2019

Sheet Active
A1: **Diagnostic & Malfunction Events | C1: =Data!B2 -> 43598.449
A2: =Data!B1 -> ABC Company
A4: **Date
A5: **From | B5: =Data!B3 -> 43568.449
A6: **To | B6: =Data!B4 -> 43598.449
A7: **Days | B7: =B6-B5 -> 30
A9: **Distance Unit | B9: =Data!B5 -> miles
A10: Include | B10: TRUE
A11: Active | B11: TRUE
A13: **Vehicle | B13: **Status | C13: **Date | D13: Type | E13: **Clear | F13: **Count
A14: Vehicle 1 | B14: UnidentifiedDrivingCompliance | C14: 43598.278 | D14: Diagnostic | E14: Active | F14: 1
A15: Vehicle 10 | B15: DataTransferCompliance | C15: 43584.465 | D15: Malfunction | E15: Active | F15: 1
B16: UnidentifiedDrivingCompliance | C16: 43598.384 | D16: Diagnostic | E16: Active | F16: 1
A17: Vehicle 2 | B17: UnidentifiedDrivingCompliance | C17: 43592.451 | D17: Diagnostic | E17: Active | F17: 1
A18: Vehicle 3 | B18: UnidentifiedDrivingCompliance | C18: 43570.765 | D18: Diagnostic | E18: Active | F18: 1
A19: Vehicle 4 | B19: UnidentifiedDrivingCompliance | C19: 43598.257 | D19: Diagnostic | E19: Active | F19: 1
A20: Vehicle 5 | B20: UnidentifiedDrivingCompliance | C20: 43595.676 | D20: Diagnostic | E20: Active | F20: 1
A21: Vehicle 6 | B21: UnidentifiedDrivingCompliance | C21: 43598.318 | D21: Diagnostic | E21: Active | F21: 1
A22: Vehicle 7 | B22: UnidentifiedDrivingCompliance | C22: 43580.674 | D22: Diagnostic | E22: Active | F22: 1
A23: Grand Total | F23: 9

Sheet Malfunctions
A1: **Diagnostic & Malfunction Events | C1: =Data!B2 -> 43598.449
A2: =Data!B1 -> ABC Company
A4: **Date
A5: **From | B5: =Data!B3 -> 43568.449
A6: **To | B6: =Data!B4 -> 43598.449
A7: **Days | B7: =B6-B5 -> 30
A9: **Distance Unit | B9: =Data!B5 -> miles
A10: Include | B10: TRUE
A11: Active | B11: TRUE
A12: Malfunction | B12: TRUE
A14: **Vehicle | B14: **Status | C14: **Date (Last Instance) | D14: **Type | E14: **Clear | F14: **Count
A15: Vehicle 10 | B15: DataTransferCompliance | C15: 43584.465 | D15: Malfunction | E15: Active | F15: 1
A16: Grand Total | F16: 1

Sheet Summary
A1: **Diagnostic & Malfunction Events | C1: =Data!B2 -> 43598.449
A2: =Data!B1 -> ABC Company
A4: **Date
A5: **From | B5: =Data!B3 -> 43568.449
A6: **To | B6: =Data!B4 -> 43598.449
A7: **Days | B7: =B6-B5 -> 30
A9: **Distance Unit | B9: =Data!B5 -> miles
A10: Include | B10: TRUE
A12: **Vehicle | B12: **Status | C12: **Date (Last Instance) | D12: **Type | E12: **Clear | F12: **Count
A13: Vehicle 10 | B13: DataTransferCompliance | C13: 43580.565 | D13: Diagnostic | E13: Cleared | F13: 1
C14: 43584.465 | D14: Malfunction | E14: Active | F14: 1
B15: PowerCompliance | C15: 43593.373 | D15: Diagnostic | E15: Cleared | F15: 1
B16: UnidentifiedDrivingCompliance | C16: 43598.384 | D16: Diagnostic | E16: Active | F16: 1
A17: Vehicle 10 Total | F17: 4
A18: Vehicle 5 | B18: DataTransferCompliance | C18: 43588.536 | D18: Diagnostic | E18: Cleared | F18: 1
B19: PowerCompliance | C19: 43593.362 | D19: Diagnostic | E19: Cleared | F19: 1
B20: UnidentifiedDrivingCompliance | C20: 43595.676 | D20: Diagnostic | E20: Active | F20: 1
A21: Vehicle 5 Total | F21: 3
A22: Vehicle 7 | B22: DataTransferCompliance | C22: 43593.398 | D22: Diagnostic | E22: Cleared | F22: 1
B23: PowerCompliance | C23: 43593.39 | D23: Diagnostic | E23: Cleared | F23: 1
B24: UnidentifiedDrivingCompliance | C24: 43580.674 | D24: Diagnostic | E24: Active | F24: 1
A25: Vehicle 7 Total | F25: 3
A26: Vehicle 6 | B26: DataTransferCompliance | C26: 43578.236 | D26: Diagnostic | E26: Cleared | F26: 1
B27: PowerCompliance | C27: 43593.364 | D27: Diagnostic | E27: Cleared | F27: 1
B28: UnidentifiedDrivingCompliance | C28: 43598.318 | D28: Diagnostic | E28: Active | F28: 1
A29: Vehicle 6 Total | F29: 3
A30: Vehicle 8 | B30: DataTransferCompliance | C30: 43595.381 | D30: Diagnostic | E30: Cleared | F30: 1
B31: PowerCompliance | C31: 43595.29 | D31: Diagnostic | E31: Cleared | F31: 1
A32: Vehicle 8 Total | F32: 2
A33: Vehicle 1 | B33: PowerCompliance | C33: 43595.31 | D33: Diagnostic | E33: Cleared | F33: 1
B34: UnidentifiedDrivingCompliance | C34: 43598.278 | D34: Diagnostic | E34: Active | F34: 1
A35: Vehicle 1 Total | F35: 2
A36: Vehicle 3 | B36: PowerCompliance | C36: 43598.344 | D36: Diagnostic | E36: Cleared | F36: 1
B37: UnidentifiedDrivingCompliance | C37: 43570.765 | D37: Diagnostic | E37: Active | F37: 1
A38: Vehicle 3 Total | F38: 2
A39: Vehicle 4 | B39: PowerCompliance | C39: 43593.363 | D39: Diagnostic | E39: Cleared | F39: 1
B40: UnidentifiedDrivingCompliance | C40: 43598.257 | D40: Diagnostic | E40: Active | F40: 1
A41: Vehicle 4 Total | F41: 2
A42: Vehicle 2 | B42: UnidentifiedDrivingCompliance | C42: 43592.451 | D42: Diagnostic | E42: Active | F42: 1
A43: Vehicle 2 Total | F43: 1
...

Sheet Data
A1: CompanyName | B1: ABC Company
A2: RunDate | B2: 43598.449
A3: FromDate | B3: 43568.449
A4: ToDate | B4: 43598.449
A5: DistanceUnit | B5: miles
A6: SpeedUnit | B6: mph
A7: SendReport | B7: =IF(COUNTIFS(Report!G:G,"Malfunction",Report!H:H,"Active",Report!F:F,"#N/A")>0,TRUE,FALSE) -> TRUE
A8: LastModifiedUser | B8: mygproduct@geotab.com
A9: Language | B9: en
A10: DutyStatusDateTime | B10: DutyStatusStatus | C10: .StatusLog.Device.DeviceName | D10: .StatusLog.Device.DeviceId | E10: .StatusLog.Device.DeviceGroup | F10: DutyStatusId | G10: DutyStatusDetailOdometer | H10: DutyStatusDetailDistance | I10: DutyStatusDetailLongitude | J10: DutyStatusDetailLatitude | K10: DutyStatusLocation | L10: DutyStatusOrigin | M10: DutyStatusMalfunctionType | N10: DutyStatusState
A11: 43568.615 | B11: UnidentifiedDrivingCompliance | C11: Vehicle 1 | D11: b5 | E11: Entire Organization | F11: aoh4J-CJ6OUaBo8pdKCJJIg | G11: 12321.004 | H11: 21.503172 | I11: Long | J11: Lat | K11: Approximate Location | L11: Automatic | M11: Diagnostic | N11: Active
A12: 43568.664 | B12: UnidentifiedDrivingCompliance | C12: Vehicle 2 | D12: b4E | E12: Entire Organization | F12: avmYnI22qr0qZRfUIMwwkSA | G12: 2990.0286 | H12: 16.041061 | I12: Long | J12: Lat | K12: Approximate Location | L12: Automatic | M12: Diagnostic | N12: Active
A13: 43568.82 | B13: UnidentifiedDrivingCompliance | C13: Vehicle 3 | D13: b5F | E13: Entire Organization | F13: afd1eZVull0Si3h9x84B4hg | G13: 116631.19 | H13: 119.23368 | I13: Long | J13: Lat | K13: Approximate Location | L13: Automatic | M13: Diagnostic | N13: Active
A14: 43568.959 | B14: UnidentifiedDrivingCompliance | C14: Vehicle 2 | D14: b4E | E14: Entire Organization | F14: a-TC4JBCcNEay-vthv-Twmg | G14: 3006.0696 | H14: 153.68159 | I14: Long | J14: Lat | K14: Approximate Location | L14: Automatic | M14: Diagnostic | N14: Active
A15: 43569.4 | B15: UnidentifiedDrivingCompliance | C15: Vehicle 4 | D15: bE | E15: Entire Organization | F15: awhyQi7q9bEWE-gSwSMC2bw | G15: 60532.684 | H15: 12.253441 | I15: Long | J15: Lat | K15: Approximate Location | L15: Automatic | M15: Diagnostic | N15: Active
A16: 43569.461 | B16: UnidentifiedDrivingCompliance | C16: Vehicle 5 | D16: b3A | E16: Entire Organization | F16: akOw24xqhUkOcERFjlY4Bqg | G16: 82226.672 | H16: 22.493639 | I16: Long | J16: Lat | K16: Approximate Location | L16: Automatic | M16: Diagnostic | N16: Active
A17: 43570.243 | B17: UnidentifiedDrivingCompliance | C17: Vehicle 4 | D17: bE | E17: Entire Organization | F17: aalu5Rhyeake5hhB8Y-KB7g | G17: 60544.934 | H17: 28.796827 | I17: Long | J17: Lat | K17: Approximate Location | L17: Automatic | M17: Diagnostic | N17: Active
A18: 43570.383 | B18: UnidentifiedDrivingCompliance | C18: Vehicle 1 | D18: b5 | E18: Entire Organization | F18: aElJszqzV20aS5BPxYBzgAw | G18: 12342.507 | H18: 33.115356 | I18: Long | J18: Lat | K18: Approximate Location | L18: Automatic | M18: Diagnostic | N18: Active
A19: 43570.4 | B19: UnidentifiedDrivingCompliance | C19: Vehicle 3 | D19: b5F | E19: Entire Organization | F19: atueKbvDrxEy2R2vWqgLtQA | G19: 116750.42 | H19: 19.645273 | I19: Long | J19: Lat | K19: Approximate Location | L19: Automatic | M19: Diagnostic | N19: Active
A20: 43570.688 | B20: UnidentifiedDrivingCompliance | C20: Vehicle 5 | D20: b3A | E20: Entire Organization | F20: ayysOa9-p00WyOLiQwZEeaA | G20: 82249.172 | H20: 5.7787523 | I20: Long | J20: Lat | K20: Approximate Location | L20: Automatic | M20: Diagnostic | N20: Active
A21: 43570.765 | B21: UnidentifiedDrivingCompliance | C21: Vehicle 3 | D21: b5F | E21: Entire Organization | F21: aq3Ejnj27O0yBFIIXCAY4Uw | G21: 116770.07 | H21: 93.832024 | I21: Long | J21: Lat | K21: Approximate Location | L21: Automatic | M21: Diagnostic | N21: Active
A22: 43571.27 | B22: UnidentifiedDrivingCompliance | C22: Vehicle 1 | D22: b5 | E22: Entire Organization | F22: aN17WKQKekkKruoU-MEBbVg | G22: 12375.622 | H22: 31.837818 | I22: Long | J22: Lat | K22: Approximate Location | L22: Automatic | M22: Diagnostic | N22: Active
... A42: 43572.851 | B42: DataTransferCompliance | C42: Vehicle 7 | D42: b55 | E42: Entire Organization | F42: aVehicle 8N1-YoSEUW-N6efb6wDrw | G42: 16944.523 | H42: 0 | I42: Long | J42: Lat | K42: Approximate Location | L42: Automatic | M42: SystemDiagnosticClear | N42: Active
A43: 43572.858 | B43: DataTransferCompliance | C43: Vehicle 9 | D43: b52 | E43: Entire Organization | F43: aVehicle 8ZLrx64QEi4Y2YSqaVhMg | G43: 309.43152 | I43: Long | J43: Lat | K43: Approximate Location | L43: Automatic | M43: SystemDiagnosticClear | N43: Active
A44: 43572.902 | B44: DataTransferCompliance | C44: Vehicle 7 | D44: b55 | E44: Entire Organization | F44: aoChZ_ndLNUCj92qfSugQxQ | G44: 16944.523 | H44: 47.96986 | I44: Long | J44: Lat | K44: Approximate Location | L44: Automatic | M44: SystemDiagnosticClear | N44: Active
A45: 43573.271 | B45: UnidentifiedDrivingCompliance | C45: Vehicle 4 | D45: bE | E45: Entire Organization | F45: aJ5F9BXFNS0CMMKdJwy69PQ | G45: 60600.348 | H45: 13.337111 | I45: Long | J45: Lat | K45: Approximate Location | L45: Automatic | M45: Diagnostic | N45: Active
A46: 43573.282 | B46: UnidentifiedDrivingCompliance | C46: Vehicle 1 | D46: b5 | E46: Entire Organization | F46: aQKRCxk9AO0e3XnljaTWFYg | G46: 12445.402 | H46: 48.169941 | I46: Long | J46: Lat | K46: Approximate Location | L46: Automatic | M46: Diagnostic | N46: Active
A47: 43573.286 | B47: UnidentifiedDrivingCompliance | C47: Vehicle 6 | D47: b60 | E47: Entire Organization | F47: al5mhfyfoXUGWfwEAhvA7vg | G47: 118566.76 | H47: 14.81349 | I47: Long | J47: Lat | K47: Approximate Location | L47: Automatic | M47: Diagnostic | N47: Active
A48: 43573.491 | B48: PowerCompliance | C48: Vehicle 3 | D48: b5F | E48: Entire Organization | F48: aP2KHNXDO_E-Sy7mdQ9Df1g | G48: 116863.9 | H48: 0 | I48: Long | J48: Lat | K48: Approximate Location | L48: Automatic | M48: Diagnostic | N48: Active
A49: 43573.491 | B49: PowerCompliance | C49: Vehicle 3 | D49: b5F | E49: Entire Organization | F49: aa-sjC2_2DUqWBLK0cswaTA | G49: 116863.9 | H49: 266.20538 | I49: Long | J49: Lat | K49: Approximate Location | L49: Automatic | M49: SystemDiagnosticClearDriving | N49: Active
A50: 43573.496 | B50: PowerCompliance | C50: Vehicle 6 | D50: b60 | E50: Entire Organization | F50: af2ejjaeaOEO2_lGPe6K8iA | G50: 118581.57 | H50: 0 | I50: Long | J50: Lat | K50: Approximate Location | L50: Automatic | M50: Diagnostic | N50: Active
A51: 43573.497 | B51: PowerCompliance | C51: Vehicle 6 | D51: b60 | E51: Entire Organization | F51: aSQTHcaWuJkqIQ2WRloHLqQ | G51: 118581.57 | H51: 52.215065 | I51: Long | J51: Lat | K51: Approximate Location | L51: Automatic | M51: SystemDiagnosticClearDriving | N51: Active
A52: 43573.51 | B52: PowerCompliance | C52: Vehicle 5 | D52: b3A | E52: Entire Organization | F52: aywyPRzJ5gU-80bzo7_rZ2Q | G52: 82278.5 | H52: 0 | I52: Long | J52: Lat | K52: Approximate Location | L52: Automatic | M52: Diagnostic | N52: Active
A53: 43573.51 | B53: PowerCompliance | C53: Vehicle 5 | D53: b3A | E53: Entire Organization | F53: a-CEOO9iHFUC-WhUWB6R1Jw | G53: 82278.5 | H53: 65.308601 | I53: Long | J53: Lat | K53: Approximate Location | L53: Automatic | M53: SystemDiagnosticClearDriving | N53: Active
A54: 43574.3 | B54: UnidentifiedDrivingCompliance | C54: Vehicle 6 | D54: b60 | E54: Entire Organization | F54: aeD8D4mm6E0CK2Z0XAz1ryA | G54: 118633.78 | H54: 49.988071 | I54: Long | J54: Lat | K54: Approximate Location | L54: Automatic | M54: Diagnostic | N54: Active
A55: 43574.552 | B55: UnidentifiedDrivingCompliance | C55: Vehicle 4 | D55: bE | E55: Entire Organization | F55: aP7zoZY9an0eQbIfO3wqLYA | G55: 60613.684 | H55: 9.7778978 | I55: Long | J55: Lat | K55: Approximate Location | L55: Automatic | M55: Diagnostic | N55: Active
... A117: 43581.341 | B117: DataTransferCompliance | C117: Vehicle 10 | D117: b61 | E117: Entire Organization | F117: aAOKhykhzWkWJBh7WO9hgWQ | G117: 93240.047 | H117: 17.025572 | I117: Long | J117: Lat | K117: Approximate Location | L117: Automatic | M117: Malfunction | N117: Active
A118: 43581.399 | B118: DataTransferCompliance | C118: Vehicle 11 | D118: b3C | E118: Entire Organization | F118: aC1N6WqfBiUy0ZCbXCoSUlw | G118: 947.52985 | I118: Long | J118: Lat | K118: Approximate Location | L118: Automatic | M118: SystemDiagnosticClear | N118: Active
A119: 43581.566 | B119: DataTransferCompliance | C119: Vehicle 8 | D119: b1 | E119: Entire Organization | F119: aK7SKxY3xdUyreb9fpK7KCQ | G119: 67050.57 | H119: 119.30328 | I119: Long | J119: Lat | K119: Approximate Location | L119: Automatic | M119: SystemDiagnosticClear | N119: Active
A120: 43581.596 | B120: UnidentifiedDrivingCompliance | C120: Vehicle 1 | D120: b5 | E120: Entire Organization | F120: aBj8h1VzUMkqlPKlYoahG5g | G120: 12635.019 | H120: 24.002327 | I120: Long | J120: Lat | K120: Approximate Location | L120: Automatic | M120: Diagnostic | N120: Active
...

Sheet Report
A1: **Diagnostic & Malfunction Events | C1: =Data!B2 -> 43598.449
A2: =Data!B1 -> ABC Company
A4: **Date
A5: **From | B5: =Data!B3 -> 43568.449
A6: **To | B6: =Data!B4 -> 43598.449
A7: **Days | B7: =B6-B5 -> 30
A9: **Distance Unit | B9: =Data!B5 -> miles
A10: **Total Row Count | B10: =COUNTA(E:E)+11 -> 260
A12: **Vehicle | B12: **Date | C12: **Status | D12: **Short Status | E12: **Vehicle & Type | F12: Next Row | G12: Malf/Diag | H12: **Clear | I12: **Type | J12: Include | K12: Active | L12: Malfunction | M12: **Longitude | N12: **Latitude | O12: **Address | P12: **Odometer | Q12: **Distance
A13: =Data!C11 -> Vehicle 1 | B13: =Data!A11 -> 43568.615 | C13: =Data!B11 -> UnidentifiedDrivingCompliance | D13: =IF(C13="PowerCompliance","Power",IF(C13="PositioningCompliance","Positioning",IF(C13="EngineSyncCompliance","Engine Sync",IF(C13="UnidentifiedDrivingCompliance","Unidentified Driving",IF(C13="DataRecordingCompliance","Data Recording",IF(C13="DataTransferCompliance","Data Transfer",IF(C13="MissingElementCompliance","Missing Element",IF(C13="OtherCompliance","Other",IF(C13="TimingCompliance","Timing",""))))))))) -> Unidentified Driving | E13: =A13&" "&D13&" "&G13 -> Vehicle 1 Unidentified Driving Diagnostic | F13: =MATCH(E13,INDIRECT("E"&ROW(E13)+1&":E"&$B$10),0) -> 7 | G13: =IF(ISNUMBER(SEARCH("Diagnostic",I13))=TRUE,"Diagnostic","Malfunction") -> Diagnostic | H13: =IF(OR(ISNUMBER(SEARCH("clear",INDIRECT("H"&ROW(I13)+F13))),ISNUMBER(SEARCH("clear",I13))),"Cleared","Active") -> Active | I13: =Data!M11 -> Diagnostic | J13: =ISERROR(F13) -> FALSE | K13: =IF(H13="Active",TRUE,FALSE) -> TRUE | L13: =IF(G13="Malfunction",TRUE,FALSE) -> FALSE | M13: =Data!I11 -> Long | N13: =Data!J11 -> Lat | O13: =Data!K11 -> Approximate Location | P13: =Data!G11 -> 12321.004 | Q13: =Data!H11 -> 21.503172
A14: =Data!C12 -> Vehicle 2 | B14: =Data!A12 -> 43568.664 | C14: =Data!B12 -> UnidentifiedDrivingCompliance | D14: =IF(C14="PowerCompliance","Power",IF(C14="PositioningCompliance","Positioning",IF(C14="EngineSyncCompliance","Engine Sync",IF(C14="UnidentifiedDrivingCompliance","Unidentified Driving",IF(C14="DataRecordingCompliance","Data Recording",IF(C14="DataTransferCompliance","Data Transfer",IF(C14="MissingElementCompliance","Missing Element",IF(C14="OtherCompliance","Other",IF(C14="TimingCompliance","Timing",""))))))))) -> Unidentified Driving | E14: =A14&" "&D14&" "&G14 -> Vehicle 2 Unidentified Driving Diagnostic | F14: =MATCH(E14,INDIRECT("E"&ROW(E14)+1&":E"&$B$10),0) -> 2 | G14: =IF(ISNUMBER(SEARCH("Diagnostic",I14))=TRUE,"Diagnostic","Malfunction") -> Diagnostic | H14: =IF(OR(ISNUMBER(SEARCH("clear",INDIRECT("H"&ROW(I14)+F14))),ISNUMBER(SEARCH("clear",I14))),"Cleared","Active") -> Active | I14: =Data!M12 -> Diagnostic | J14: =ISERROR(F14) -> FALSE | K14: =IF(H14="Active",TRUE,FALSE) -> TRUE | L14: =IF(G14="Malfunction",TRUE,FALSE) -> FALSE | M14: =Data!I12 -> Long | N14: =Data!J12 -> Lat | O14: =Data!K12 -> Approximate Location | P14: =Data!G12 -> 2990.0286 | Q14: =Data!H12 -> 16.041061
A15: =Data!C13 -> Vehicle 3 | B15: =Data!A13 -> 43568.82 | C15: =Data!B13 -> UnidentifiedDrivingCompliance | D15: =IF(C15="PowerCompliance","Power",IF(C15="PositioningCompliance","Positioning",IF(C15="EngineSyncCompliance","Engine Sync",IF(C15="UnidentifiedDrivingCompliance","Unidentified Driving",IF(C15="DataRecordingCompliance","Data Recording",IF(C15="DataTransferCompliance","Data Transfer",IF(C15="MissingElementCompliance","Missing Element",IF(C15="OtherCompliance","Other",IF(C15="TimingCompliance","Timing",""))))))))) -> Unidentified Driving | E15: =A15&" "&D15&" "&G15 -> Vehicle 3 Unidentified Driving Diagnostic | F15: =MATCH(E15,INDIRECT("E"&ROW(E15)+1&":E"&$B$10),0) -> 6 | G15: =IF(ISNUMBER(SEARCH("Diagnostic",I15))=TRUE,"Diagnostic","Malfunction") -> Diagnostic | H15: =IF(OR(ISNUMBER(SEARCH("clear",INDIRECT("H"&ROW(I15)+F15))),ISNUMBER(SEARCH("clear",I15))),"Cleared","Active") -> Active | I15: =Data!M13 -> Diagnostic | J15: =ISERROR(F15) -> FALSE | K15: =IF(H15="Active",TRUE,FALSE) -> TRUE | L15: =IF(G15="Malfunction",TRUE,FALSE) -> FALSE | M15: =Data!I13 -> Long | N15: =Data!J13 -> Lat | O15: =Data!K13 -> Approximate Location | P15: =Data!G13 -> 116631.19 | Q15: =Data!H13 -> 119.23368
A16: =Data!C14 -> Vehicle 2 | B16: =Data!A14 -> 43568.959 | C16: =Data!B14 -> UnidentifiedDrivingCompliance | D16: =IF(C16="PowerCompliance","Power",IF(C16="PositioningCompliance","Positioning",IF(C16="EngineSyncCompliance","Engine Sync",IF(C16="UnidentifiedDrivingCompliance","Unidentified Driving",IF(C16="DataRecordingCompliance","Data Recording",IF(C16="DataTransferCompliance","Data Transfer",IF(C16="MissingElementCompliance","Missing Element",IF(C16="OtherCompliance","Other",IF(C16="TimingCompliance","Timing",""))))))))) -> Unidentified Driving | E16: =A16&" "&D16&" "&G16 -> Vehicle 2 Unidentified Driving Diagnostic | F16: =MATCH(E16,INDIRECT("E"&ROW(E16)+1&":E"&$B$10),0) -> 76 | G16: =IF(ISNUMBER(SEARCH("Diagnostic",I16))=TRUE,"Diagnostic","Malfunction") -> Diagnostic | H16: =IF(OR(ISNUMBER(SEARCH("clear",INDIRECT("H"&ROW(I16)+F16))),ISNUMBER(SEARCH("clear",I16))),"Cleared","Active") -> Active | I16: =Data!M14 -> Diagnostic | J16: =ISERROR(F16) -> FALSE | K16: =IF(H16="Active",TRUE,FALSE) -> TRUE | L16: =IF(G16="Malfunction",TRUE,FALSE) -> FALSE | M16: =Data!I14 -> Long | N16: =Data!J14 -> Lat | O16: =Data!K14 -> Approximate Location | P16: =Data!G14 -> 3006.0696 | Q16: =Data!H14 -> 153.68159
A17: =Data!C15 -> Vehicle 4 | B17: =Data!A15 -> 43569.4 | C17: =Data!B15 -> UnidentifiedDrivingCompliance | D17: =IF(C17="PowerCompliance","Power",IF(C17="PositioningCompliance","Positioning",IF(C17="EngineSyncCompliance","Engine Sync",IF(C17="UnidentifiedDrivingCompliance","Unidentified Driving",IF(C17="DataRecordingCompliance","Data Recording",IF(C17="DataTransferCompliance","Data Transfer",IF(C17="MissingElementCompliance","Missing Element",IF(C17="OtherCompliance","Other",IF(C17="TimingCompliance","Timing",""))))))))) -> Unidentified Driving | E17: =A17&" "&D17&" "&G17 -> Vehicle 4 Unidentified Driving Diagnostic | F17: =MATCH(E17,INDIRECT("E"&ROW(E17)+1&":E"&$B$10),0) -> 2 | G17: =IF(ISNUMBER(SEARCH("Diagnostic",I17))=TRUE,"Diagnostic","Malfunction") -> Diagnostic | H17: =IF(OR(ISNUMBER(SEARCH("clear",INDIRECT("H"&ROW(I17)+F17))),ISNUMBER(SEARCH("clear",I17))),"Cleared","Active") -> Active | I17: =Data!M15 -> Diagnostic | J17: =ISERROR(F17) -> FALSE | K17: =IF(H17="Active",TRUE,FALSE) -> TRUE | L17: =IF(G17="Malfunction",TRUE,FALSE) -> FALSE | M17: =Data!I15 -> Long | N17: =Data!J15 -> Lat | O17: =Data!K15 -> Approximate Location | P17: =Data!G15 -> 60532.684 | Q17: =Data!H15 -> 12.253441
A18: =Data!C16 -> Vehicle 5 | B18: =Data!A16 -> 43569.461 | C18: =Data!B16 -> UnidentifiedDrivingCompliance | D18: =IF(C18="PowerCompliance","Power",IF(C18="PositioningCompliance","Positioning",IF(C18="EngineSyncCompliance","Engine Sync",IF(C18="UnidentifiedDrivingCompliance","Unidentified Driving",IF(C18="DataRecordingCompliance","Data Recording",IF(C18="DataTransferCompliance","Data Transfer",IF(C18="MissingElementCompliance","Missing Element",IF(C18="OtherCompliance","Other",IF(C18="TimingCompliance","Timing",""))))))))) -> Unidentified Driving | E18: =A18&" "&D18&" "&G18 -> Vehicle 5 Unidentified Driving Diagnostic | F18: =MATCH(E18,INDIRECT("E"&ROW(E18)+1&":E"&$B$10),0) -> 4 | G18: =IF(ISNUMBER(SEARCH("Diagnostic",I18))=TRUE,"Diagnostic","Malfunction") -> Diagnostic | H18: =IF(OR(ISNUMBER(SEARCH("clear",INDIRECT("H"&ROW(I18)+F18))),ISNUMBER(SEARCH("clear",I18))),"Cleared","Active") -> Active | I18: =Data!M16 -> Diagnostic | J18: =ISERROR(F18) -> FALSE | K18: =IF(H18="Active",TRUE,FALSE) -> TRUE | L18: =IF(G18="Malfunction",TRUE,FALSE) -> FALSE | M18: =Data!I16 -> Long | N18: =Data!J16 -> Lat | O18: =Data!K16 -> Approximate Location | P18: =Data!G16 -> 82226.672 | Q18: =Data!H16 -> 22.493639
A19: =Data!C17 -> Vehicle 4 | B19: =Data!A17 -> 43570.243 | C19: =Data!B17 -> UnidentifiedDrivingCompliance | D19: =IF(C19="PowerCompliance","Power",IF(C19="PositioningCompliance","Positioning",IF(C19="EngineSyncCompliance","Engine Sync",IF(C19="UnidentifiedDrivingCompliance","Unidentified Driving",IF(C19="DataRecordingCompliance","Data Recording",IF(C19="DataTransferCompliance","Data Transfer",IF(C19="MissingElementCompliance","Missing Element",IF(C19="OtherCompliance","Other",IF(C19="TimingCompliance","Timing",""))))))))) -> Unidentified Driving | E19: =A19&" "&D19&" "&G19 -> Vehicle 4 Unidentified Driving Diagnostic | F19: =MATCH(E19,INDIRECT("E"&ROW(E19)+1&":E"&$B$10),0) -> 7 | G19: =IF(ISNUMBER(SEARCH("Diagnostic",I19))=TRUE,"Diagnostic","Malfunction") -> Diagnostic | H19: =IF(OR(ISNUMBER(SEARCH("clear",INDIRECT("H"&ROW(I19)+F19))),ISNUMBER(SEARCH("clear",I19))),"Cleared","Active") -> Active | I19: =Data!M17 -> Diagnostic | J19: =ISERROR(F19) -> FALSE | K19: =IF(H19="Active",TRUE,FALSE) -> TRUE | L19: =IF(G19="Malfunction",TRUE,FALSE) -> FALSE | M19: =Data!I17 -> Long | N19: =Data!J17 -> Lat | O19: =Data!K17 -> Approximate Location | P19: =Data!G17 -> 60544.934 | Q19: =Data!H17 -> 28.796827
A20: =Data!C18 -> Vehicle 1 | B20: =Data!A18 -> 43570.383 | C20: =Data!B18 -> UnidentifiedDrivingCompliance | D20: =IF(C20="PowerCompliance","Power",IF(C20="PositioningCompliance","Positioning",IF(C20="EngineSyncCompliance","Engine Sync",IF(C20="UnidentifiedDrivingCompliance","Unidentified Driving",IF(C20="DataRecordingCompliance","Data Recording",IF(C20="DataTransferCompliance","Data Transfer",IF(C20="MissingElementCompliance","Missing Element",IF(C20="OtherCompliance","Other",IF(C20="TimingCompliance","Timing",""))))))))) -> Unidentified Driving | E20: =A20&" "&D20&" "&G20 -> Vehicle 1 Unidentified Driving Diagnostic | F20: =MATCH(E20,INDIRECT("E"&ROW(E20)+1&":E"&$B$10),0) -> 4 | G20: =IF(ISNUMBER(SEARCH("Diagnostic",I20))=TRUE,"Diagnostic","Malfunction") -> Diagnostic | H20: =IF(OR(ISNUMBER(SEARCH("clear",INDIRECT("H"&ROW(I20)+F20))),ISNUMBER(SEARCH("clear",I20))),"Cleared","Active") -> Active | I20: =Data!M18 -> Diagnostic | J20: =ISERROR(F20) -> FALSE | K20: =IF(H20="Active",TRUE,FALSE) -> TRUE | L20: =IF(G20="Malfunction",TRUE,FALSE) -> FALSE | M20: =Data!I18 -> Long | N20: =Data!J18 -> Lat | O20: =Data!K18 -> Approximate Location | P20: =Data!G18 -> 12342.507 | Q20: =Data!H18 -> 33.115356
A21: =Data!C19 -> Vehicle 3 | B21: =Data!A19 -> 43570.4 | C21: =Data!B19 -> UnidentifiedDrivingCompliance | D21: =IF(C21="PowerCompliance","Power",IF(C21="PositioningCompliance","Positioning",IF(C21="EngineSyncCompliance","Engine Sync",IF(C21="UnidentifiedDrivingCompliance","Unidentified Driving",IF(C21="DataRecordingCompliance","Data Recording",IF(C21="DataTransferCompliance","Data Transfer",IF(C21="MissingElementCompliance","Missing Element",IF(C21="OtherCompliance","Other",IF(C21="TimingCompliance","Timing",""))))))))) -> Unidentified Driving | E21: =A21&" "&D21&" "&G21 -> Vehicle 3 Unidentified Driving Diagnostic | F21: =MATCH(E21,INDIRECT("E"&ROW(E21)+1&":E"&$B$10),0) -> 2 | G21: =IF(ISNUMBER(SEARCH("Diagnostic",I21))=TRUE,"Diagnostic","Malfunction") -> Diagnostic | H21: =IF(OR(ISNUMBER(SEARCH("clear",INDIRECT("H"&ROW(I21)+F21))),ISNUMBER(SEARCH("clear",I21))),"Cleared","Active") -> Active | I21: =Data!M19 -> Diagnostic | J21: =ISERROR(F21) -> FALSE | K21: =IF(H21="Active",TRUE,FALSE) -> TRUE | L21: =IF(G21="Malfunction",TRUE,FALSE) -> FALSE | M21: =Data!I19 -> Long | N21: =Data!J19 -> Lat | O21: =Data!K19 -> Approximate Location | P21: =Data!G19 -> 116750.42 | Q21: =Data!H19 -> 19.645273
A22: =Data!C20 -> Vehicle 5 | B22: =Data!A20 -> 43570.688 | C22: =Data!B20 -> UnidentifiedDrivingCompliance | D22: =IF(C22="PowerCompliance","Power",IF(C22="PositioningCompliance","Positioning",IF(C22="EngineSyncCompliance","Engine Sync",IF(C22="UnidentifiedDrivingCompliance","Unidentified Driving",IF(C22="DataRecordingCompliance","Data Recording",IF(C22="DataTransferCompliance","Data Transfer",IF(C22="MissingElementCompliance","Missing Element",IF(C22="OtherCompliance","Other",IF(C22="TimingCompliance","Timing",""))))))))) -> Unidentified Driving | E22: =A22&" "&D22&" "&G22 -> Vehicle 5 Unidentified Driving Diagnostic | F22: =MATCH(E22,INDIRECT("E"&ROW(E22)+1&":E"&$B$10),0) -> 150 | G22: =IF(ISNUMBER(SEARCH("Diagnostic",I22))=TRUE,"Diagnostic","Malfunction") -> Diagnostic | H22: =IF(OR(ISNUMBER(SEARCH("clear",INDIRECT("H"&ROW(I22)+F22))),ISNUMBER(SEARCH("clear",I22))),"Cleared","Active") -> Active | I22: =Data!M20 -> Diagnostic | J22: =ISERROR(F22) -> FALSE | K22: =IF(H22="Active",TRUE,FALSE) -> TRUE | L22: =IF(G22="Malfunction",TRUE,FALSE) -> FALSE | M22: =Data!I20 -> Long | N22: =Data!J20 -> Lat | O22: =Data!K20 -> Approximate Location | P22: =Data!G20 -> 82249.172 | Q22: =Data!H20 -> 5.7787523
A23: =Data!C21 -> Vehicle 3 | B23: =Data!A21 -> 43570.765 | C23: =Data!B21 -> UnidentifiedDrivingCompliance | D23: =IF(C23="PowerCompliance","Power",IF(C23="PositioningCompliance","Positioning",IF(C23="EngineSyncCompliance","Engine Sync",IF(C23="UnidentifiedDrivingCompliance","Unidentified Driving",IF(C23="DataRecordingCompliance","Data Recording",IF(C23="DataTransferCompliance","Data Transfer",IF(C23="MissingElementCompliance","Missing Element",IF(C23="OtherCompliance","Other",IF(C23="TimingCompliance","Timing",""))))))))) -> Unidentified Driving | E23: =A23&" "&D23&" "&G23 -> Vehicle 3 Unidentified Driving Diagnostic | F23: =MATCH(E23,INDIRECT("E"&ROW(E23)+1&":E"&$B$10),0) -> #N/A | G23: =IF(ISNUMBER(SEARCH("Diagnostic",I23))=TRUE,"Diagnostic","Malfunction") -> Diagnostic | H23: =IF(OR(ISNUMBER(SEARCH("clear",INDIRECT("H"&ROW(I23)+F23))),ISNUMBER(SEARCH("clear",I23))),"Cleared","Active") -> Active | I23: =Data!M21 -> Diagnostic | J23: =ISERROR(F23) -> TRUE | K23: =IF(H23="Active",TRUE,FALSE) -> TRUE | L23: =IF(G23="Malfunction",TRUE,FALSE) -> FALSE | M23: =Data!I21 -> Long | N23: =Data!J21 -> Lat | O23: =Data!K21 -> Approximate Location | P23: =Data!G21 -> 116770.07 | Q23: =Data!H21 -> 93.832024
A24: =Data!C22 -> Vehicle 1 | B24: =Data!A22 -> 43571.27 | C24: =Data!B22 -> UnidentifiedDrivingCompliance | D24: =IF(C24="PowerCompliance","Power",IF(C24="PositioningCompliance","Positioning",IF(C24="EngineSyncCompliance","Engine Sync",IF(C24="UnidentifiedDrivingCompliance","Unidentified Driving",IF(C24="DataRecordingCompliance","Data Recording",IF(C24="DataTransferCompliance","Data Transfer",IF(C24="MissingElementCompliance","Missing Element",IF(C24="OtherCompliance","Other",IF(C24="TimingCompliance","Timing",""))))))))) -> Unidentified Driving | E24: =A24&" "&D24&" "&G24 -> Vehicle 1 Unidentified Driving Diagnostic | F24: =MATCH(E24,INDIRECT("E"&ROW(E24)+1&":E"&$B$10),0) -> 13 | G24: =IF(ISNUMBER(SEARCH("Diagnostic",I24))=TRUE,"Diagnostic","Malfunction") -> Diagnostic | H24: =IF(OR(ISNUMBER(SEARCH("clear",INDIRECT("H"&ROW(I24)+F24))),ISNUMBER(SEARCH("clear",I24))),"Cleared","Active") -> Active | I24: =Data!M22 -> Diagnostic | J24: =ISERROR(F24) -> FALSE | K24: =IF(H24="Active",TRUE,FALSE) -> TRUE | L24: =IF(G24="Malfunction",TRUE,FALSE) -> FALSE | M24: =Data!I22 -> Long | N24: =Data!J22 -> Lat | O24: =Data!K22 -> Approximate Location | P24: =Data!G22 -> 12375.622 | Q24: =Data!H22 -> 31.837818
... A260: =Data!C258 -> Vehicle 2 | B260: =Data!A258 -> 43598.444 | C260: =Data!B258 -> DataTransferCompliance | D260: =IF(C260="PowerCompliance","Power",IF(C260="PositioningCompliance","Positioning",IF(C260="EngineSyncCompliance","Engine Sync",IF(C260="UnidentifiedDrivingCompliance","Unidentified Driving",IF(C260="DataRecordingCompliance","Data Recording",IF(C260="DataTransferCompliance","Data Transfer",IF(C260="MissingElementCompliance","Missing Element",IF(C260="OtherCompliance","Other",IF(C260="TimingCompliance","Timing",""))))))))) -> Data Transfer | E260: =A260&" "&D260&" "&G260 -> Vehicle 2 Data Transfer Diagnostic | F260: =MATCH(E260,INDIRECT("E"&ROW(E260)+1&":E"&$B$10),0) -> 1 | G260: =IF(ISNUMBER(SEARCH("Diagnostic",I260))=TRUE,"Diagnostic","Malfunction") -> Diagnostic | H260: =IF(OR(ISNUMBER(SEARCH("clear",INDIRECT("H"&ROW(I260)+F260))),ISNUMBER(SEARCH("clear",I260))),"Cleared","Active") -> Cleared | I260: =Data!M258 -> SystemDiagnosticClear | J260: =ISERROR(F260) -> FALSE | K260: =IF(H260="Active",TRUE,FALSE) -> FALSE | L260: =IF(G260="Malfunction",TRUE,FALSE) -> FALSE | M260: =Data!I258 -> Long | N260: =Data!J258 -> Lat | O260: =Data!K258 -> Approximate Location | P260: =Data!G258 -> 3844.79 | Q260: =Data!H258 -> 0

Sheet Languages
A1: English | B1: French | C1: Spanish | D1: German | E1: Japanese | F1: Polish | G1: Portuguese-Brazil | H1: Dutch | I1: Italian
A2: **Driver | B2: Conducteur | C2: Conductor | D2: Fahrer | E2: ドライバー | F2: Kierowca | G2: Motorista | H2: Chauffeur | I2: Conducente
A3: **Date | B3: Date | C3: Fecha | D3: Datum | E3: データ | F3: Data | G3: Data | H3: Datum | I3: Data
A4: **Status | B4: État | C4: Estado | D4: Status | E4: ステータス | F4: Status | G4: Status | H4: Status | I4: Stato
A5: **Device | B5: Dispositif | C5: Dispositivo | D5: Gerät | E5: デバイス | F5: Urzadzenie | G5: Dispositivo | H5: Apparaat | I5: Dispositivo
A6: **Co-drivers | B6: Co-chauffeurs | C6: Copiloto | D6: Beifahrer | E6: 補助ドライバー | F6: Wspólkierowcy | G6: Comotoristas | H6: Tweede chauffeurs | I6: Secondi conducenti
A7: **Trailers | B7: Gros porteurs | C7: Remolques | D7: Anhänger | E7: トレーラー | F7: Przyczepy | G7: Reboques | H7: Aanhangers | I7: Rimorchi
A8: **Longitude | B8: Longitude | C8: Longitud | D8: Längengrad | E8: 経度 | F8: Dlugosc geograficzna | G8: Longitude | H8: Lengtegraad | I8: Longitudine
A9: **Latitude | B9: Latitude | C9: Latitud | D9: Breitengrad | E9: 緯度 | F9: Szerokosc geograficzna | G9: Latitude | H9: Breedtegraad | I9: Latitudine
A10: **Address | B10: Adresse | C10: Dirección | D10: Adresse | E10: 住所 | F10: Adres | G10: Endereço | H10: Adres | I10: Indirizzo
A11: **Odometer | B11: Odomètre | C11: Odómetro | D11: Kilometerstand | E11: オドメータ | F11: Licznik kilometrów | G11: Velocímetro | H11: Kilometerteller | I11: Contachilometri
A12: **Distance | B12: Distance | C12: Distancia | D12: Entfernung | E12: 距離 | F12: Odleglosc | G12: Distância | H12: Afstand | I12: Distanza
... A23: **Log Origin | B23: Origine du Journal | C23: Origen del Registro | D23: Protokollherkunft | E23: ログの起源 | F23: Powstanie dziennika | G23: Origem do registro | H23: Oorsprong logboek | I23: Origine del registro
A24: **Diagnostic & Malfunction Events
A25: **Days
A26: **Distance Unit
A27: **Total Row Count
A28: **Active Diagnostics
A29: **Active Malfunctions
A30: **Count
A31: **Date (Last Instance)
A32: **Type
A33: **Clear
A34: **Vehicle
