Workbook
Name AllData: Report!$A$12:$X$621

Sheet Data
A1: CompanyName | B1: abc_company
A2: RunDate | B2: 45443.579
A3: FromDate | B3: 45442.854
A4: ToDate | B4: 45442.896
A5: TimeZone | B5: America/New_York
A6: SpeedUnit | B6: km/h
A7: SendReport | B7: =TRUE() -> TRUE
A8: LastModifiedUser | B8: **<No User>
A9: Language | B9: en
A10: DeviceName | B10: DeviceGroup | C10: DeviceEngineVIN | D10: DebugDateTime | E10: DebugRecordType | F10: DebugLocation | G10: DebugLongitude | H10: DebugLatitude | I10: DiagnosticName | J10: DebuggingStatusRecordDisplayData | K10: DebuggingStatusRecordUnitOfMeasureName
A11: vehicle1 | B11: Vehicle, Gasoline or Petrol | C11: 1f2g3h4j5k6l | D11: 45066.153 | E11: DebugRecord
A12: vehicle1 | B12: Vehicle, Gasoline or Petrol | C12: 1f2g3h4j5k6l | D12: 45066.132 | E12: EngineStatusRecord | I12: Cranking voltage | J12: 12.39364 | K12: V
A13: vehicle1 | B13: Vehicle, Gasoline or Petrol | C13: 1f2g3h4j5k6l | D13: 45066.132 | E13: EngineStatusRecord | I13: Cranking voltage | J13: 12.21474 | K13: V
A14: vehicle1 | B14: Vehicle, Gasoline or Petrol | C14: 1f2g3h4j5k6l | D14: 45066.132 | E14: EngineStatusRecord | I14: Cranking voltage | J14: 12.03584 | K14: V
A15: vehicle1 | B15: Vehicle, Gasoline or Petrol | C15: 1f2g3h4j5k6l | D15: 45066.132 | E15: EngineStatusRecord | I15: Cranking voltage | J15: 8.77986 | K15: V
A16: vehicle1 | B16: Vehicle, Gasoline or Petrol | C16: 1f2g3h4j5k6l | D16: 45066.132 | E16: DebugRecord
A17: vehicle1 | B17: Vehicle, Gasoline or Petrol | C17: 1f2g3h4j5k6l | D17: 45066.132 | E17: EngineStatusRecord | I17: Cranking voltage | J17: 9.88904 | K17: V
A18: vehicle1 | B18: Vehicle, Gasoline or Petrol | C18: 1f2g3h4j5k6l | D18: 45066.132 | E18: DebugRecord
A19: vehicle1 | B19: Vehicle, Gasoline or Petrol | C19: 1f2g3h4j5k6l | D19: 45066.132 | E19: DebugRecord
A20: vehicle1 | B20: Vehicle, Gasoline or Petrol | C20: 1f2g3h4j5k6l | D20: 45066.132 | E20: DebugRecord
A21: vehicle1 | B21: Vehicle, Gasoline or Petrol | C21: 1f2g3h4j5k6l | D21: 45066.132 | E21: DebugRecord
A22: vehicle1 | B22: Vehicle, Gasoline or Petrol | C22: 1f2g3h4j5k6l | D22: 45066.132 | E22: DebugRecord
A23: vehicle1 | B23: Vehicle, Gasoline or Petrol | C23: 1f2g3h4j5k6l | D23: 45066.132 | E23: DebugRecord
A24: vehicle1 | B24: Vehicle, Gasoline or Petrol | C24: 1f2g3h4j5k6l | D24: 45066.132 | E24: DebugRecord
A25: vehicle1 | B25: Vehicle, Gasoline or Petrol | C25: 1f2g3h4j5k6l | D25: 45066.132 | E25: DebugRecord
A26: vehicle1 | B26: Vehicle, Gasoline or Petrol | C26: 1f2g3h4j5k6l | D26: 45066.132 | E26: DebugRecord
A27: vehicle1 | B27: Vehicle, Gasoline or Petrol | C27: 1f2g3h4j5k6l | D27: 45066.132 | E27: DebugRecord
A28: vehicle1 | B28: Vehicle, Gasoline or Petrol | C28: 1f2g3h4j5k6l | D28: 45066.132 | E28: DebugRecord
A29: vehicle1 | B29: Vehicle, Gasoline or Petrol | C29: 1f2g3h4j5k6l | D29: 45066.132 | E29: DebugRecord
... A33: vehicle1 | B33: Vehicle, Gasoline or Petrol | C33: 1f2g3h4j5k6l | D33: 45066.132 | E33: DebugRecord
A34: vehicle1 | B34: Vehicle, Gasoline or Petrol | C34: 1f2g3h4j5k6l | D34: 45066.132 | E34: EngineStatusRecord | I34: Cranking voltage | J34: 10.74776 | K34: V
A35: vehicle1 | B35: Vehicle, Gasoline or Petrol | C35: 1f2g3h4j5k6l | D35: 45066.132 | E35: DebugRecord
A36: vehicle1 | B36: Vehicle, Gasoline or Petrol | C36: 1f2g3h4j5k6l | D36: 45066.132 | E36: DebugRecord
A37: vehicle1 | B37: Vehicle, Gasoline or Petrol | C37: 1f2g3h4j5k6l | D37: 45066.132 | E37: DebugRecord
A38: vehicle1 | B38: Vehicle, Gasoline or Petrol | C38: 1f2g3h4j5k6l | D38: 45066.132 | E38: DebugRecord
A39: vehicle1 | B39: Vehicle, Gasoline or Petrol | C39: 1f2g3h4j5k6l | D39: 45066.132 | E39: EngineStatusRecord | I39: Cranking voltage | J39: 11.64226 | K39: V
A40: vehicle1 | B40: Vehicle, Gasoline or Petrol | C40: 1f2g3h4j5k6l | D40: 45066.132 | E40: EngineStatusRecord | I40: Cranking voltage | J40: 12.71566 | K40: V
A41: vehicle1 | B41: Vehicle, Gasoline or Petrol | C41: 1f2g3h4j5k6l | D41: 45066.132 | E41: DebugRecord
A42: vehicle1 | B42: Vehicle, Gasoline or Petrol | C42: 1f2g3h4j5k6l | D42: 45066.132 | E42: DebugRecord
A43: vehicle1 | B43: Vehicle, Gasoline or Petrol | C43: 1f2g3h4j5k6l | D43: 45066.132 | E43: EngineStatusRecord | I43: Cranking voltage | J43: 13.68172 | K43: V
...

Sheet Report
A1: Fuel Tax Distance Records (IFTA) | S1: =Data!B2 -> 45443.579
A2: =Data!B1 -> abc_company
A4: Date
A5: From | B5: =Data!B3 -> 45442.854
A6: To | B6: =Data!B4 -> 45442.896
A7: Days | B7: =B6-B5 -> 0.041666667
A9: Time Zone | B9: =Data!B5 -> America/New_York
A10: Speed Unit | B10: =Data!B6 -> km/h
G11: Canada | H11: USA
A12: Device | B12: Device Group | C12: Engine VIN | D12: Date Time | E12: Location | F12: Address | G12: h1 | H12: h2 | I12: h3 | J12: h4 | K12: h5 | L12: h6 | M12: h7 | N12: h8 | O12: h9 | P12: h10 | Q12: State Code | R12: State | S12: Lon | T12: Lat | U12: Longitude | V12: Latitude | W12: Engine Diagnostic | X12: Engine Status
A13: =Data!A11 -> vehicle1 | B13: =Data!B11 -> Vehicle, Gasoline or Petrol | C13: =Data!C11 -> 1f2g3h4j5k6l | D13: =Data!D11 -> 45066.153 | E13: =IF(Data!E11="GpsRecord",Data!F11,"") | F13: =IF(E13<>"",E13, IF(F12<>$F$12, F12, "")) | G13: =ISNUMBER(FIND($G$11,E13)) -> FALSE | H13: =ISNUMBER(FIND($H$11,E13)) -> FALSE | I13: =OR(G13,H13) -> FALSE | J13: =IFERROR(MID(E13,FIND(": ",E13)+2,255),E13) | K13: =IFERROR(RIGHT(J13,LEN(J13)-FIND("@",SUBSTITUTE(J13,",","@",LEN(J13)-LEN(SUBSTITUTE(J13,",",""))),1)),J13) | L13: =","&K13 -> , | M13: =IF(I13,SUBSTITUTE(J13,L13,""),J13) | N13: =IFERROR(RIGHT(M13,LEN(M13)-FIND("@",SUBSTITUTE(M13,",","@",LEN(M13)-LEN(SUBSTITUTE(M13,",",""))),1)),M13) | O13: =IFERROR(RIGHT(N13,LEN(N13)-FIND("@",SUBSTITUTE(N13," ","@",LEN(N13)-LEN(SUBSTITUTE(N13," ",""))),1)),N13) | P13: =SUBSTITUTE(N13,CONCATENATE(" ",O13),"") | Q13: =IF(G13, MID(P13,2,2),RIGHT(P13,2)) | R13: =IF(Q13<>"",Q13, IF(R12<>$R$12, R12, "")) | S13: =IF(Data!E11="GpsRecord",Data!G11,"") | T13: =IF(Data!E11="GpsRecord",Data!H11,"") | U13: =IF(S13<>"", S13, IF(U12<>$U$12, U12, "")) | V13: =IF(T13<>"", T13, IF(V12<>$V$12, V12, "")) | W13: =Data!I11 -> 0 | X13: =CONCATENATE(Data!J11, " ", Data!K11)
A14: =Data!A12 -> vehicle1 | B14: =Data!B12 -> Vehicle, Gasoline or Petrol | C14: =Data!C12 -> 1f2g3h4j5k6l | D14: =Data!D12 -> 45066.132 | E14: =IF(Data!E12="GpsRecord",Data!F12,"") | F14: =IF(E14<>"",E14, IF(F13<>$F$12, F13, "")) | G14: =ISNUMBER(FIND($G$11,E14)) -> FALSE | H14: =ISNUMBER(FIND($H$11,E14)) -> FALSE | I14: =OR(G14,H14) -> FALSE | J14: =IFERROR(MID(E14,FIND(": ",E14)+2,255),E14) | K14: =IFERROR(RIGHT(J14,LEN(J14)-FIND("@",SUBSTITUTE(J14,",","@",LEN(J14)-LEN(SUBSTITUTE(J14,",",""))),1)),J14) | L14: =","&K14 -> , | M14: =IF(I14,SUBSTITUTE(J14,L14,""),J14) | N14: =IFERROR(RIGHT(M14,LEN(M14)-FIND("@",SUBSTITUTE(M14,",","@",LEN(M14)-LEN(SUBSTITUTE(M14,",",""))),1)),M14) | O14: =IFERROR(RIGHT(N14,LEN(N14)-FIND("@",SUBSTITUTE(N14," ","@",LEN(N14)-LEN(SUBSTITUTE(N14," ",""))),1)),N14) | P14: =SUBSTITUTE(N14,CONCATENATE(" ",O14),"") | Q14: =IF(G14, MID(P14,2,2),RIGHT(P14,2)) | R14: =IF(Q14<>"",Q14, IF(R13<>$R$12, R13, "")) | S14: =IF(Data!E12="GpsRecord",Data!G12,"") | T14: =IF(Data!E12="GpsRecord",Data!H12,"") | U14: =IF(S14<>"", S14, IF(U13<>$U$12, U13, "")) | V14: =IF(T14<>"", T14, IF(V13<>$V$12, V13, "")) | W14: =Data!I12 -> Cranking voltage | X14: =CONCATENATE(Data!J12, " ", Data!K12) -> 12.39364 V
A15: =Data!A13 -> vehicle1 | B15: =Data!B13 -> Vehicle, Gasoline or Petrol | C15: =Data!C13 -> 1f2g3h4j5k6l | D15: =Data!D13 -> 45066.132 | E15: =IF(Data!E13="GpsRecord",Data!F13,"") | F15: =IF(E15<>"",E15, IF(F14<>$F$12, F14, "")) | G15: =ISNUMBER(FIND($G$11,E15)) -> FALSE | H15: =ISNUMBER(FIND($H$11,E15)) -> FALSE | I15: =OR(G15,H15) -> FALSE | J15: =IFERROR(MID(E15,FIND(": ",E15)+2,255),E15) | K15: =IFERROR(RIGHT(J15,LEN(J15)-FIND("@",SUBSTITUTE(J15,",","@",LEN(J15)-LEN(SUBSTITUTE(J15,",",""))),1)),J15) | L15: =","&K15 -> , | M15: =IF(I15,SUBSTITUTE(J15,L15,""),J15) | N15: =IFERROR(RIGHT(M15,LEN(M15)-FIND("@",SUBSTITUTE(M15,",","@",LEN(M15)-LEN(SUBSTITUTE(M15,",",""))),1)),M15) | O15: =IFERROR(RIGHT(N15,LEN(N15)-FIND("@",SUBSTITUTE(N15," ","@",LEN(N15)-LEN(SUBSTITUTE(N15," ",""))),1)),N15) | P15: =SUBSTITUTE(N15,CONCATENATE(" ",O15),"") | Q15: =IF(G15, MID(P15,2,2),RIGHT(P15,2)) | R15: =IF(Q15<>"",Q15, IF(R14<>$R$12, R14, "")) | S15: =IF(Data!E13="GpsRecord",Data!G13,"") | T15: =IF(Data!E13="GpsRecord",Data!H13,"") | U15: =IF(S15<>"", S15, IF(U14<>$U$12, U14, "")) | V15: =IF(T15<>"", T15, IF(V14<>$V$12, V14, "")) | W15: =Data!I13 -> Cranking voltage | X15: =CONCATENATE(Data!J13, " ", Data!K13) -> 12.21474 V
A16: =Data!A14 -> vehicle1 | B16: =Data!B14 -> Vehicle, Gasoline or Petrol | C16: =Data!C14 -> 1f2g3h4j5k6l | D16: =Data!D14 -> 45066.132 | E16: =IF(Data!E14="GpsRecord",Data!F14,"") | F16: =IF(E16<>"",E16, IF(F15<>$F$12, F15, "")) | G16: =ISNUMBER(FIND($G$11,E16)) -> FALSE | H16: =ISNUMBER(FIND($H$11,E16)) -> FALSE | I16: =OR(G16,H16) -> FALSE | J16: =IFERROR(MID(E16,FIND(": ",E16)+2,255),E16) | K16: =IFERROR(RIGHT(J16,LEN(J16)-FIND("@",SUBSTITUTE(J16,",","@",LEN(J16)-LEN(SUBSTITUTE(J16,",",""))),1)),J16) | L16: =","&K16 -> , | M16: =IF(I16,SUBSTITUTE(J16,L16,""),J16) | N16: =IFERROR(RIGHT(M16,LEN(M16)-FIND("@",SUBSTITUTE(M16,",","@",LEN(M16)-LEN(SUBSTITUTE(M16,",",""))),1)),M16) | O16: =IFERROR(RIGHT(N16,LEN(N16)-FIND("@",SUBSTITUTE(N16," ","@",LEN(N16)-LEN(SUBSTITUTE(N16," ",""))),1)),N16) | P16: =SUBSTITUTE(N16,CONCATENATE(" ",O16),"") | Q16: =IF(G16, MID(P16,2,2),RIGHT(P16,2)) | R16: =IF(Q16<>"",Q16, IF(R15<>$R$12, R15, "")) | S16: =IF(Data!E14="GpsRecord",Data!G14,"") | T16: =IF(Data!E14="GpsRecord",Data!H14,"") | U16: =IF(S16<>"", S16, IF(U15<>$U$12, U15, "")) | V16: =IF(T16<>"", T16, IF(V15<>$V$12, V15, "")) | W16: =Data!I14 -> Cranking voltage | X16: =CONCATENATE(Data!J14, " ", Data!K14) -> 12.03584 V
A17: =Data!A15 -> vehicle1 | B17: =Data!B15 -> Vehicle, Gasoline or Petrol | C17: =Data!C15 -> 1f2g3h4j5k6l | D17: =Data!D15 -> 45066.132 | E17: =IF(Data!E15="GpsRecord",Data!F15,"") | F17: =IF(E17<>"",E17, IF(F16<>$F$12, F16, "")) | G17: =ISNUMBER(FIND($G$11,E17)) -> FALSE | H17: =ISNUMBER(FIND($H$11,E17)) -> FALSE | I17: =OR(G17,H17) -> FALSE | J17: =IFERROR(MID(E17,FIND(": ",E17)+2,255),E17) | K17: =IFERROR(RIGHT(J17,LEN(J17)-FIND("@",SUBSTITUTE(J17,",","@",LEN(J17)-LEN(SUBSTITUTE(J17,",",""))),1)),J17) | L17: =","&K17 -> , | M17: =IF(I17,SUBSTITUTE(J17,L17,""),J17) | N17: =IFERROR(RIGHT(M17,LEN(M17)-FIND("@",SUBSTITUTE(M17,",","@",LEN(M17)-LEN(SUBSTITUTE(M17,",",""))),1)),M17) | O17: =IFERROR(RIGHT(N17,LEN(N17)-FIND("@",SUBSTITUTE(N17," ","@",LEN(N17)-LEN(SUBSTITUTE(N17," ",""))),1)),N17) | P17: =SUBSTITUTE(N17,CONCATENATE(" ",O17),"") | Q17: =IF(G17, MID(P17,2,2),RIGHT(P17,2)) | R17: =IF(Q17<>"",Q17, IF(R16<>$R$12, R16, "")) | S17: =IF(Data!E15="GpsRecord",Data!G15,"") | T17: =IF(Data!E15="GpsRecord",Data!H15,"") | U17: =IF(S17<>"", S17, IF(U16<>$U$12, U16, "")) | V17: =IF(T17<>"", T17, IF(V16<>$V$12, V16, "")) | W17: =Data!I15 -> Cranking voltage | X17: =CONCATENATE(Data!J15, " ", Data!K15) -> 8.77986 V
A18: =Data!A16 -> vehicle1 | B18: =Data!B16 -> Vehicle, Gasoline or Petrol | C18: =Data!C16 -> 1f2g3h4j5k6l | D18: =Data!D16 -> 45066.132 | E18: =IF(Data!E16="GpsRecord",Data!F16,"") | F18: =IF(E18<>"",E18, IF(F17<>$F$12, F17, "")) | G18: =ISNUMBER(FIND($G$11,E18)) -> FALSE | H18: =ISNUMBER(FIND($H$11,E18)) -> FALSE | I18: =OR(G18,H18) -> FALSE | J18: =IFERROR(MID(E18,FIND(": ",E18)+2,255),E18) | K18: =IFERROR(RIGHT(J18,LEN(J18)-FIND("@",SUBSTITUTE(J18,",","@",LEN(J18)-LEN(SUBSTITUTE(J18,",",""))),1)),J18) | L18: =","&K18 -> , | M18: =IF(I18,SUBSTITUTE(J18,L18,""),J18) | N18: =IFERROR(RIGHT(M18,LEN(M18)-FIND("@",SUBSTITUTE(M18,",","@",LEN(M18)-LEN(SUBSTITUTE(M18,",",""))),1)),M18) | O18: =IFERROR(RIGHT(N18,LEN(N18)-FIND("@",SUBSTITUTE(N18," ","@",LEN(N18)-LEN(SUBSTITUTE(N18," ",""))),1)),N18) | P18: =SUBSTITUTE(N18,CONCATENATE(" ",O18),"") | Q18: =IF(G18, MID(P18,2,2),RIGHT(P18,2)) | R18: =IF(Q18<>"",Q18, IF(R17<>$R$12, R17, "")) | S18: =IF(Data!E16="GpsRecord",Data!G16,"") | T18: =IF(Data!E16="GpsRecord",Data!H16,"") | U18: =IF(S18<>"", S18, IF(U17<>$U$12, U17, "")) | V18: =IF(T18<>"", T18, IF(V17<>$V$12, V17, "")) | W18: =Data!I16 -> 0 | X18: =CONCATENATE(Data!J16, " ", Data!K16)
A19: =Data!A17 -> vehicle1 | B19: =Data!B17 -> Vehicle, Gasoline or Petrol | C19: =Data!C17 -> 1f2g3h4j5k6l | D19: =Data!D17 -> 45066.132 | E19: =IF(Data!E17="GpsRecord",Data!F17,"") | F19: =IF(E19<>"",E19, IF(F18<>$F$12, F18, "")) | G19: =ISNUMBER(FIND($G$11,E19)) -> FALSE | H19: =ISNUMBER(FIND($H$11,E19)) -> FALSE | I19: =OR(G19,H19) -> FALSE | J19: =IFERROR(MID(E19,FIND(": ",E19)+2,255),E19) | K19: =IFERROR(RIGHT(J19,LEN(J19)-FIND("@",SUBSTITUTE(J19,",","@",LEN(J19)-LEN(SUBSTITUTE(J19,",",""))),1)),J19) | L19: =","&K19 -> , | M19: =IF(I19,SUBSTITUTE(J19,L19,""),J19) | N19: =IFERROR(RIGHT(M19,LEN(M19)-FIND("@",SUBSTITUTE(M19,",","@",LEN(M19)-LEN(SUBSTITUTE(M19,",",""))),1)),M19) | O19: =IFERROR(RIGHT(N19,LEN(N19)-FIND("@",SUBSTITUTE(N19," ","@",LEN(N19)-LEN(SUBSTITUTE(N19," ",""))),1)),N19) | P19: =SUBSTITUTE(N19,CONCATENATE(" ",O19),"") | Q19: =IF(G19, MID(P19,2,2),RIGHT(P19,2)) | R19: =IF(Q19<>"",Q19, IF(R18<>$R$12, R18, "")) | S19: =IF(Data!E17="GpsRecord",Data!G17,"") | T19: =IF(Data!E17="GpsRecord",Data!H17,"") | U19: =IF(S19<>"", S19, IF(U18<>$U$12, U18, "")) | V19: =IF(T19<>"", T19, IF(V18<>$V$12, V18, "")) | W19: =Data!I17 -> Cranking voltage | X19: =CONCATENATE(Data!J17, " ", Data!K17) -> 9.88904 V
A20: =Data!A18 -> vehicle1 | B20: =Data!B18 -> Vehicle, Gasoline or Petrol | C20: =Data!C18 -> 1f2g3h4j5k6l | D20: =Data!D18 -> 45066.132 | E20: =IF(Data!E18="GpsRecord",Data!F18,"") | F20: =IF(E20<>"",E20, IF(F19<>$F$12, F19, "")) | G20: =ISNUMBER(FIND($G$11,E20)) -> FALSE | H20: =ISNUMBER(FIND($H$11,E20)) -> FALSE | I20: =OR(G20,H20) -> FALSE | J20: =IFERROR(MID(E20,FIND(": ",E20)+2,255),E20) | K20: =IFERROR(RIGHT(J20,LEN(J20)-FIND("@",SUBSTITUTE(J20,",","@",LEN(J20)-LEN(SUBSTITUTE(J20,",",""))),1)),J20) | L20: =","&K20 -> , | M20: =IF(I20,SUBSTITUTE(J20,L20,""),J20) | N20: =IFERROR(RIGHT(M20,LEN(M20)-FIND("@",SUBSTITUTE(M20,",","@",LEN(M20)-LEN(SUBSTITUTE(M20,",",""))),1)),M20) | O20: =IFERROR(RIGHT(N20,LEN(N20)-FIND("@",SUBSTITUTE(N20," ","@",LEN(N20)-LEN(SUBSTITUTE(N20," ",""))),1)),N20) | P20: =SUBSTITUTE(N20,CONCATENATE(" ",O20),"") | Q20: =IF(G20, MID(P20,2,2),RIGHT(P20,2)) | R20: =IF(Q20<>"",Q20, IF(R19<>$R$12, R19, "")) | S20: =IF(Data!E18="GpsRecord",Data!G18,"") | T20: =IF(Data!E18="GpsRecord",Data!H18,"") | U20: =IF(S20<>"", S20, IF(U19<>$U$12, U19, "")) | V20: =IF(T20<>"", T20, IF(V19<>$V$12, V19, "")) | W20: =Data!I18 -> 0 | X20: =CONCATENATE(Data!J18, " ", Data!K18)
A21: =Data!A19 -> vehicle1 | B21: =Data!B19 -> Vehicle, Gasoline or Petrol | C21: =Data!C19 -> 1f2g3h4j5k6l | D21: =Data!D19 -> 45066.132 | E21: =IF(Data!E19="GpsRecord",Data!F19,"") | F21: =IF(E21<>"",E21, IF(F20<>$F$12, F20, "")) | G21: =ISNUMBER(FIND($G$11,E21)) -> FALSE | H21: =ISNUMBER(FIND($H$11,E21)) -> FALSE | I21: =OR(G21,H21) -> FALSE | J21: =IFERROR(MID(E21,FIND(": ",E21)+2,255),E21) | K21: =IFERROR(RIGHT(J21,LEN(J21)-FIND("@",SUBSTITUTE(J21,",","@",LEN(J21)-LEN(SUBSTITUTE(J21,",",""))),1)),J21) | L21: =","&K21 -> , | M21: =IF(I21,SUBSTITUTE(J21,L21,""),J21) | N21: =IFERROR(RIGHT(M21,LEN(M21)-FIND("@",SUBSTITUTE(M21,",","@",LEN(M21)-LEN(SUBSTITUTE(M21,",",""))),1)),M21) | O21: =IFERROR(RIGHT(N21,LEN(N21)-FIND("@",SUBSTITUTE(N21," ","@",LEN(N21)-LEN(SUBSTITUTE(N21," ",""))),1)),N21) | P21: =SUBSTITUTE(N21,CONCATENATE(" ",O21),"") | Q21: =IF(G21, MID(P21,2,2),RIGHT(P21,2)) | R21: =IF(Q21<>"",Q21, IF(R20<>$R$12, R20, "")) | S21: =IF(Data!E19="GpsRecord",Data!G19,"") | T21: =IF(Data!E19="GpsRecord",Data!H19,"") | U21: =IF(S21<>"", S21, IF(U20<>$U$12, U20, "")) | V21: =IF(T21<>"", T21, IF(V20<>$V$12, V20, "")) | W21: =Data!I19 -> 0 | X21: =CONCATENATE(Data!J19, " ", Data!K19)
A22: =Data!A20 -> vehicle1 | B22: =Data!B20 -> Vehicle, Gasoline or Petrol | C22: =Data!C20 -> 1f2g3h4j5k6l | D22: =Data!D20 -> 45066.132 | E22: =IF(Data!E20="GpsRecord",Data!F20,"") | F22: =IF(E22<>"",E22, IF(F21<>$F$12, F21, "")) | G22: =ISNUMBER(FIND($G$11,E22)) -> FALSE | H22: =ISNUMBER(FIND($H$11,E22)) -> FALSE | I22: =OR(G22,H22) -> FALSE | J22: =IFERROR(MID(E22,FIND(": ",E22)+2,255),E22) | K22: =IFERROR(RIGHT(J22,LEN(J22)-FIND("@",SUBSTITUTE(J22,",","@",LEN(J22)-LEN(SUBSTITUTE(J22,",",""))),1)),J22) | L22: =","&K22 -> , | M22: =IF(I22,SUBSTITUTE(J22,L22,""),J22) | N22: =IFERROR(RIGHT(M22,LEN(M22)-FIND("@",SUBSTITUTE(M22,",","@",LEN(M22)-LEN(SUBSTITUTE(M22,",",""))),1)),M22) | O22: =IFERROR(RIGHT(N22,LEN(N22)-FIND("@",SUBSTITUTE(N22," ","@",LEN(N22)-LEN(SUBSTITUTE(N22," ",""))),1)),N22) | P22: =SUBSTITUTE(N22,CONCATENATE(" ",O22),"") | Q22: =IF(G22, MID(P22,2,2),RIGHT(P22,2)) | R22: =IF(Q22<>"",Q22, IF(R21<>$R$12, R21, "")) | S22: =IF(Data!E20="GpsRecord",Data!G20,"") | T22: =IF(Data!E20="GpsRecord",Data!H20,"") | U22: =IF(S22<>"", S22, IF(U21<>$U$12, U21, "")) | V22: =IF(T22<>"", T22, IF(V21<>$V$12, V21, "")) | W22: =Data!I20 -> 0 | X22: =CONCATENATE(Data!J20, " ", Data!K20)
A23: =Data!A21 -> vehicle1 | B23: =Data!B21 -> Vehicle, Gasoline or Petrol | C23: =Data!C21 -> 1f2g3h4j5k6l | D23: =Data!D21 -> 45066.132 | E23: =IF(Data!E21="GpsRecord",Data!F21,"") | F23: =IF(E23<>"",E23, IF(F22<>$F$12, F22, "")) | G23: =ISNUMBER(FIND($G$11,E23)) -> FALSE | H23: =ISNUMBER(FIND($H$11,E23)) -> FALSE | I23: =OR(G23,H23) -> FALSE | J23: =IFERROR(MID(E23,FIND(": ",E23)+2,255),E23) | K23: =IFERROR(RIGHT(J23,LEN(J23)-FIND("@",SUBSTITUTE(J23,",","@",LEN(J23)-LEN(SUBSTITUTE(J23,",",""))),1)),J23) | L23: =","&K23 -> , | M23: =IF(I23,SUBSTITUTE(J23,L23,""),J23) | N23: =IFERROR(RIGHT(M23,LEN(M23)-FIND("@",SUBSTITUTE(M23,",","@",LEN(M23)-LEN(SUBSTITUTE(M23,",",""))),1)),M23) | O23: =IFERROR(RIGHT(N23,LEN(N23)-FIND("@",SUBSTITUTE(N23," ","@",LEN(N23)-LEN(SUBSTITUTE(N23," ",""))),1)),N23) | P23: =SUBSTITUTE(N23,CONCATENATE(" ",O23),"") | Q23: =IF(G23, MID(P23,2,2),RIGHT(P23,2)) | R23: =IF(Q23<>"",Q23, IF(R22<>$R$12, R22, "")) | S23: =IF(Data!E21="GpsRecord",Data!G21,"") | T23: =IF(Data!E21="GpsRecord",Data!H21,"") | U23: =IF(S23<>"", S23, IF(U22<>$U$12, U22, "")) | V23: =IF(T23<>"", T23, IF(V22<>$V$12, V22, "")) | W23: =Data!I21 -> 0 | X23: =CONCATENATE(Data!J21, " ", Data!K21)
A24: =Data!A22 -> vehicle1 | B24: =Data!B22 -> Vehicle, Gasoline or Petrol | C24: =Data!C22 -> 1f2g3h4j5k6l | D24: =Data!D22 -> 45066.132 | E24: =IF(Data!E22="GpsRecord",Data!F22,"") | F24: =IF(E24<>"",E24, IF(F23<>$F$12, F23, "")) | G24: =ISNUMBER(FIND($G$11,E24)) -> FALSE | H24: =ISNUMBER(FIND($H$11,E24)) -> FALSE | I24: =OR(G24,H24) -> FALSE | J24: =IFERROR(MID(E24,FIND(": ",E24)+2,255),E24) | K24: =IFERROR(RIGHT(J24,LEN(J24)-FIND("@",SUBSTITUTE(J24,",","@",LEN(J24)-LEN(SUBSTITUTE(J24,",",""))),1)),J24) | L24: =","&K24 -> , | M24: =IF(I24,SUBSTITUTE(J24,L24,""),J24) | N24: =IFERROR(RIGHT(M24,LEN(M24)-FIND("@",SUBSTITUTE(M24,",","@",LEN(M24)-LEN(SUBSTITUTE(M24,",",""))),1)),M24) | O24: =IFERROR(RIGHT(N24,LEN(N24)-FIND("@",SUBSTITUTE(N24," ","@",LEN(N24)-LEN(SUBSTITUTE(N24," ",""))),1)),N24) | P24: =SUBSTITUTE(N24,CONCATENATE(" ",O24),"") | Q24: =IF(G24, MID(P24,2,2),RIGHT(P24,2)) | R24: =IF(Q24<>"",Q24, IF(R23<>$R$12, R23, "")) | S24: =IF(Data!E22="GpsRecord",Data!G22,"") | T24: =IF(Data!E22="GpsRecord",Data!H22,"") | U24: =IF(S24<>"", S24, IF(U23<>$U$12, U23, "")) | V24: =IF(T24<>"", T24, IF(V23<>$V$12, V23, "")) | W24: =Data!I22 -> 0 | X24: =CONCATENATE(Data!J22, " ", Data!K22)
... A621: =Data!A619 -> vehicle1 | B621: =Data!B619 -> Vehicle, Gasoline or Petrol | C621: =Data!C619 -> 1f2g3h4j5k6l | D621: =Data!D619 -> 45066.158 | E621: =IF(Data!E619="GpsRecord",Data!F619,"") -> 717 NE 122nd St, Oklahoma City, OK 73114, USA | F621: =IF(E621<>"",E621, IF(F620<>$F$12, F620, "")) -> 717 NE 122nd St, Oklahoma City, OK 73114, USA | G621: =ISNUMBER(FIND($G$11,E621)) -> FALSE | H621: =ISNUMBER(FIND($H$11,E621)) -> TRUE | I621: =OR(G621,H621) -> TRUE | J621: =IFERROR(MID(E621,FIND(": ",E621)+2,255),E621) -> 717 NE 122nd St, Oklahoma City, OK 73114, USA | K621: =IFERROR(RIGHT(J621,LEN(J621)-FIND("@",SUBSTITUTE(J621,",","@",LEN(J621)-LEN(SUBSTITUTE(J621,",",""))),1)),J621) -> USA | L621: =","&K621 -> , USA | M621: =IF(I621,SUBSTITUTE(J621,L621,""),J621) -> 717 NE 122nd St, Oklahoma City, OK 73114 | N621: =IFERROR(RIGHT(M621,LEN(M621)-FIND("@",SUBSTITUTE(M621,",","@",LEN(M621)-LEN(SUBSTITUTE(M621,",",""))),1)),M621) -> OK 73114 | O621: =IFERROR(RIGHT(N621,LEN(N621)-FIND("@",SUBSTITUTE(N621," ","@",LEN(N621)-LEN(SUBSTITUTE(N621," ",""))),1)),N621) -> 73114 | P621: =SUBSTITUTE(N621,CONCATENATE(" ",O621),"") -> OK | Q621: =IF(G621, MID(P621,2,2),RIGHT(P621,2)) -> OK | R621: =IF(Q621<>"",Q621, IF(R620<>$R$12, R620, "")) -> OK | S621: =IF(Data!E619="GpsRecord",Data!G619,"") -> -39.39277 | T621: =IF(Data!E619="GpsRecord",Data!H619,"") -> 33.74227 | U621: =IF(S621<>"", S621, IF(U620<>$U$12, U620, "")) -> -39.39277 | V621: =IF(T621<>"", T621, IF(V620<>$V$12, V620, "")) -> 33.74227 | W621: =Data!I619 -> 0 | X621: =CONCATENATE(Data!J619, " ", Data!K619)

Sheet Summary
A1: Fuel Tax Distance Records (IFTA) | D1: =Data!B2 -> 45443.579
A2: =Data!B1 -> abc_company
A4: Date | D4: =IF(COUNTA(A13:A50)=0, "Data absent in the table below means there is no raw odometer available for this vehicle. Please reach out to your designated support channel for help with pulling a report with odometer values from other sources.", "")
A5: From | B5: =Data!B3 -> 45442.854
A6: To | B6: =Data!B4 -> 45442.896
A7: Days | B7: =B6-B5 -> 0.041666667
A9: Time Zone | B9: =Data!B5 -> America/New_York
A10: Speed Unit | B10: =Data!B6 -> km/h
A12: Device | B12: Device Group | C12: Engine Reported VIN | D12: Date Time | E12: Address | F12: State | G12: Longitude | H12: Latitude | I12: Engine Diagnostic | J12: Odometer
A13: vehicle1 | B13: Vehicle, Gasoline or Petrol | C13: 1f2g3h4j5k6l | D13: 45066.132 | E13: Whispering Pines, 401 Loblolly Cir, Clayton, NC 27520, USA | F13: NC | G13: -39.42104 | H13: 33.73687 | I13: Raw odometer | J13: 82832 km
A14: vehicle1 | B14: Vehicle, Gasoline or Petrol | C14: 1f2g3h4j5k6l | D14: 45066.156 | E14: 40840 Barto St, Leesburg, FL 34788, USA | F14: FL | G14: -39.41052 | H14: 33.72696 | I14: Raw odometer | J14: 82834 km
A15: vehicle1 | B15: Vehicle, Gasoline or Petrol | C15: 1f2g3h4j5k6l | D15: 45066.156 | E15: 1501 E U.s. 6, Hamlet, IN 46532, USA | F15: IN | G15: -39.40432 | H15: 33.73247 | I15: Raw odometer | J15: 82835 km
A16: vehicle1 | B16: Vehicle, Gasoline or Petrol | C16: 1f2g3h4j5k6l | D16: 45066.158 | E16: 717 NE 122nd St, Oklahoma City, OK 73114, USA | F16: OK | G16: -39.39539 | H16: 33.74045 | I16: Raw odometer | J16: 82836 km

Sheet Languages
A1: English | B1: French Canada | C1: Spanish | D1: German | E1: Japanese | F1: Polish | G1: Portuguese-Brazil | H1: Dutch | I1: Italian | J1: Simplified Chinese | K1: Thai | L1: Indonesian | M1: Czech | N1: Swedish | O1: Turkish | P1: Malay | Q1: French France
A2: **Device | B2: Dispositif | C2: Dispositivo | D2: Gerät | E2: デバイス | F2: Urzadzenie | G2: Dispositivo | H2: Apparaat | I2: Dispositivo | J2: 设备 | K2: อุปกรณ์ | L2: Perangkat | M2: Zařízení | N2: Enhet | O2: Aygıt | P2: Peranti | Q2: Boîtier
A3: **First Name | B3: Prénom | C3: Nombre | D3: Vorname | E3: ファーストネー | F3: Imie | G3: Nome | H3: Voornaam | I3: Nome | J3: 名字 | K3: ชื่อ | L3: Nama Depan | M3: Křestní jméno | N3: Förnamn | O3: Ad | P3: Nama pertama | Q3: Prénom
A4: **Last Name | B4: Nom de famille | C4: Apellido | D4: Nachname | E4: ラストネーム | F4: Nazwisko | G4: Sobrenome | H4: Achternaam | I4: Cognome | J4: 姓氏 | K4: นามสกุล | L4: Nama belakang | M4: Příjmení | N4: Efternamn | O4: Soyadı | P4: Nama keluarga | Q4: Nom de famille
A5: **Device Group | B5: Groupe de dispositifs | C5: Grupo de dispositivos | D5: Gerätegruppe | E5: デバイスグループ | F5: Grupa urzadzen | G5: Grupo de dispositivo | H5: Apparaatgroep | I5: Gruppo di dispositivi | J5: 设备的组名 | K5: กลุ่มอุปกรณ์ | L5: Grup Perangkat | M5: Skupina zařízení | N5: Enhetsgrupp | O5: Aygıt Grubu | P5: Kumpulan Peranti | Q5: Groupe de boîtiers
A6: **Driver Name | B6: Nom du conducteur | C6: Nombre del Conductor | D6: Fahrername | E6: ドライバー名 | F6: Imie i nazwisko kierowcy | G6: Nome do motorista | H6: Naam chauffeur | I6: Nome del conducente | J6: 驾驶员名字 | K6: ชื่อผู้ขับ | L6: Nama Pengemudi | M6: Jméno řidiče | N6: Förarnamn | O6: Sürücü Adı | P6: Nama Pemandu | Q6: Nom du conducteur
A7: **Date | B7: Date | C7: Fecha | D7: Datum | E7: データ | F7: Data | G7: Data | H7: Datum | I7: Data | J7: 日期 | K7: วันที่ | L7: Tanggal | M7: Datum | N7: Datum | O7: Tarih | P7: Tarikh | Q7: Date
A8: **Log Time | B8: Heure du registre | C8: Tiempo registrado | D8: Protokollzeit | E8: ログ時間 | F8: Czas pliku dziennika | G8: Hora do registro | H8: Logtijd | I8: Tempo di registro | J8: 日志记录时间 | K8: เวลาที่บันทึก | L8: Waktu Log | M8: Čas protokolu | N8: Loggtid | O8: Kayıt Zamanı | P8: Masa Log | Q8: Heure du registre
A9: **Record Type | B9: Type de record | C9: Tipo de registro | D9: Aufzeichnungstyp | E9: 記録タイプ | F9: Typ rekordu | G9: Tipo de registro | H9: Registratietype | I9: Tipo di record | J9: 记录类型 | K9: ประเภทบันทึก | L9: Jenis Catatan | M9: Typ záznamu | N9: Posttyp | O9: Kayıt Türü | P9: Jenis Rekod | Q9: Type d’enregistrement
A10: **Speed | B10: Vitesse | C10: Velocidad | D10: Geschwindigkeit | E10: スピード | F10: PREDKOSC | G10: VELOCIDADE | H10: SNELHEID | I10: VELOCITÀ | J10: 速度 | K10: ความเร็ว | L10: KECEPATAN | M10: RYCHLOST | N10: HASTIGHET | O10: Hız | P10: KELAJUAN | Q10: VITESSE
A11: **Longitude | B11: Longitude | C11: Longitud | D11: Längengrad | E11: 経度 | F11: Dlugosc geograficzna | G11: Longitude | H11: Lengtegraad | I11: Longitudine | J11: 经度 | K11: ลองจิจูด | L11: Garis Bujur | M11: Zeměpisná délka | N11: Longitud | O11: Boylam | P11: Longitud | Q11: Longitude
A12: **Latitude | B12: Latitude | C12: Latitud | D12: Breitengrad | E12: 緯度 | F12: Szerokosc geograficzna | G12: Latitude | H12: Breedtegraad | I12: Latitudine | J12: 纬度 | K12: ละติจูด | L12: Garis Lintang | M12: Zeměpisná šířka | N12: Latitud | O12: Enlem | P12: Latitud | Q12: Latitude
... A38: **Days | B38: Jours | C38: Días | D38: Tage | E38: 日 | F38: Dni | G38: Dias | H38: Dagen | I38: Giorni | J38: 天 | K38: วัน | L38: Hari | M38: Dny | N38: Dagar | O38: Gün | P38: hari | Q38: jours
