Workbook
Name AllData: Report!$A$12:$AK$98

Sheet Data
A1: CompanyName | B1: Template Company Name
A2: RunDate | B2: 44498.903
A3: FromDate | B3: 44486
A4: ToDate | B4: 44493
A5: TimeZone | B5: America/New_York
A6: DistanceUnit | B6: km
A7: SpeedUnit | B7: km/h
A8: SendReport | B8: TRUE
A9: LastModifiedUser | B9: System
A10: Language | B10: en
A11: DutyStatusDateTime | B11: DutyStatusStatus | C11: DutyStatusDetailDuration | D11: DutyStatusDetailDistance | E11: .StatusLog.Device.DeviceName | F11: .StatusLog.Driver.UserFirstName | G11: .StatusLog.Driver.UserLastName | H11: .StatusLog.Driver.UserName | I11: .StatusLog.Driver.UserEmployeeNo | J11: .StatusLog.Driver.UserTimeZone | K11: DutyStatusDetailTrailers | L11: .StatusLog.Driver.UserAuthorityName
A12: 44486 | B12: OFF | C12: 1.2417466 | E12: Vehicle1 | F12: First 1 | G12: Last 1 | H12: Driver1@abc.com | I12: 1 | J12: America/New_York | K12: Trailer 1 | L12: 1
A13: 44487.242 | B13: ON | C13: 0.00017511574 | E13: Vehicle1 | F13: First 1 | G13: Last 1 | H13: Driver1@abc.com | I13: 1 | J13: America/New_York | L13: 1
A14: 44487.242 | B14: ON | C14: 1.1574074e-07 | E14: Vehicle1 | F14: First 1 | G14: Last 1 | H14: Driver1@abc.com | I14: 1 | J14: America/New_York | K14: Trailer 1, Trailer 2 | L14: 1
A15: 44487.242 | B15: YM | C15: 0.0052007407 | D15: 0.079535514 | E15: Vehicle1 | F15: First 1 | G15: Last 1 | H15: Driver1@abc.com | I15: 1 | J15: America/New_York | L15: 1
A16: 44487.247 | B16: ON | C16: 0.0039076389 | E16: Vehicle1 | F16: First 1 | G16: Last 1 | H16: Driver1@abc.com | I16: 1 | J16: America/New_York | L16: 1
A17: 44487.251 | B17: D | C17: 0.050162269 | D17: 51.340176 | E17: Vehicle1 | F17: First 1 | G17: Last 1 | H17: Driver1@abc.com | I17: 1 | J17: America/New_York | L17: 1
A18: 44487.293 | B18: INT_D | D18: 11.095204 | E18: Vehicle1 | F18: First 1 | G18: Last 1 | H18: Driver1@abc.com | I18: 1 | J18: America/New_York | L18: 1
A19: 44487.301 | B19: ON | C19: 0.004930706 | E19: Vehicle1 | F19: First 1 | G19: Last 1 | H19: Driver1@abc.com | I19: 1 | J19: America/New_York | L19: 1
A20: 44487.306 | B20: D | C20: 0.085960266 | D20: 38.017979 | E20: Vehicle1 | F20: First 1 | G20: Last 1 | H20: Driver1@abc.com | I20: 1 | J20: America/New_York | L20: 1
A21: 44487.348 | B21: INT_D | D21: 23.542513 | E21: Vehicle1 | F21: First 1 | G21: Last 1 | H21: Driver1@abc.com | I21: 1 | J21: America/New_York | L21: 1
A22: 44487.389 | B22: INT_D | D22: 0.19883879 | E22: Vehicle1 | F22: First 1 | G22: Last 1 | H22: Driver1@abc.com | I22: 1 | J22: America/New_York | L22: 1
A23: 44487.392 | B23: ON | C23: 0.0095028935 | E23: Vehicle1 | F23: First 1 | G23: Last 1 | H23: Driver1@abc.com | I23: 1 | J23: America/New_York | L23: 1
A24: 44487.402 | B24: D | C24: 0.021701505 | D24: 11.811024 | E24: Vehicle1 | F24: First 1 | G24: Last 1 | H24: Driver1@abc.com | I24: 1 | J24: America/New_York | L24: 1
A25: 44487.423 | B25: ON | C25: 0.0062734954 | E25: Vehicle1 | F25: First 1 | G25: Last 1 | H25: Driver1@abc.com | I25: 1 | J25: America/New_York | L25: 1
A26: 44487.43 | B26: D | C26: 0.0084252662 | D26: 2.9428141 | E26: Vehicle1 | F26: First 1 | G26: Last 1 | H26: Driver1@abc.com | I26: 1 | J26: America/New_York | L26: 1
A27: 44487.438 | B27: ON | C27: 0.0058221065 | E27: Vehicle1 | F27: First 1 | G27: Last 1 | H27: Driver1@abc.com | I27: 1 | J27: America/New_York | L27: 1
A28: 44487.444 | B28: D | C28: 0.0078467245 | D28: 3.0223496 | E28: Vehicle1 | F28: First 1 | G28: Last 1 | H28: Driver1@abc.com | I28: 1 | J28: America/New_York | L28: 1
A29: 44487.452 | B29: ON | C29: 0.013947523 | E29: Vehicle1 | F29: First 1 | G29: Last 1 | H29: Driver1@abc.com | I29: 1 | J29: America/New_York | L29: 1
A30: 44487.466 | B30: D | C30: 0.013078403 | D30: 7.913784 | E30: Vehicle1 | F30: First 1 | G30: Last 1 | H30: Driver1@abc.com | I30: 1 | J30: America/New_York | L30: 1
A31: 44487.479 | B31: ON | C31: 0.010288843 | E31: Vehicle1 | F31: First 1 | G31: Last 1 | H31: Driver1@abc.com | I31: 1 | J31: America/New_York | L31: 1
A32: 44487.489 | B32: D | C32: 0.021354942 | D32: 8.3512297 | E32: Vehicle1 | F32: First 1 | G32: Last 1 | H32: Driver1@abc.com | I32: 1 | J32: America/New_York | L32: 1
A33: 44487.51 | B33: ON | C33: 0.0047564815 | E33: Vehicle1 | F33: First 1 | G33: Last 1 | H33: Driver1@abc.com | I33: 1 | J33: America/New_York | L33: 1
A34: 44487.515 | B34: D | C34: 0.031715937 | D34: 35.31377 | E34: Vehicle1 | F34: First 1 | G34: Last 1 | H34: Driver1@abc.com | I34: 1 | J34: America/New_York | L34: 1
A35: 44487.547 | B35: ON | C35: 1.1574074e-07 | E35: Vehicle1 | F35: First 1 | G35: Last 1 | H35: Driver1@abc.com | I35: 1 | J35: America/New_York | L35: 1
A36: 44487.547 | B36: YM | C36: 0.0028439005 | D36: 0.039767757 | E36: Vehicle1 | F36: First 1 | G36: Last 1 | H36: Driver1@abc.com | I36: 1 | J36: America/New_York | L36: 1
A37: 44487.55 | B37: ON | C37: 0.013112581 | E37: Vehicle1 | F37: First 1 | G37: Last 1 | H37: Driver1@abc.com | I37: 1 | J37: America/New_York | L37: 1
A38: 44487.563 | B38: ON | C38: 0.006633287 | E38: Vehicle1 | F38: First 1 | G38: Last 1 | H38: Driver1@abc.com | I38: 1 | J38: America/New_York | L38: 1
A39: 44487.569 | B39: D | C39: 0.0032293981 | D39: 1.153265 | E39: Vehicle1 | F39: First 1 | G39: Last 1 | H39: Driver1@abc.com | I39: 1 | J39: America/New_York | L39: 1
A40: 44487.573 | B40: ON | C40: 0.0094907407 | E40: Vehicle1 | F40: First 1 | G40: Last 1 | H40: Driver1@abc.com | I40: 1 | J40: America/New_York | L40: 1
...

Sheet TimeZone
B5: Timezone | C5: GMT Conversion
B6: America/St_Johns | C6: 2.5
B7: Atlantic Standard Time | C7: 4
B8: America/Halifax | C8: 4
B9: Eastern Standard Time | C9: 5
B10: EST5EDT | C10: 5
B11: America/New_York | C11: 5
B12: America/Toronto | C12: 5
B13: America/Montreal | C13: 5
B14: America/Thunder_Bay | C14: 5
B15: Central Standard Time | C15: 6
B16: CST6CDT | C16: 6
B17: America/Chicago | C17: 6
... B25: Alaska Standard Time | C25: 9

Sheet Languages
A1: English | B1: French | C1: Spanish | D1: German | E1: Japanese | F1: Polish | G1: Portuguese-Brazil | H1: Dutch | I1: Italian | J1: Simplified Chinese | K1: Thai | L1: Indonesian | M1: Czech | N1: Swedish
A2: **Driver | B2: Conducteur | C2: Conductor | D2: Fahrer | E2: ドライバー | F2: Kierowca | G2: Motorista | H2: Chauffeur | I2: Conducente | J2: 驾驶员 | K2: ผู้ขับ | L2: Pengemudi | M2: Řidič | N2: Förare
A3: **Driver | B3: Date | C3: Fecha | D3: Datum | E3: データ | F3: Data | G3: Data | H3: Datum | I3: Data | J3: 日期 | K3: วันที่ | L3: Tanggal | M3: Datum | N3: Datum
A4: **Status | B4: État | C4: Estado | D4: Status | E4: ステータス | F4: Status | G4: Status | H4: Status | I4: Stato | J4: 状态 | K4: สถานะ | L4: Status | M4: Stav | N4: Status
A5: **Device | B5: Dispositif | C5: Dispositivo | D5: Gerät | E5: デバイス | F5: Urzadzenie | G5: Dispositivo | H5: Apparaat | I5: Dispositivo | J5: 设备 | K5: อุปกรณ์ | L5: Perangkat | M5: Zařízení | N5: Enhet
A6: **Co-drivers | B6: Co-chauffeurs | C6: Copiloto | D6: Beifahrer | E6: 補助ドライバー | F6: Wspólkierowcy | G6: Comotoristas | H6: Tweede chauffeurs | I6: Secondi conducenti | J6: 副驾驶 | K6: ผู้ช่วยคนขับ | L6: Pendamping Pengemudi | M6: Spolujezdci | N6: Andreförare
A7: **Trailers | B7: Gros porteurs | C7: Remolques | D7: Anhänger | E7: トレーラー | F7: Przyczepy | G7: Reboques | H7: Aanhangers | I7: Rimorchi | J7: 拖车 | K7: รถเทรลเลอร์ | L7: Trailer | M7: Přívěsy | N7: Trailers
A8: **Longitude | B8: Longitude | C8: Longitud | D8: Längengrad | E8: 経度 | F8: Dlugosc geograficzna | G8: Longitude | H8: Lengtegraad | I8: Longitudine | J8: 经度 | K8: ลองจิจูด | L8: Garis Bujur | M8: Zeměpisná délka | N8: Longitud
A9: **Latitude | B9: Latitude | C9: Latitud | D9: Breitengrad | E9: 緯度 | F9: Szerokosc geograficzna | G9: Latitude | H9: Breedtegraad | I9: Latitudine | J9: 纬度 | K9: ละติจูด | L9: Garis Lintang | M9: Zeměpisná šířka | N9: Latitud
A10: **Address | B10: Adresse | C10: Dirección | D10: Adresse | E10: 住所 | F10: Adres | G10: Endereço | H10: Adres | I10: Indirizzo | J10: 地址 | K10: ที่อยู่ | L10: Alamat | M10: Adresa | N10: Adress
A11: **Odometer | B11: Odomètre | C11: Odómetro | D11: Kilometerstand | E11: オドメータ | F11: Licznik kilometrów | G11: Hodômetro | H11: Kilometerteller | I11: Contachilometri | J11: 里程表 | K11: มาตรระยะทาง | L11: Odometer | M11: Počítadlo ujetých kilometrů | N11: Mätarställning
A12: **Duration | B12: durée | C12: duración | D12: Dauer | E12: 期間 | F12: Czas trwania | G12: duração | H12: duur | I12: durata | J12: 时长 | K12: ระยะเวลา | L12: Durasi | M12: doba trvání | N12: varaktighet
... A26: **Time Zone | B26: Fuseau horaire | C26: Huso horario | D26: Zeitzone | E26: タイムゾーン | F26: Strefa czasowa | G26: Zona horária | H26: Tijdzone | I26: Fuso orario | J26: 时区 | K26: โซนเวลา | L26: Zona Waktu | M26: Časové pásmo | N26: Tidszon
A27: **Driver Name
A28: **Employee Number
A29: **Small Fleet Payroll Report
A30: **Driver Time Zone
A31: **Date and Time
A32: **Days
A33: **Date

Sheet Report
A1: **Small Fleet Payroll Report | C1: =Data!B2 -> 44498.903
A2: =Data!B1 -> Template Company Name
A4: **Date
A5: **From | B5: =Data!B3 -> 44486
A6: **To | B6: =Data!B4 -> 44493
A7: **Days | B7: =B6-B5 -> 6.9999884
A9: **Time Zone | B9: =Data!B5 -> America/New_York | C9: =VLOOKUP(B9, TimeZone!$B$5:$C$25, 2, FALSE) -> 5
A10: **Distance Unit | B10: =Data!B6 -> km
A12: **Driver Name | B12: **Driver | C12: **Employee Number | D12: Data Date | E12: **Driver Time Zone | F12: Factor | G12: **Date and Time | H12: **Date | I12: Time | J12: LDD | K12: Count LDD | L12: **Device | M12: last LDD | N12: Vehicle List | O12: **Trailers | P12: Trailer List | Q12: V and T help1 | R12: V and T help2 | S12: Activity | T12: Datastatus | U12: DataDistance | V12: **Status | W12: **Duration | X12: ClockIn | Y12: ClockOut | Z12: FALSE | AA12: ONLogStart | AB12: ONLogEnd | AC12: ONDutyTime | AD12: DLogStart | AE12: DLogEnd | AF12: DDutyTime | AG12: TotalTime | AH12: OFFLogStart | AI12: OFFLogEnd | AJ12: OFFDutyTime | AK12: **Authority Name
A13: =CONCATENATE(Data!F12, " ", Data!G12) -> First 1 Last 1 | B13: =Data!H12 -> Driver1@abc.com | C13: =Data!I12 -> 1 | D13: =Data!A12 -> 44486 | E13: =Data!J12 -> America/New_York | F13: =(VLOOKUP(E13, TimeZone[], 2, FALSE)-$C$9)/24 -> 0 | G13: =(INT(D13)+TIME(HOUR(D13), MINUTE(D13), SECOND(D13)))-F13 -> 44486 | H13: =INT(G13) -> 44486 | I13: =MOD(G13, 1) -> 0 | J13: =COUNTIFS(A:A, A13,H:H, H13) -> 1 | K13: =COUNTIFS($A$13:A13, A13,$H$13:H13, H13) -> 1 | L13: =Data!E12 -> Vehicle1 | M13: =OR(A13<>A14,H13<>H14) -> TRUE | N13: =IF(AND(A12=A13,H12=H13),IF(ISERROR(FIND(L13,N12)),N12&", "&L13,N12),L13) -> Vehicle1 | O13: =Data!K12 -> Trailer 1 | P13: =IF(AND(A12=A13,H12=H13),IF(O12="",O13,IF(AND(ISERROR(FIND(O13,P12)),Data!K12<>""),P12&", "&O13,P12)),IF(Data!K12<>"",O13,"")) -> Trailer 1 | Q13: =IF(M13,"Vehicle(s): "&N13&CHAR(10)&"Trailer(s): "&P13,"") -> Vehicle(s): Vehicle1 Trailer(s): Trailer 1 | R13: =B13&H13&K13 -> Driver1@abc.com444861 | S13: =INDEX(Q:Q, MATCH(CONCATENATE(B13, H13, J13),R:R, 0)) -> Vehicle(s): Vehicle1 Trailer(s): Trailer 1 | T13: =Data!B12 -> OFF | U13: =IF(Data!D12<>"", Data!D12, "") | V13: =IF(OR(ISNUMBER(FIND("OFF",T13)),ISNUMBER(FIND("SB",T13)),ISNUMBER(FIND("PC",T13))),"OFF",IF(OR(ISNUMBER(FIND("ON",T13)),ISNUMBER(FIND("YM",T13))),"ON",IF(ISNUMBER(FIND("D", T13)), "D", "NA"))) -> OFF | W13: =Data!C12 -> 1.2417466 | X13: =IF(OR(T13="ON", T13="D", IF(J13=1, TRUE, Z12)), IF(AND(IF(J13=1, TRUE, Z12), T12<>"OFF"), H13, G13), "") -> 44486 | Y13: =IF(X13<>"", IF(AND(J13<>1, V13<>"OFF"), IF(Z13, IF(Z12, IF(V13="OFF", G13, H13+1), H13+1), IF(Z12, IF(V13="OFF", G13, G13+W13), X13+W13)),H13), "") -> 44486 | Z13: =INT(G13+W13)<>H13 -> TRUE | AA13: =IF(OR(V13="ON", Z12), IF(AND(Z12, V12="ON"), H13, G13), "") | AB13: =IF(AA13<>"", IF(Z13, IF(Z12, IF(V13<>"ON", G13, H13+1), H13+1), IF(Z12, IF(V13<>"ON", G13, G13+W13), AA13+W13)), "") | AC13: =IFERROR(AB13-AA13, 0) -> 0 | AD13: =IF(OR(V13="D", Z12), IF(AND(Z12, V12="D"), H13, G13), "") | AE13: =IF(AD13<>"", IF(Z13, IF(Z12, IF(V13<>"D", G13, H13+1), H13+1), IF(Z12, IF(V13<>"D", G13, G13+W13), AD13+W13)), "") | AF13: =IFERROR(AE13-AD13, 0) -> 0 | AG13: =AC13+AF13 -> 0 | AH13: =IF(OR(V13="OFF", Z12), IF(AND(Z12, V12="OFF"), H13, G13), "") -> 44486 | AI13: =IF(AH13<>"", IF(Z13, IF(Z12, IF(V13<>"OFF", G13, H13+1), H13+1), IF(Z12, IF(V13<>"OFF", G13, G13+W13), AH13+W13)), "") -> 44487 | AJ13: =IFERROR(AI13-AH13, 0) -> 1 | AK13: =Data!L12 -> 1
A14: =CONCATENATE(Data!F13, " ", Data!G13) -> First 1 Last 1 | B14: =Data!H13 -> Driver1@abc.com | C14: =Data!I13 -> 1 | D14: =Data!A13 -> 44487.242 | E14: =Data!J13 -> America/New_York | F14: =(VLOOKUP(E14, TimeZone[], 2, FALSE)-$C$9)/24 -> 0 | G14: =(INT(D14)+TIME(HOUR(D14), MINUTE(D14), SECOND(D14)))-F14 -> 44487.242 | H14: =INT(G14) -> 44487 | I14: =MOD(G14, 1) -> 0.24174769 | J14: =COUNTIFS(A:A, A14,H:H, H14) -> 45 | K14: =COUNTIFS($A$13:A14, A14,$H$13:H14, H14) -> 1 | L14: =Data!E13 -> Vehicle1 | M14: =OR(A14<>A15,H14<>H15) -> FALSE | N14: =IF(AND(A13=A14,H13=H14),IF(ISERROR(FIND(L14,N13)),N13&", "&L14,N13),L14) -> Vehicle1 | O14: =Data!K13 -> 0 | P14: =IF(AND(A13=A14,H13=H14),IF(O13="",O14,IF(AND(ISERROR(FIND(O14,P13)),Data!K13<>""),P13&", "&O14,P13)),IF(Data!K13<>"",O14,"")) | Q14: =IF(M14,"Vehicle(s): "&N14&CHAR(10)&"Trailer(s): "&P14,"") | R14: =B14&H14&K14 -> Driver1@abc.com444871 | S14: =INDEX(Q:Q, MATCH(CONCATENATE(B14, H14, J14),R:R, 0)) -> Vehicle(s): Vehicle1 Trailer(s): , Trailer 1, Trailer 2 | T14: =Data!B13 -> ON | U14: =IF(Data!D13<>"", Data!D13, "") | V14: =IF(OR(ISNUMBER(FIND("OFF",T14)),ISNUMBER(FIND("SB",T14)),ISNUMBER(FIND("PC",T14))),"OFF",IF(OR(ISNUMBER(FIND("ON",T14)),ISNUMBER(FIND("YM",T14))),"ON",IF(ISNUMBER(FIND("D", T14)), "D", "NA"))) -> ON | W14: =Data!C13 -> 0.00017511574 | X14: =IF(OR(T14="ON", T14="D", IF(J14=1, TRUE, Z13)), IF(AND(IF(J14=1, TRUE, Z13), T13<>"OFF"), H14, G14), "") -> 44487.242 | Y14: =IF(X14<>"", IF(AND(J14<>1, V14<>"OFF"), IF(Z14, IF(Z13, IF(V14="OFF", G14, H14+1), H14+1), IF(Z13, IF(V14="OFF", G14, G14+W14), X14+W14)),H14), "") -> 44487.242 | Z14: =INT(G14+W14)<>H14 -> FALSE | AA14: =IF(OR(V14="ON", Z13), IF(AND(Z13, V13="ON"), H14, G14), "") -> 44487.242 | AB14: =IF(AA14<>"", IF(Z14, IF(Z13, IF(V14<>"ON", G14, H14+1), H14+1), IF(Z13, IF(V14<>"ON", G14, G14+W14), AA14+W14)), "") -> 44487.242 | AC14: =IFERROR(AB14-AA14, 0) -> 0.00017511574 | AD14: =IF(OR(V14="D", Z13), IF(AND(Z13, V13="D"), H14, G14), "") -> 44487.242 | AE14: =IF(AD14<>"", IF(Z14, IF(Z13, IF(V14<>"D", G14, H14+1), H14+1), IF(Z13, IF(V14<>"D", G14, G14+W14), AD14+W14)), "") -> 44487.242 | AF14: =IFERROR(AE14-AD14, 0) -> 0 | AG14: =AC14+AF14 -> 0.00017511574 | AH14: =IF(OR(V14="OFF", Z13), IF(AND(Z13, V13="OFF"), H14, G14), "") -> 44487 | AI14: =IF(AH14<>"", IF(Z14, IF(Z13, IF(V14<>"OFF", G14, H14+1), H14+1), IF(Z13, IF(V14<>"OFF", G14, G14+W14), AH14+W14)), "") -> 44487.242 | AJ14: =IFERROR(AI14-AH14, 0) -> 0.24174769 | AK14: =Data!L13 -> 1
A15: =CONCATENATE(Data!F14, " ", Data!G14) -> First 1 Last 1 | B15: =Data!H14 -> Driver1@abc.com | C15: =Data!I14 -> 1 | D15: =Data!A14 -> 44487.242 | E15: =Data!J14 -> America/New_York | F15: =(VLOOKUP(E15, TimeZone[], 2, FALSE)-$C$9)/24 -> 0 | G15: =(INT(D15)+TIME(HOUR(D15), MINUTE(D15), SECOND(D15)))-F15 -> 44487.242 | H15: =INT(G15) -> 44487 | I15: =MOD(G15, 1) -> 0.2419213 | J15: =COUNTIFS(A:A, A15,H:H, H15) -> 45 | K15: =COUNTIFS($A$13:A15, A15,$H$13:H15, H15) -> 2 | L15: =Data!E14 -> Vehicle1 | M15: =OR(A15<>A16,H15<>H16) -> FALSE | N15: =IF(AND(A14=A15,H14=H15),IF(ISERROR(FIND(L15,N14)),N14&", "&L15,N14),L15) -> Vehicle1 | O15: =Data!K14 -> Trailer 1, Trailer 2 | P15: =IF(AND(A14=A15,H14=H15),IF(O14="",O15,IF(AND(ISERROR(FIND(O15,P14)),Data!K14<>""),P14&", "&O15,P14)),IF(Data!K14<>"",O15,"")) -> , Trailer 1, Trailer 2 | Q15: =IF(M15,"Vehicle(s): "&N15&CHAR(10)&"Trailer(s): "&P15,"") | R15: =B15&H15&K15 -> Driver1@abc.com444872 | S15: =INDEX(Q:Q, MATCH(CONCATENATE(B15, H15, J15),R:R, 0)) -> Vehicle(s): Vehicle1 Trailer(s): , Trailer 1, Trailer 2 | T15: =Data!B14 -> ON | U15: =IF(Data!D14<>"", Data!D14, "") | V15: =IF(OR(ISNUMBER(FIND("OFF",T15)),ISNUMBER(FIND("SB",T15)),ISNUMBER(FIND("PC",T15))),"OFF",IF(OR(ISNUMBER(FIND("ON",T15)),ISNUMBER(FIND("YM",T15))),"ON",IF(ISNUMBER(FIND("D", T15)), "D", "NA"))) -> ON | W15: =Data!C14 -> 1.1574074e-07 | X15: =IF(OR(T15="ON", T15="D", IF(J15=1, TRUE, Z14)), IF(AND(IF(J15=1, TRUE, Z14), T14<>"OFF"), H15, G15), "") -> 44487.242 | Y15: =IF(X15<>"", IF(AND(J15<>1, V15<>"OFF"), IF(Z15, IF(Z14, IF(V15="OFF", G15, H15+1), H15+1), IF(Z14, IF(V15="OFF", G15, G15+W15), X15+W15)),H15), "") -> 44487.242 | Z15: =INT(G15+W15)<>H15 -> FALSE | AA15: =IF(OR(V15="ON", Z14), IF(AND(Z14, V14="ON"), H15, G15), "") -> 44487.242 | AB15: =IF(AA15<>"", IF(Z15, IF(Z14, IF(V15<>"ON", G15, H15+1), H15+1), IF(Z14, IF(V15<>"ON", G15, G15+W15), AA15+W15)), "") -> 44487.242 | AC15: =IFERROR(AB15-AA15, 0) -> 1.1573866e-07 | AD15: =IF(OR(V15="D", Z14), IF(AND(Z14, V14="D"), H15, G15), "") | AE15: =IF(AD15<>"", IF(Z15, IF(Z14, IF(V15<>"D", G15, H15+1), H15+1), IF(Z14, IF(V15<>"D", G15, G15+W15), AD15+W15)), "") | AF15: =IFERROR(AE15-AD15, 0) -> 0 | AG15: =AC15+AF15 -> 1.1573866e-07 | AH15: =IF(OR(V15="OFF", Z14), IF(AND(Z14, V14="OFF"), H15, G15), "") | AI15: =IF(AH15<>"", IF(Z15, IF(Z14, IF(V15<>"OFF", G15, H15+1), H15+1), IF(Z14, IF(V15<>"OFF", G15, G15+W15), AH15+W15)), "") | AJ15: =IFERROR(AI15-AH15, 0) -> 0 | AK15: =Data!L14 -> 1
A16: =CONCATENATE(Data!F15, " ", Data!G15) -> First 1 Last 1 | B16: =Data!H15 -> Driver1@abc.com | C16: =Data!I15 -> 1 | D16: =Data!A15 -> 44487.242 | E16: =Data!J15 -> America/New_York | F16: =(VLOOKUP(E16, TimeZone[], 2, FALSE)-$C$9)/24 -> 0 | G16: =(INT(D16)+TIME(HOUR(D16), MINUTE(D16), SECOND(D16)))-F16 -> 44487.242 | H16: =INT(G16) -> 44487 | I16: =MOD(G16, 1) -> 0.2419213 | J16: =COUNTIFS(A:A, A16,H:H, H16) -> 45 | K16: =COUNTIFS($A$13:A16, A16,$H$13:H16, H16) -> 3 | L16: =Data!E15 -> Vehicle1 | M16: =OR(A16<>A17,H16<>H17) -> FALSE | N16: =IF(AND(A15=A16,H15=H16),IF(ISERROR(FIND(L16,N15)),N15&", "&L16,N15),L16) -> Vehicle1 | O16: =Data!K15 -> 0 | P16: =IF(AND(A15=A16,H15=H16),IF(O15="",O16,IF(AND(ISERROR(FIND(O16,P15)),Data!K15<>""),P15&", "&O16,P15)),IF(Data!K15<>"",O16,"")) -> , Trailer 1, Trailer 2 | Q16: =IF(M16,"Vehicle(s): "&N16&CHAR(10)&"Trailer(s): "&P16,"") | R16: =B16&H16&K16 -> Driver1@abc.com444873 | S16: =INDEX(Q:Q, MATCH(CONCATENATE(B16, H16, J16),R:R, 0)) -> Vehicle(s): Vehicle1 Trailer(s): , Trailer 1, Trailer 2 | T16: =Data!B15 -> YM | U16: =IF(Data!D15<>"", Data!D15, "") -> 0.079535514 | V16: =IF(OR(ISNUMBER(FIND("OFF",T16)),ISNUMBER(FIND("SB",T16)),ISNUMBER(FIND("PC",T16))),"OFF",IF(OR(ISNUMBER(FIND("ON",T16)),ISNUMBER(FIND("YM",T16))),"ON",IF(ISNUMBER(FIND("D", T16)), "D", "NA"))) -> ON | W16: =Data!C15 -> 0.0052007407 | X16: =IF(OR(T16="ON", T16="D", IF(J16=1, TRUE, Z15)), IF(AND(IF(J16=1, TRUE, Z15), T15<>"OFF"), H16, G16), "") | Y16: =IF(X16<>"", IF(AND(J16<>1, V16<>"OFF"), IF(Z16, IF(Z15, IF(V16="OFF", G16, H16+1), H16+1), IF(Z15, IF(V16="OFF", G16, G16+W16), X16+W16)),H16), "") | Z16: =INT(G16+W16)<>H16 -> FALSE | AA16: =IF(OR(V16="ON", Z15), IF(AND(Z15, V15="ON"), H16, G16), "") -> 44487.242 | AB16: =IF(AA16<>"", IF(Z16, IF(Z15, IF(V16<>"ON", G16, H16+1), H16+1), IF(Z15, IF(V16<>"ON", G16, G16+W16), AA16+W16)), "") -> 44487.247 | AC16: =IFERROR(AB16-AA16, 0) -> 0.0052007407 | AD16: =IF(OR(V16="D", Z15), IF(AND(Z15, V15="D"), H16, G16), "") | AE16: =IF(AD16<>"", IF(Z16, IF(Z15, IF(V16<>"D", G16, H16+1), H16+1), IF(Z15, IF(V16<>"D", G16, G16+W16), AD16+W16)), "") | AF16: =IFERROR(AE16-AD16, 0) -> 0 | AG16: =AC16+AF16 -> 0.0052007407 | AH16: =IF(OR(V16="OFF", Z15), IF(AND(Z15, V15="OFF"), H16, G16), "") | AI16: =IF(AH16<>"", IF(Z16, IF(Z15, IF(V16<>"OFF", G16, H16+1), H16+1), IF(Z15, IF(V16<>"OFF", G16, G16+W16), AH16+W16)), "") | AJ16: =IFERROR(AI16-AH16, 0) -> 0 | AK16: =Data!L15 -> 1
A17: =CONCATENATE(Data!F16, " ", Data!G16) -> First 1 Last 1 | B17: =Data!H16 -> Driver1@abc.com | C17: =Data!I16 -> 1 | D17: =Data!A16 -> 44487.247 | E17: =Data!J16 -> America/New_York | F17: =(VLOOKUP(E17, TimeZone[], 2, FALSE)-$C$9)/24 -> 0 | G17: =(INT(D17)+TIME(HOUR(D17), MINUTE(D17), SECOND(D17)))-F17 -> 44487.247 | H17: =INT(G17) -> 44487 | I17: =MOD(G17, 1) -> 0.24711806 | J17: =COUNTIFS(A:A, A17,H:H, H17) -> 45 | K17: =COUNTIFS($A$13:A17, A17,$H$13:H17, H17) -> 4 | L17: =Data!E16 -> Vehicle1 | M17: =OR(A17<>A18,H17<>H18) -> FALSE | N17: =IF(AND(A16=A17,H16=H17),IF(ISERROR(FIND(L17,N16)),N16&", "&L17,N16),L17) -> Vehicle1 | O17: =Data!K16 -> 0 | P17: =IF(AND(A16=A17,H16=H17),IF(O16="",O17,IF(AND(ISERROR(FIND(O17,P16)),Data!K16<>""),P16&", "&O17,P16)),IF(Data!K16<>"",O17,"")) -> , Trailer 1, Trailer 2 | Q17: =IF(M17,"Vehicle(s): "&N17&CHAR(10)&"Trailer(s): "&P17,"") | R17: =B17&H17&K17 -> Driver1@abc.com444874 | S17: =INDEX(Q:Q, MATCH(CONCATENATE(B17, H17, J17),R:R, 0)) -> Vehicle(s): Vehicle1 Trailer(s): , Trailer 1, Trailer 2 | T17: =Data!B16 -> ON | U17: =IF(Data!D16<>"", Data!D16, "") | V17: =IF(OR(ISNUMBER(FIND("OFF",T17)),ISNUMBER(FIND("SB",T17)),ISNUMBER(FIND("PC",T17))),"OFF",IF(OR(ISNUMBER(FIND("ON",T17)),ISNUMBER(FIND("YM",T17))),"ON",IF(ISNUMBER(FIND("D", T17)), "D", "NA"))) -> ON | W17: =Data!C16 -> 0.0039076389 | X17: =IF(OR(T17="ON", T17="D", IF(J17=1, TRUE, Z16)), IF(AND(IF(J17=1, TRUE, Z16), T16<>"OFF"), H17, G17), "") -> 44487.247 | Y17: =IF(X17<>"", IF(AND(J17<>1, V17<>"OFF"), IF(Z17, IF(Z16, IF(V17="OFF", G17, H17+1), H17+1), IF(Z16, IF(V17="OFF", G17, G17+W17), X17+W17)),H17), "") -> 44487.251 | Z17: =INT(G17+W17)<>H17 -> FALSE | AA17: =IF(OR(V17="ON", Z16), IF(AND(Z16, V16="ON"), H17, G17), "") -> 44487.247 | AB17: =IF(AA17<>"", IF(Z17, IF(Z16, IF(V17<>"ON", G17, H17+1), H17+1), IF(Z16, IF(V17<>"ON", G17, G17+W17), AA17+W17)), "") -> 44487.251 | AC17: =IFERROR(AB17-AA17, 0) -> 0.0039076389 | AD17: =IF(OR(V17="D", Z16), IF(AND(Z16, V16="D"), H17, G17), "") | AE17: =IF(AD17<>"", IF(Z17, IF(Z16, IF(V17<>"D", G17, H17+1), H17+1), IF(Z16, IF(V17<>"D", G17, G17+W17), AD17+W17)), "") | AF17: =IFERROR(AE17-AD17, 0) -> 0 | AG17: =AC17+AF17 -> 0.0039076389 | AH17: =IF(OR(V17="OFF", Z16), IF(AND(Z16, V16="OFF"), H17, G17), "") | AI17: =IF(AH17<>"", IF(Z17, IF(Z16, IF(V17<>"OFF", G17, H17+1), H17+1), IF(Z16, IF(V17<>"OFF", G17, G17+W17), AH17+W17)), "") | AJ17: =IFERROR(AI17-AH17, 0) -> 0 | AK17: =Data!L16 -> 1
A18: =CONCATENATE(Data!F17, " ", Data!G17) -> First 1 Last 1 | B18: =Data!H17 -> Driver1@abc.com | C18: =Data!I17 -> 1 | D18: =Data!A17 -> 44487.251 | E18: =Data!J17 -> America/New_York | F18: =(VLOOKUP(E18, TimeZone[], 2, FALSE)-$C$9)/24 -> 0 | G18: =(INT(D18)+TIME(HOUR(D18), MINUTE(D18), SECOND(D18)))-F18 -> 44487.251 | H18: =INT(G18) -> 44487 | I18: =MOD(G18, 1) -> 0.25103009 | J18: =COUNTIFS(A:A, A18,H:H, H18) -> 45 | K18: =COUNTIFS($A$13:A18, A18,$H$13:H18, H18) -> 5 | L18: =Data!E17 -> Vehicle1 | M18: =OR(A18<>A19,H18<>H19) -> FALSE | N18: =IF(AND(A17=A18,H17=H18),IF(ISERROR(FIND(L18,N17)),N17&", "&L18,N17),L18) -> Vehicle1 | O18: =Data!K17 -> 0 | P18: =IF(AND(A17=A18,H17=H18),IF(O17="",O18,IF(AND(ISERROR(FIND(O18,P17)),Data!K17<>""),P17&", "&O18,P17)),IF(Data!K17<>"",O18,"")) -> , Trailer 1, Trailer 2 | Q18: =IF(M18,"Vehicle(s): "&N18&CHAR(10)&"Trailer(s): "&P18,"") | R18: =B18&H18&K18 -> Driver1@abc.com444875 | S18: =INDEX(Q:Q, MATCH(CONCATENATE(B18, H18, J18),R:R, 0)) -> Vehicle(s): Vehicle1 Trailer(s): , Trailer 1, Trailer 2 | T18: =Data!B17 -> D | U18: =IF(Data!D17<>"", Data!D17, "") -> 51.340176 | V18: =IF(OR(ISNUMBER(FIND("OFF",T18)),ISNUMBER(FIND("SB",T18)),ISNUMBER(FIND("PC",T18))),"OFF",IF(OR(ISNUMBER(FIND("ON",T18)),ISNUMBER(FIND("YM",T18))),"ON",IF(ISNUMBER(FIND("D", T18)), "D", "NA"))) -> D | W18: =Data!C17 -> 0.050162269 | X18: =IF(OR(T18="ON", T18="D", IF(J18=1, TRUE, Z17)), IF(AND(IF(J18=1, TRUE, Z17), T17<>"OFF"), H18, G18), "") -> 44487.251 | Y18: =IF(X18<>"", IF(AND(J18<>1, V18<>"OFF"), IF(Z18, IF(Z17, IF(V18="OFF", G18, H18+1), H18+1), IF(Z17, IF(V18="OFF", G18, G18+W18), X18+W18)),H18), "") -> 44487.301 | Z18: =INT(G18+W18)<>H18 -> FALSE | AA18: =IF(OR(V18="ON", Z17), IF(AND(Z17, V17="ON"), H18, G18), "") | AB18: =IF(AA18<>"", IF(Z18, IF(Z17, IF(V18<>"ON", G18, H18+1), H18+1), IF(Z17, IF(V18<>"ON", G18, G18+W18), AA18+W18)), "") | AC18: =IFERROR(AB18-AA18, 0) -> 0 | AD18: =IF(OR(V18="D", Z17), IF(AND(Z17, V17="D"), H18, G18), "") -> 44487.251 | AE18: =IF(AD18<>"", IF(Z18, IF(Z17, IF(V18<>"D", G18, H18+1), H18+1), IF(Z17, IF(V18<>"D", G18, G18+W18), AD18+W18)), "") -> 44487.301 | AF18: =IFERROR(AE18-AD18, 0) -> 0.050162269 | AG18: =AC18+AF18 -> 0.050162269 | AH18: =IF(OR(V18="OFF", Z17), IF(AND(Z17, V17="OFF"), H18, G18), "") | AI18: =IF(AH18<>"", IF(Z18, IF(Z17, IF(V18<>"OFF", G18, H18+1), H18+1), IF(Z17, IF(V18<>"OFF", G18, G18+W18), AH18+W18)), "") | AJ18: =IFERROR(AI18-AH18, 0) -> 0 | AK18: =Data!L17 -> 1
A19: =CONCATENATE(Data!F18, " ", Data!G18) -> First 1 Last 1 | B19: =Data!H18 -> Driver1@abc.com | C19: =Data!I18 -> 1 | D19: =Data!A18 -> 44487.293 | E19: =Data!J18 -> America/New_York | F19: =(VLOOKUP(E19, TimeZone[], 2, FALSE)-$C$9)/24 -> 0 | G19: =(INT(D19)+TIME(HOUR(D19), MINUTE(D19), SECOND(D19)))-F19 -> 44487.293 | H19: =INT(G19) -> 44487 | I19: =MOD(G19, 1) -> 0.29269676 | J19: =COUNTIFS(A:A, A19,H:H, H19) -> 45 | K19: =COUNTIFS($A$13:A19, A19,$H$13:H19, H19) -> 6 | L19: =Data!E18 -> Vehicle1 | M19: =OR(A19<>A20,H19<>H20) -> FALSE | N19: =IF(AND(A18=A19,H18=H19),IF(ISERROR(FIND(L19,N18)),N18&", "&L19,N18),L19) -> Vehicle1 | O19: =Data!K18 -> 0 | P19: =IF(AND(A18=A19,H18=H19),IF(O18="",O19,IF(AND(ISERROR(FIND(O19,P18)),Data!K18<>""),P18&", "&O19,P18)),IF(Data!K18<>"",O19,"")) -> , Trailer 1, Trailer 2 | Q19: =IF(M19,"Vehicle(s): "&N19&CHAR(10)&"Trailer(s): "&P19,"") | R19: =B19&H19&K19 -> Driver1@abc.com444876 | S19: =INDEX(Q:Q, MATCH(CONCATENATE(B19, H19, J19),R:R, 0)) -> Vehicle(s): Vehicle1 Trailer(s): , Trailer 1, Trailer 2 | T19: =Data!B18 -> INT_D | U19: =IF(Data!D18<>"", Data!D18, "") -> 11.095204 | V19: =IF(OR(ISNUMBER(FIND("OFF",T19)),ISNUMBER(FIND("SB",T19)),ISNUMBER(FIND("PC",T19))),"OFF",IF(OR(ISNUMBER(FIND("ON",T19)),ISNUMBER(FIND("YM",T19))),"ON",IF(ISNUMBER(FIND("D", T19)), "D", "NA"))) -> D | W19: =Data!C18 -> 0 | X19: =IF(OR(T19="ON", T19="D", IF(J19=1, TRUE, Z18)), IF(AND(IF(J19=1, TRUE, Z18), T18<>"OFF"), H19, G19), "") | Y19: =IF(X19<>"", IF(AND(J19<>1, V19<>"OFF"), IF(Z19, IF(Z18, IF(V19="OFF", G19, H19+1), H19+1), IF(Z18, IF(V19="OFF", G19, G19+W19), X19+W19)),H19), "") | Z19: =INT(G19+W19)<>H19 -> FALSE | AA19: =IF(OR(V19="ON", Z18), IF(AND(Z18, V18="ON"), H19, G19), "") | AB19: =IF(AA19<>"", IF(Z19, IF(Z18, IF(V19<>"ON", G19, H19+1), H19+1), IF(Z18, IF(V19<>"ON", G19, G19+W19), AA19+W19)), "") | AC19: =IFERROR(AB19-AA19, 0) -> 0 | AD19: =IF(OR(V19="D", Z18), IF(AND(Z18, V18="D"), H19, G19), "") -> 44487.293 | AE19: =IF(AD19<>"", IF(Z19, IF(Z18, IF(V19<>"D", G19, H19+1), H19+1), IF(Z18, IF(V19<>"D", G19, G19+W19), AD19+W19)), "") -> 44487.293 | AF19: =IFERROR(AE19-AD19, 0) -> 0 | AG19: =AC19+AF19 -> 0 | AH19: =IF(OR(V19="OFF", Z18), IF(AND(Z18, V18="OFF"), H19, G19), "") | AI19: =IF(AH19<>"", IF(Z19, IF(Z18, IF(V19<>"OFF", G19, H19+1), H19+1), IF(Z18, IF(V19<>"OFF", G19, G19+W19), AH19+W19)), "") | AJ19: =IFERROR(AI19-AH19, 0) -> 0 | AK19: =Data!L18 -> 1
A20: =CONCATENATE(Data!F19, " ", Data!G19) -> First 1 Last 1 | B20: =Data!H19 -> Driver1@abc.com | C20: =Data!I19 -> 1 | D20: =Data!A19 -> 44487.301 | E20: =Data!J19 -> America/New_York | F20: =(VLOOKUP(E20, TimeZone[], 2, FALSE)-$C$9)/24 -> 0 | G20: =(INT(D20)+TIME(HOUR(D20), MINUTE(D20), SECOND(D20)))-F20 -> 44487.301 | H20: =INT(G20) -> 44487 | I20: =MOD(G20, 1) -> 0.30119213 | J20: =COUNTIFS(A:A, A20,H:H, H20) -> 45 | K20: =COUNTIFS($A$13:A20, A20,$H$13:H20, H20) -> 7 | L20: =Data!E19 -> Vehicle1 | M20: =OR(A20<>A21,H20<>H21) -> FALSE | N20: =IF(AND(A19=A20,H19=H20),IF(ISERROR(FIND(L20,N19)),N19&", "&L20,N19),L20) -> Vehicle1 | O20: =Data!K19 -> 0 | P20: =IF(AND(A19=A20,H19=H20),IF(O19="",O20,IF(AND(ISERROR(FIND(O20,P19)),Data!K19<>""),P19&", "&O20,P19)),IF(Data!K19<>"",O20,"")) -> , Trailer 1, Trailer 2 | Q20: =IF(M20,"Vehicle(s): "&N20&CHAR(10)&"Trailer(s): "&P20,"") | R20: =B20&H20&K20 -> Driver1@abc.com444877 | S20: =INDEX(Q:Q, MATCH(CONCATENATE(B20, H20, J20),R:R, 0)) -> Vehicle(s): Vehicle1 Trailer(s): , Trailer 1, Trailer 2 | T20: =Data!B19 -> ON | U20: =IF(Data!D19<>"", Data!D19, "") | V20: =IF(OR(ISNUMBER(FIND("OFF",T20)),ISNUMBER(FIND("SB",T20)),ISNUMBER(FIND("PC",T20))),"OFF",IF(OR(ISNUMBER(FIND("ON",T20)),ISNUMBER(FIND("YM",T20))),"ON",IF(ISNUMBER(FIND("D", T20)), "D", "NA"))) -> ON | W20: =Data!C19 -> 0.004930706 | X20: =IF(OR(T20="ON", T20="D", IF(J20=1, TRUE, Z19)), IF(AND(IF(J20=1, TRUE, Z19), T19<>"OFF"), H20, G20), "") -> 44487.301 | Y20: =IF(X20<>"", IF(AND(J20<>1, V20<>"OFF"), IF(Z20, IF(Z19, IF(V20="OFF", G20, H20+1), H20+1), IF(Z19, IF(V20="OFF", G20, G20+W20), X20+W20)),H20), "") -> 44487.306 | Z20: =INT(G20+W20)<>H20 -> FALSE | AA20: =IF(OR(V20="ON", Z19), IF(AND(Z19, V19="ON"), H20, G20), "") -> 44487.301 | AB20: =IF(AA20<>"", IF(Z20, IF(Z19, IF(V20<>"ON", G20, H20+1), H20+1), IF(Z19, IF(V20<>"ON", G20, G20+W20), AA20+W20)), "") -> 44487.306 | AC20: =IFERROR(AB20-AA20, 0) -> 0.004930706 | AD20: =IF(OR(V20="D", Z19), IF(AND(Z19, V19="D"), H20, G20), "") | AE20: =IF(AD20<>"", IF(Z20, IF(Z19, IF(V20<>"D", G20, H20+1), H20+1), IF(Z19, IF(V20<>"D", G20, G20+W20), AD20+W20)), "") | AF20: =IFERROR(AE20-AD20, 0) -> 0 | AG20: =AC20+AF20 -> 0.004930706 | AH20: =IF(OR(V20="OFF", Z19), IF(AND(Z19, V19="OFF"), H20, G20), "") | AI20: =IF(AH20<>"", IF(Z20, IF(Z19, IF(V20<>"OFF", G20, H20+1), H20+1), IF(Z19, IF(V20<>"OFF", G20, G20+W20), AH20+W20)), "") | AJ20: =IFERROR(AI20-AH20, 0) -> 0 | AK20: =Data!L19 -> 1
A21: =CONCATENATE(Data!F20, " ", Data!G20) -> First 1 Last 1 | B21: =Data!H20 -> Driver1@abc.com | C21: =Data!I20 -> 1 | D21: =Data!A20 -> 44487.306 | E21: =Data!J20 -> America/New_York | F21: =(VLOOKUP(E21, TimeZone[], 2, FALSE)-$C$9)/24 -> 0 | G21: =(INT(D21)+TIME(HOUR(D21), MINUTE(D21), SECOND(D21)))-F21 -> 44487.306 | H21: =INT(G21) -> 44487 | I21: =MOD(G21, 1) -> 0.30612269 | J21: =COUNTIFS(A:A, A21,H:H, H21) -> 45 | K21: =COUNTIFS($A$13:A21, A21,$H$13:H21, H21) -> 8 | L21: =Data!E20 -> Vehicle1 | M21: =OR(A21<>A22,H21<>H22) -> FALSE | N21: =IF(AND(A20=A21,H20=H21),IF(ISERROR(FIND(L21,N20)),N20&", "&L21,N20),L21) -> Vehicle1 | O21: =Data!K20 -> 0 | P21: =IF(AND(A20=A21,H20=H21),IF(O20="",O21,IF(AND(ISERROR(FIND(O21,P20)),Data!K20<>""),P20&", "&O21,P20)),IF(Data!K20<>"",O21,"")) -> , Trailer 1, Trailer 2 | Q21: =IF(M21,"Vehicle(s): "&N21&CHAR(10)&"Trailer(s): "&P21,"") | R21: =B21&H21&K21 -> Driver1@abc.com444878 | S21: =INDEX(Q:Q, MATCH(CONCATENATE(B21, H21, J21),R:R, 0)) -> Vehicle(s): Vehicle1 Trailer(s): , Trailer 1, Trailer 2 | T21: =Data!B20 -> D | U21: =IF(Data!D20<>"", Data!D20, "") -> 38.017979 | V21: =IF(OR(ISNUMBER(FIND("OFF",T21)),ISNUMBER(FIND("SB",T21)),ISNUMBER(FIND("PC",T21))),"OFF",IF(OR(ISNUMBER(FIND("ON",T21)),ISNUMBER(FIND("YM",T21))),"ON",IF(ISNUMBER(FIND("D", T21)), "D", "NA"))) -> D | W21: =Data!C20 -> 0.085960266 | X21: =IF(OR(T21="ON", T21="D", IF(J21=1, TRUE, Z20)), IF(AND(IF(J21=1, TRUE, Z20), T20<>"OFF"), H21, G21), "") -> 44487.306 | Y21: =IF(X21<>"", IF(AND(J21<>1, V21<>"OFF"), IF(Z21, IF(Z20, IF(V21="OFF", G21, H21+1), H21+1), IF(Z20, IF(V21="OFF", G21, G21+W21), X21+W21)),H21), "") -> 44487.392 | Z21: =INT(G21+W21)<>H21 -> FALSE | AA21: =IF(OR(V21="ON", Z20), IF(AND(Z20, V20="ON"), H21, G21), "") | AB21: =IF(AA21<>"", IF(Z21, IF(Z20, IF(V21<>"ON", G21, H21+1), H21+1), IF(Z20, IF(V21<>"ON", G21, G21+W21), AA21+W21)), "") | AC21: =IFERROR(AB21-AA21, 0) -> 0 | AD21: =IF(OR(V21="D", Z20), IF(AND(Z20, V20="D"), H21, G21), "") -> 44487.306 | AE21: =IF(AD21<>"", IF(Z21, IF(Z20, IF(V21<>"D", G21, H21+1), H21+1), IF(Z20, IF(V21<>"D", G21, G21+W21), AD21+W21)), "") -> 44487.392 | AF21: =IFERROR(AE21-AD21, 0) -> 0.085960266 | AG21: =AC21+AF21 -> 0.085960266 | AH21: =IF(OR(V21="OFF", Z20), IF(AND(Z20, V20="OFF"), H21, G21), "") | AI21: =IF(AH21<>"", IF(Z21, IF(Z20, IF(V21<>"OFF", G21, H21+1), H21+1), IF(Z20, IF(V21<>"OFF", G21, G21+W21), AH21+W21)), "") | AJ21: =IFERROR(AI21-AH21, 0) -> 0 | AK21: =Data!L20 -> 1
A22: =CONCATENATE(Data!F21, " ", Data!G21) -> First 1 Last 1 | B22: =Data!H21 -> Driver1@abc.com | C22: =Data!I21 -> 1 | D22: =Data!A21 -> 44487.348 | E22: =Data!J21 -> America/New_York | F22: =(VLOOKUP(E22, TimeZone[], 2, FALSE)-$C$9)/24 -> 0 | G22: =(INT(D22)+TIME(HOUR(D22), MINUTE(D22), SECOND(D22)))-F22 -> 44487.348 | H22: =INT(G22) -> 44487 | I22: =MOD(G22, 1) -> 0.34778935 | J22: =COUNTIFS(A:A, A22,H:H, H22) -> 45 | K22: =COUNTIFS($A$13:A22, A22,$H$13:H22, H22) -> 9 | L22: =Data!E21 -> Vehicle1 | M22: =OR(A22<>A23,H22<>H23) -> FALSE | N22: =IF(AND(A21=A22,H21=H22),IF(ISERROR(FIND(L22,N21)),N21&", "&L22,N21),L22) -> Vehicle1 | O22: =Data!K21 -> 0 | P22: =IF(AND(A21=A22,H21=H22),IF(O21="",O22,IF(AND(ISERROR(FIND(O22,P21)),Data!K21<>""),P21&", "&O22,P21)),IF(Data!K21<>"",O22,"")) -> , Trailer 1, Trailer 2 | Q22: =IF(M22,"Vehicle(s): "&N22&CHAR(10)&"Trailer(s): "&P22,"") | R22: =B22&H22&K22 -> Driver1@abc.com444879 | S22: =INDEX(Q:Q, MATCH(CONCATENATE(B22, H22, J22),R:R, 0)) -> Vehicle(s): Vehicle1 Trailer(s): , Trailer 1, Trailer 2 | T22: =Data!B21 -> INT_D | U22: =IF(Data!D21<>"", Data!D21, "") -> 23.542513 | V22: =IF(OR(ISNUMBER(FIND("OFF",T22)),ISNUMBER(FIND("SB",T22)),ISNUMBER(FIND("PC",T22))),"OFF",IF(OR(ISNUMBER(FIND("ON",T22)),ISNUMBER(FIND("YM",T22))),"ON",IF(ISNUMBER(FIND("D", T22)), "D", "NA"))) -> D | W22: =Data!C21 -> 0 | X22: =IF(OR(T22="ON", T22="D", IF(J22=1, TRUE, Z21)), IF(AND(IF(J22=1, TRUE, Z21), T21<>"OFF"), H22, G22), "") | Y22: =IF(X22<>"", IF(AND(J22<>1, V22<>"OFF"), IF(Z22, IF(Z21, IF(V22="OFF", G22, H22+1), H22+1), IF(Z21, IF(V22="OFF", G22, G22+W22), X22+W22)),H22), "") | Z22: =INT(G22+W22)<>H22 -> FALSE | AA22: =IF(OR(V22="ON", Z21), IF(AND(Z21, V21="ON"), H22, G22), "") | AB22: =IF(AA22<>"", IF(Z22, IF(Z21, IF(V22<>"ON", G22, H22+1), H22+1), IF(Z21, IF(V22<>"ON", G22, G22+W22), AA22+W22)), "") | AC22: =IFERROR(AB22-AA22, 0) -> 0 | AD22: =IF(OR(V22="D", Z21), IF(AND(Z21, V21="D"), H22, G22), "") -> 44487.348 | AE22: =IF(AD22<>"", IF(Z22, IF(Z21, IF(V22<>"D", G22, H22+1), H22+1), IF(Z21, IF(V22<>"D", G22, G22+W22), AD22+W22)), "") -> 44487.348 | AF22: =IFERROR(AE22-AD22, 0) -> 0 | AG22: =AC22+AF22 -> 0 | AH22: =IF(OR(V22="OFF", Z21), IF(AND(Z21, V21="OFF"), H22, G22), "") | AI22: =IF(AH22<>"", IF(Z22, IF(Z21, IF(V22<>"OFF", G22, H22+1), H22+1), IF(Z21, IF(V22<>"OFF", G22, G22+W22), AH22+W22)), "") | AJ22: =IFERROR(AI22-AH22, 0) -> 0 | AK22: =Data!L21 -> 1
A23: =CONCATENATE(Data!F22, " ", Data!G22) -> First 1 Last 1 | B23: =Data!H22 -> Driver1@abc.com | C23: =Data!I22 -> 1 | D23: =Data!A22 -> 44487.389 | E23: =Data!J22 -> America/New_York | F23: =(VLOOKUP(E23, TimeZone[], 2, FALSE)-$C$9)/24 -> 0 | G23: =(INT(D23)+TIME(HOUR(D23), MINUTE(D23), SECOND(D23)))-F23 -> 44487.389 | H23: =INT(G23) -> 44487 | I23: =MOD(G23, 1) -> 0.38945602 | J23: =COUNTIFS(A:A, A23,H:H, H23) -> 45 | K23: =COUNTIFS($A$13:A23, A23,$H$13:H23, H23) -> 10 | L23: =Data!E22 -> Vehicle1 | M23: =OR(A23<>A24,H23<>H24) -> FALSE | N23: =IF(AND(A22=A23,H22=H23),IF(ISERROR(FIND(L23,N22)),N22&", "&L23,N22),L23) -> Vehicle1 | O23: =Data!K22 -> 0 | P23: =IF(AND(A22=A23,H22=H23),IF(O22="",O23,IF(AND(ISERROR(FIND(O23,P22)),Data!K22<>""),P22&", "&O23,P22)),IF(Data!K22<>"",O23,"")) -> , Trailer 1, Trailer 2 | Q23: =IF(M23,"Vehicle(s): "&N23&CHAR(10)&"Trailer(s): "&P23,"") | R23: =B23&H23&K23 -> Driver1@abc.com4448710 | S23: =INDEX(Q:Q, MATCH(CONCATENATE(B23, H23, J23),R:R, 0)) -> Vehicle(s): Vehicle1 Trailer(s): , Trailer 1, Trailer 2 | T23: =Data!B22 -> INT_D | U23: =IF(Data!D22<>"", Data!D22, "") -> 0.19883879 | V23: =IF(OR(ISNUMBER(FIND("OFF",T23)),ISNUMBER(FIND("SB",T23)),ISNUMBER(FIND("PC",T23))),"OFF",IF(OR(ISNUMBER(FIND("ON",T23)),ISNUMBER(FIND("YM",T23))),"ON",IF(ISNUMBER(FIND("D", T23)), "D", "NA"))) -> D | W23: =Data!C22 -> 0 | X23: =IF(OR(T23="ON", T23="D", IF(J23=1, TRUE, Z22)), IF(AND(IF(J23=1, TRUE, Z22), T22<>"OFF"), H23, G23), "") | Y23: =IF(X23<>"", IF(AND(J23<>1, V23<>"OFF"), IF(Z23, IF(Z22, IF(V23="OFF", G23, H23+1), H23+1), IF(Z22, IF(V23="OFF", G23, G23+W23), X23+W23)),H23), "") | Z23: =INT(G23+W23)<>H23 -> FALSE | AA23: =IF(OR(V23="ON", Z22), IF(AND(Z22, V22="ON"), H23, G23), "") | AB23: =IF(AA23<>"", IF(Z23, IF(Z22, IF(V23<>"ON", G23, H23+1), H23+1), IF(Z22, IF(V23<>"ON", G23, G23+W23), AA23+W23)), "") | AC23: =IFERROR(AB23-AA23, 0) -> 0 | AD23: =IF(OR(V23="D", Z22), IF(AND(Z22, V22="D"), H23, G23), "") -> 44487.389 | AE23: =IF(AD23<>"", IF(Z23, IF(Z22, IF(V23<>"D", G23, H23+1), H23+1), IF(Z22, IF(V23<>"D", G23, G23+W23), AD23+W23)), "") -> 44487.389 | AF23: =IFERROR(AE23-AD23, 0) -> 0 | AG23: =AC23+AF23 -> 0 | AH23: =IF(OR(V23="OFF", Z22), IF(AND(Z22, V22="OFF"), H23, G23), "") | AI23: =IF(AH23<>"", IF(Z23, IF(Z22, IF(V23<>"OFF", G23, H23+1), H23+1), IF(Z22, IF(V23<>"OFF", G23, G23+W23), AH23+W23)), "") | AJ23: =IFERROR(AI23-AH23, 0) -> 0 | AK23: =Data!L22 -> 1
A24: =CONCATENATE(Data!F23, " ", Data!G23) -> First 1 Last 1 | B24: =Data!H23 -> Driver1@abc.com | C24: =Data!I23 -> 1 | D24: =Data!A23 -> 44487.392 | E24: =Data!J23 -> America/New_York | F24: =(VLOOKUP(E24, TimeZone[], 2, FALSE)-$C$9)/24 -> 0 | G24: =(INT(D24)+TIME(HOUR(D24), MINUTE(D24), SECOND(D24)))-F24 -> 44487.392 | H24: =INT(G24) -> 44487 | I24: =MOD(G24, 1) -> 0.39208333 | J24: =COUNTIFS(A:A, A24,H:H, H24) -> 45 | K24: =COUNTIFS($A$13:A24, A24,$H$13:H24, H24) -> 11 | L24: =Data!E23 -> Vehicle1 | M24: =OR(A24<>A25,H24<>H25) -> FALSE | N24: =IF(AND(A23=A24,H23=H24),IF(ISERROR(FIND(L24,N23)),N23&", "&L24,N23),L24) -> Vehicle1 | O24: =Data!K23 -> 0 | P24: =IF(AND(A23=A24,H23=H24),IF(O23="",O24,IF(AND(ISERROR(FIND(O24,P23)),Data!K23<>""),P23&", "&O24,P23)),IF(Data!K23<>"",O24,"")) -> , Trailer 1, Trailer 2 | Q24: =IF(M24,"Vehicle(s): "&N24&CHAR(10)&"Trailer(s): "&P24,"") | R24: =B24&H24&K24 -> Driver1@abc.com4448711 | S24: =INDEX(Q:Q, MATCH(CONCATENATE(B24, H24, J24),R:R, 0)) -> Vehicle(s): Vehicle1 Trailer(s): , Trailer 1, Trailer 2 | T24: =Data!B23 -> ON | U24: =IF(Data!D23<>"", Data!D23, "") | V24: =IF(OR(ISNUMBER(FIND("OFF",T24)),ISNUMBER(FIND("SB",T24)),ISNUMBER(FIND("PC",T24))),"OFF",IF(OR(ISNUMBER(FIND("ON",T24)),ISNUMBER(FIND("YM",T24))),"ON",IF(ISNUMBER(FIND("D", T24)), "D", "NA"))) -> ON | W24: =Data!C23 -> 0.0095028935 | X24: =IF(OR(T24="ON", T24="D", IF(J24=1, TRUE, Z23)), IF(AND(IF(J24=1, TRUE, Z23), T23<>"OFF"), H24, G24), "") -> 44487.392 | Y24: =IF(X24<>"", IF(AND(J24<>1, V24<>"OFF"), IF(Z24, IF(Z23, IF(V24="OFF", G24, H24+1), H24+1), IF(Z23, IF(V24="OFF", G24, G24+W24), X24+W24)),H24), "") -> 44487.402 | Z24: =INT(G24+W24)<>H24 -> FALSE | AA24: =IF(OR(V24="ON", Z23), IF(AND(Z23, V23="ON"), H24, G24), "") -> 44487.392 | AB24: =IF(AA24<>"", IF(Z24, IF(Z23, IF(V24<>"ON", G24, H24+1), H24+1), IF(Z23, IF(V24<>"ON", G24, G24+W24), AA24+W24)), "") -> 44487.402 | AC24: =IFERROR(AB24-AA24, 0) -> 0.0095028935 | AD24: =IF(OR(V24="D", Z23), IF(AND(Z23, V23="D"), H24, G24), "") | AE24: =IF(AD24<>"", IF(Z24, IF(Z23, IF(V24<>"D", G24, H24+1), H24+1), IF(Z23, IF(V24<>"D", G24, G24+W24), AD24+W24)), "") | AF24: =IFERROR(AE24-AD24, 0) -> 0 | AG24: =AC24+AF24 -> 0.0095028935 | AH24: =IF(OR(V24="OFF", Z23), IF(AND(Z23, V23="OFF"), H24, G24), "") | AI24: =IF(AH24<>"", IF(Z24, IF(Z23, IF(V24<>"OFF", G24, H24+1), H24+1), IF(Z23, IF(V24<>"OFF", G24, G24+W24), AH24+W24)), "") | AJ24: =IFERROR(AI24-AH24, 0) -> 0 | AK24: =Data!L23 -> 1
... A98: =CONCATENATE(Data!F97, " ", Data!G97) -> First 2 Last 2 | B98: =Data!H97 -> Driver2@abc.com | C98: =Data!I97 -> 2 | D98: =Data!A97 -> 44491.7 | E98: =Data!J97 -> CST6CDT | F98: =(VLOOKUP(E98, TimeZone[], 2, FALSE)-$C$9)/24 -> 0.041666667 | G98: =(INT(D98)+TIME(HOUR(D98), MINUTE(D98), SECOND(D98)))-F98 -> 44491.658 | H98: =INT(G98) -> 44491 | I98: =MOD(G98, 1) -> 0.65813657 | J98: =COUNTIFS(A:A, A98,H:H, H98) -> 16 | K98: =COUNTIFS($A$13:A98, A98,$H$13:H98, H98) -> 16 | L98: =Data!E97 -> Vehicle2 | M98: =OR(A98<>A99,H98<>H99) -> TRUE | N98: =IF(AND(A97=A98,H97=H98),IF(ISERROR(FIND(L98,N97)),N97&", "&L98,N97),L98) -> Vehicle2 | O98: =Data!K97 -> 0 | P98: =IF(AND(A97=A98,H97=H98),IF(O97="",O98,IF(AND(ISERROR(FIND(O98,P97)),Data!K97<>""),P97&", "&O98,P97)),IF(Data!K97<>"",O98,"")) | Q98: =IF(M98,"Vehicle(s): "&N98&CHAR(10)&"Trailer(s): "&P98,"") -> Vehicle(s): Vehicle2 Trailer(s): | R98: =B98&H98&K98 -> Driver2@abc.com4449116 | S98: =INDEX(Q:Q, MATCH(CONCATENATE(B98, H98, J98),R:R, 0)) -> Vehicle(s): Vehicle2 Trailer(s): | T98: =Data!B97 -> OFF | U98: =IF(Data!D97<>"", Data!D97, "") | V98: =IF(OR(ISNUMBER(FIND("OFF",T98)),ISNUMBER(FIND("SB",T98)),ISNUMBER(FIND("PC",T98))),"OFF",IF(OR(ISNUMBER(FIND("ON",T98)),ISNUMBER(FIND("YM",T98))),"ON",IF(ISNUMBER(FIND("D", T98)), "D", "NA"))) -> OFF | W98: =Data!C97 -> 1.3001808 | X98: =IF(OR(T98="ON", T98="D", IF(J98=1, TRUE, Z97)), IF(AND(IF(J98=1, TRUE, Z97), T97<>"OFF"), H98, G98), "") | Y98: =IF(X98<>"", IF(AND(J98<>1, V98<>"OFF"), IF(Z98, IF(Z97, IF(V98="OFF", G98, H98+1), H98+1), IF(Z97, IF(V98="OFF", G98, G98+W98), X98+W98)),H98), "") | Z98: =INT(G98+W98)<>H98 -> TRUE | AA98: =IF(OR(V98="ON", Z97), IF(AND(Z97, V97="ON"), H98, G98), "") | AB98: =IF(AA98<>"", IF(Z98, IF(Z97, IF(V98<>"ON", G98, H98+1), H98+1), IF(Z97, IF(V98<>"ON", G98, G98+W98), AA98+W98)), "") | AC98: =IFERROR(AB98-AA98, 0) -> 0 | AD98: =IF(OR(V98="D", Z97), IF(AND(Z97, V97="D"), H98, G98), "") | AE98: =IF(AD98<>"", IF(Z98, IF(Z97, IF(V98<>"D", G98, H98+1), H98+1), IF(Z97, IF(V98<>"D", G98, G98+W98), AD98+W98)), "") | AF98: =IFERROR(AE98-AD98, 0) -> 0 | AG98: =AC98+AF98 -> 0 | AH98: =IF(OR(V98="OFF", Z97), IF(AND(Z97, V97="OFF"), H98, G98), "") -> 44491.658 | AI98: =IF(AH98<>"", IF(Z98, IF(Z97, IF(V98<>"OFF", G98, H98+1), H98+1), IF(Z97, IF(V98<>"OFF", G98, G98+W98), AH98+W98)), "") -> 44492 | AJ98: =IFERROR(AI98-AH98, 0) -> 0.34186343 | AK98: =Data!L97 -> 2

Sheet Summary
A1: =Report!A1 -> **Small Fleet Payroll Report | D1: =Data!B2 -> 44498.903
A2: =Data!B1 -> Template Company Name
A4: **Date
A5: **From | B5: =Data!B3 -> 44486
A6: **To | B6: =Data!B4 -> 44493
A7: **Days | B7: =B6-B5 -> 6.9999884
A9: **Time Zone | B9: =Data!B5 -> America/New_York
A11: Totals: | G11: =SUM(G$13:G$1498) -> 0.33719907 | H11: =SUM(H$13:H$1498) -> 0.72145833 | I11: =SUM(I$13:I$1498) -> 1.0586574 | J11: =SUM(J$13:J$1498) -> 2.9413426
A13: **Driver | B13: **Employee Number | C13: **Date | D13: Activity | E13: Clock In Time | F13: Clock Out Time | G13: ON Duty Duration | H13: Driving Duration | I13: Total Work Duration | J13: OFF Duty Duration
A14: Driver1@abc.com | B14: 1 | C14: 44486 | D14: Vehicle(s): Vehicle1 Trailer(s): Trailer 1 | E14: 44486 | F14: 44486 | G14: 0 | H14: 0 | I14: 0 | J14: 1
C15: 44487 | D15: Vehicle(s): Vehicle1 Trailer(s): , Trailer 1, Trailer 2 | E15: 44487.242 | F15: 44487.788 | G15: 0.15436343 | H15: 0.39158565 | I15: 0.54594907 | J15: 0.45405093
A16: Driver2@abc.com | B16: 2 | C16: 44490 | D16: Vehicle(s): Vehicle2 Trailer(s): | E16: 44490.311 | F16: 44490.584 | G16: 0.08474537 | H16: 0.12986111 | I16: 0.21460648 | J16: 0.78539352
C17: 44491 | D17: Vehicle(s): Vehicle2 Trailer(s): | E17: 44491.294 | F17: 44491.658 | G17: 0.098090278 | H17: 0.20001157 | I17: 0.29810185 | J17: 0.70189815
